Workbook

Sheet 执行清单
A1: 流程 | B1: 检查项 | C1: 判断依据 | D1: 自动结论 | E1: 手动确认 | F1: 不通过动作 | G1: 备注
A2: A.止损检查 | B2: 东风股份(600006) | C2: WAIVED | 现价5.49 vs 止损5.22 | 浮亏-37.0% | D2: 持有(不加不减) | E2: — | F2: 若跌破5.22立即止损 | G2: WAIVED豁免, 固定止损5.22, 远离止损线
A3: A.止损检查 | B3: 贵绳股份(600992) | C3: 现价9.17 vs 止损8.44 | 浮亏-0.01% | D3: 持有观察 | E3: — | F3: 若跌破8.44止损 | G3: 接近成本价, 弱势震荡, 关注方向选择
A4: A.止损检查 | B4: 松芝/三力士/拱东 | C4: 三只浮盈标的, 止损均未破 | D4: 持有 | E4: — | F4: — | G4: 松芝+2.7% 三力士+3.1% 拱东+2.9%, 止损线上移保护利润
A5: B.卖出信号 | B5: — | C5: 今日无持仓标的出现日线卖点 | D5: 无操作 | E5: — | F5: — | G5: 持仓6只均在止损线上方, 无卖出信号
A6: C.买入 | B6: 台华新材(603055) | C6: 核心池 | DL_P=0.96 ratio=19% | 现价¥8.30 | D6: 买入100股@8.30 | E6: 待委托 | F6: 若开盘跌破7.83(买点低点)放弃 | G6: 1手=¥830, 加仓后仓位≈36.0%, 总仓位仍在60%上限内
A7: C.买入 | B7: 日上集团(002593) | C7: 核心池 | DL_P=0.94 ratio=19% | 现价¥4.18 | D7: 买入200股@4.18 | E7: 待委托 | F7: 若开盘跌破3.96(买点低点)放弃 | G7: 2手=¥836, 加仓后仓位≈36.4%
A8: D.持有 | B8: 拱东医疗(605369) | C8: 浮盈+2.9% | 仓位14.93% | 接近单股上限25% | D8: 持有(不加仓) | E8: — | F8: — | G8: 仓位占比最高, 浮盈保护, 止损上移至14.10
A9: D.持有 | B9: 松芝股份(002454) | C9: 浮盈+2.7% | 仓位8.93% | D9: 持有 | E9: — | F9: — | G9: 止损4.227, 现价4.72>止损, 浮盈保护
A10: D.持有 | B10: 三力士(002224) | C10: 浮盈+3.1% | 仓位4.81% | D10: 持有 | E10: — | F10: — | G10: 止损3.024, 现价3.39>止损, 浮盈保护
A11: E.资金 | B11: 买入冻结 | C11: 台华¥830 + 日上¥836 | D11: -¥1666 | E11: — | F11: — | G11: 两笔买入共冻结¥1666
A12: E.资金 | B12: 成交后现金 | C12: 13615.56 - 1666 | D12: ¥11,949.56 | E12: — | F12: — | G12: 现金充裕, 保留应急资金
... A17: F.风控 | B17: 候选池观察 | C17: 观察池+边缘池标的 | D17: 仅观察 | E17: — | F17: — | G17: 平安银行(观察池) DL_P=0.88, 待DL_P升至0.90+升入核心池后考虑
A19: 合规审查
A20: 审查项 | B20: 检查内容 | C20: 判断依据 | D20: 结论 | E20: 处理动作 | F20: 严重度 | G20: 备注
A21: ⚠️ 违规买入 | B21: 沃华医药(买入200股@6.000) | C21: 沃华医药不在候选池内! 候选池5只: 台华新材/日上集团/丽珠集团/中国平安/平安银行. 未经系统筛选, 无DL_P/ratio数据, 属随意买入. | D21: 不通过 | E21: 建议撤单 | F21: 高
A22: ⚠️ 违规卖出 | B22: 三力士(卖出300股@3.380) | C22: 执行清单计划为"持有", 三力士浮盈+3.14%, 止损3.024未破. 但实际挂了全仓卖出单, 与计划矛盾. 可能是手动操作或误触. | D22: 不通过 | E22: 建议撤单, 除非有明确的日线卖点信号 | F22: 中
A23: ✓ 价格合规 | B23: 台华新材/日上集团买入价 | C23: 计划价8.30/4.18, 实际委托8.32/4.20, 偏差+0.02/+0.02, 在正常盘口范围内. | D23: 通过 | E23: — | F23: 低
A24: ✓ 仓位合规 | B24: 总仓位检查 | C24: 当前仓位35.6%, 买入委托冻结¥2,872, 若全部成交仓位≈49.2%, 低于60%上限. | D24: 通过 | E24: — | F24: 低
A25: ✓ 单股合规 | B25: 单股仓位上限 | C25: 最大持仓拱东医疗14.93%, 低于25%上限. 其他标的均合规. | D25: 通过 | E25: — | F25: 低
A26: ✓ 止损合规 | B26: 持仓止损检查 | C26: 5只持仓标的止损价均未破: 东风5.49>5.22(WAIVED), 贵绳9.17>8.44, 松芝4.72>4.23, 三力士3.39>3.02, 拱东15.78>14.10. | D26: 通过 | E26: — | F26: 低
A27: ✓ 资产核对 | B27: 账户资产一致性 | C27: Excel总资产21,142.56 vs 截图21,142.76, 差异+0.20可忽略. 可用现金从13,615降至10,740, 减少2,875≈买入委托冻结2,872(含手续费). | D27: 通过 | E27: — | F27: 低
A28: ℹ️ 可用数量 | B28: 三力士可用=0 | C28: 三力士持仓300股但可用0, 因挂了卖出300股委托. 撤单后可用恢复. | D28: 通过 | E28: 撤掉卖出单后恢复可用 | F28: 低
A29: ✓ 盈亏合理 | B29: 当日盈亏+49.02 | C29: 当日盈亏+49.02元(+0.23%), 来自4只浮盈标的的日内涨幅, 金额合理. | D29: 通过 | E29: — | F29: 低
A30: 审查结论 | C30: 发现2项违规(沃华医药违规买入+三力士违规卖出), 7项合规通过. 建议立即撤掉沃华医药买入单和三力士卖出单.

Sheet 关键变量表
A1: 类型 | B1: 变量名 | C1: Excel字段 | D1: 计算方式 | E1: 触发阈值 | F1: 影响动作 | G1: 复盘频率 | H1: 备注
A2: 生存变量 | B2: MaxDrawdown | C2: 账户总表!最大回撤 | D2: (TotalAsset-PeakAsset)/PeakAsset | E2: <=-10%, <=-15% | F2: 降总仓位/禁止新买入 | G2: 每日+周复盘 | H2: 决定系统是否降速
A3: 生存变量 | B3: 单笔止损 | C3: 持仓表!止损价 | D3: max(BuyPointLow*0.98, EntryPrice*0.92) | E3: Price<=StopPrice | F3: 次日卖出或立即卖出 | G3: 每日 | H3: 买前必须定义
A4: 生存变量 | B4: 连续亏损 | C4: 交易记录!结果分类 | D4: 近5笔亏损数 | E4: >=3笔 | F4: 暂停新开仓5个交易日 | G4: 每次成交后 | H4: 后续可扩展公式
A5: 扩张变量 | B5: 赚钱效应分数 | C5: 账户总表!赚钱效应分数 | D5: 0-5分 | E5: >=3 | F5: 允许转入/扩大执行 | G5: 周末 | H5: 强时按系数放大转入
A6: 扩张变量 | B6: 合规候选数量 | C6: 候选池!最终是否可买 | D6: COUNTIF(...,"是") | E6: >=1 | F6: 准备买入计划 | G6: 周末+盘前 | H6: 只统计规则通过标的
A7: 收缩变量 | B7: 亏钱效应分数 | C7: 账户总表!亏钱效应分数 | D7: 0-6分 | E7: >=3警戒, >=4防守 | F7: 暂停转入/提高现金 | G7: 每日+周末 | H7: 优先级高于赚钱效应
A8: 收缩变量 | B8: RiskWatch | C8: 持仓表!RiskWatch | D8: Close<EntryPrice AND DL_P<0.8 | E8: True | F8: 重点盯防 | G8: 每日 | H8: 观察不等于立即卖出
A9: 仓位变量 | B9: TotalPositionCap | C9: 账户总表!总仓位上限 | D9: 市场状态+信号等级+回撤保护 | E9: 最高70% | F9: 限制新增买入 | G9: 周一盘前 | H9: 硬性仓位上限
A10: 仓位变量 | B10: SingleStockCap | C10: 账户总表!单股上限 | D10: 按总资产分档 | E10: 20%-35% | F10: 限制单票暴露 | G10: 每日 | H10: 非WAIVED适用
A11: 仓位变量 | B11: MaxShares/MinShares | C11: 候选池!最大/最小可买股数 | D11: 100股整数约束 | E11: Max>=Min | F11: 决定是否可落地交易 | G11: 盘前 | H11: A股最小单位适配
A12: 执行变量 | B12: NotChasing | C12: 候选池!是否未追价 | D12: Price<=SignalPrice*1.02 | E12: 是 | F12: 禁止情绪追价 | G12: 盘前+盘中 | H12: 高开无回踩不买
... A22: 心态变量 | B22: 盘中看盘次数 | C22: 心态日志!盘中看盘次数 | D22: 每日看盘次数 | E22: 0次=满分 | F22: 目标逐步降至0次 | G22: 每日 | H22: 信息节食核心指标

Sheet 账户总表
A1: 日期 | B1: 总资产 TotalAsset | C1: 可用现金 CashAvailable | D1: 持仓市值 | E1: 总仓位 TotalPositionRatio | F1: 净入金 NetDeposit | G1: 阶段高点资产 PeakAsset | H1: 账户收益率 AccountReturn | I1: 最大回撤 MaxDrawdown | J1: 当前市场状态 MarketState | K1: 本周最高信号等级 | L1: 赚钱效应分数 | M1: 亏钱效应分数 | N1: 总仓位上限 TotalPositionCap | O1: 单股上限 SingleStockCap | P1: 总持仓数 | Q1: WAIVED数 | R1: 有效持仓数 | S1: 有效持仓上限 | T1: 当前状态 | U1: 是否允许转入 | V1: 是否允许新开仓 | W1: 是否暂停买入 | X1: 本周计划转入金额 | Y1: 本周计划转出金额 | Z1: 备注 | AA1: 初始本金 Principal | AB1: 目标年化收益率 TargetAnnualReturn | AC1: 运行月数 MonthsRunning | AD1: 目标资产 TargetAsset | AE1: 复利偏离度 CompoundDeviation | AF1: 交易股票数 TradeCount | AG1: 账户阶段 | AH1: 平均仓位 AvgPosition | AI1: 平均持仓天数 AvgHoldDays | AJ1: 交易成功率 SuccessRate | AK1: 资金周转率 CapitalTurnover | AL1: 做T次数 T0Count | AM1: 做T成功率 T0SuccessRate | AN1: 重仓行业 HeavySector | AO1: 投资风格 Style | AP1: 跑赢上证 BeatIndex | AQ1: 净入金后累计盈利 RealPnL | AR1: 幼儿目标资产 | AS1: 距目标差额 | AT1: 目标完成率 | AU1: 单股上限金额 | AV1: 现金比例 | AW1: 有效持仓超限数 | AX1: 允许加仓 | AY1: 本阶段核心原则
A2: 2026-01-31 | B2: 6683.54 | C2: 0 | D2: =IF($A2="","",SUMIFS(持仓表!$J:$J,持仓表!$A:$A,$A2)) -> 0 | E2: =IFERROR(D2/B2,0) -> 0 | F2: 2700 | G2: =IF($B2="","",MAX($B$2:B2)) -> 6683.54 | H2: =IFERROR((B2-$AA$2-SUM($F$2:F2))/($AA$2+SUM($F$2:F2)),0) -> -0.28773789 | I2: =IFERROR((B2-G2)/G2,0) -> 0 | J2: 中性 | K2: B | L2: 2 | M2: 2 | N2: =IF($B2="","",MIN(70%,IF($I2<=-15%,10%,IF($I2<=-10%,30%,IF($M2>=4,10%,IF($M2>=3,30%,IF($J2="强",IF($K2="A",70%,IF($K2="B",60%,40%)),IF($J2="中性",IF($K2="A",50%,IF($K2="B",40%,25%)),IF($K2="A",30%,IF($K2="B",20%,10%)))))))))) -> 0.4 | O2: =IF($B2="","",IF(B2<30000,35%,IF(B2<50000,30%,IF(B2<100000,25%,20%)))) -> 0.35 | P2: =IF($A2="","",COUNTIFS(持仓表!$A:$A,$A2,持仓表!$G:$G,">0")) -> 0 | Q2: =IF($A2="","",COUNTIFS(持仓表!$A:$A,$A2,持仓表!$D:$D,"是",持仓表!$G:$G,">0")) -> 0 | R2: =IF($A2="","",MAX(0,P2-Q2)) -> 0 | S2: =IF($B2="","",IF(B2<50000,3,IF(B2<100000,4,5))) -> 3 | T2: =IF($A2="","",IF(OR(M2>=4,I2<=-8%),"防守",IF(OR(M2>=2,I2<=-5%),"警戒","正常"))) -> 警戒 | U2: =IF($A2="","",IF(AND(L2>=3,M2<=2,T2<>"防守"),"是","否")) -> 否 | V2: =IF($A2="","",IF(AND(E2<N2,R2<S2,M2<=2,I2>-15%),"是","否")) -> 是 | W2: =IF($A2="","",IF(OR(M2>=3,I2<=-15%),"是","否")) -> 否 | X2: =IF($A2="","",IFERROR(maxifs(候选池!$AB:$AB,候选池!$A:$A,$A2),0)) -> 0 | Y2: =IF($A2="","",IF(OR(M2>=4,I2<=-8%),MAX(0,B2*60%-C2),IF(AND(ISNUMBER(AD2),B2>AD2),IF(B2<30000,0,IF(B2<100000,MAX(0,(B2-AD2)*0.2),MAX(0,(B2-AD2)*0.3))),0))) -> 0 | AA2: 6683.54 | AB2: =IF($A2="","",IF(B2<30000,0.03,IF(B2<100000,0.02,0.015))) -> 0.03 | AC2: =IF($A2="","",IFERROR(DATEDIF($A$2,$A2,"m"),0)) -> 0 | AD2: =IF($A2="","",IF(OR(AA2="",AB2="",AC2=""),"",AA2*POWER(1+AB2,AC2))) -> 6683.54 | AE2: =IF($A2="","",IF(OR(AD2="",AD2=0),"",B2/AD2-1)) -> 0 | AF2: 2 | AG2: =IF($A2="","",IF(B2<30000,"婴儿",IF(B2<100000,"成长","成熟"))) -> 婴儿 | AH2: 0.7073 | AI2: 38 | AJ2: 1 | AK2: 0.0002 | AL2: 0 | AM2: 0 | AN2: 汽车 | AO2: 小盘 | AP2: 否 | AQ2: =IF($A2="","",B2-$AA$2-SUM($F$2:F2)) -> -2700 | AR2: =IF($A2="","",30000) -> 30000 | AS2: =IF($A2="","",AR2-B2) -> 23316.46 | AT2: =IF($A2="","",IFERROR(B2/AR2,0)) -> 0.22278467 | AU2: =IF($A2="","",IFERROR(B2*O2,0)) -> 2339.239 | AV2: =IF($A2="","",IFERROR(C2/B2,0)) -> 0 | AW2: =IF($A2="","",MAX(0,R2-S2)) -> 0 | AX2: =IF($A2="","",IF(AW2>0,"优先降持仓数",IF(C2<=0,"现金不足","允许评估"))) -> 现金不足 | AY2: =IF($A2="","",IF(B2<30000,"婴儿阶段: 优先活下来,禁止单票失控,限制持仓数,服务3W目标","幼儿阶段达成")) -> 婴儿阶段: 优先活下来,禁止单票失控,限制持仓数,服务3W目标
A3: 2026-02-28 | B3: 9520.45 | C3: 0 | D3: =IF($A3="","",SUMIFS(持仓表!$J:$J,持仓表!$A:$A,$A3)) -> 0 | E3: =IFERROR(D3/B3,0) -> 0 | F3: 0 | G3: =IF($B3="","",MAX($B$2:B3)) -> 9520.45 | H3: =IFERROR((B3-$AA$2-SUM($F$2:F3))/($AA$2+SUM($F$2:F3)),0) -> 0.014590442 | I3: =IFERROR((B3-G3)/G3,0) -> 0 | J3: 强 | K3: A | L3: 3 | M3: 1 | N3: =IF($B3="","",MIN(70%,IF($I3<=-15%,10%,IF($I3<=-10%,30%,IF($M3>=4,10%,IF($M3>=3,30%,IF($J3="强",IF($K3="A",70%,IF($K3="B",60%,40%)),IF($J3="中性",IF($K3="A",50%,IF($K3="B",40%,25%)),IF($K3="A",30%,IF($K3="B",20%,10%)))))))))) -> 0.7 | O3: =IF($B3="","",IF(B3<30000,35%,IF(B3<50000,30%,IF(B3<100000,25%,20%)))) -> 0.35 | P3: =IF($A3="","",COUNTIFS(持仓表!$A:$A,$A3,持仓表!$G:$G,">0")) -> 0 | Q3: =IF($A3="","",COUNTIFS(持仓表!$A:$A,$A3,持仓表!$D:$D,"是",持仓表!$G:$G,">0")) -> 0 | R3: =IF($A3="","",MAX(0,P3-Q3)) -> 0 | S3: =IF($B3="","",IF(B3<50000,3,IF(B3<100000,4,5))) -> 3 | T3: =IF($A3="","",IF(OR(M3>=4,I3<=-8%),"防守",IF(OR(M3>=2,I3<=-5%),"警戒","正常"))) -> 正常 | U3: =IF($A3="","",IF(AND(L3>=3,M3<=2,T3<>"防守"),"是","否")) -> 是 | V3: =IF($A3="","",IF(AND(E3<N3,R3<S3,M3<=2,I3>-15%),"是","否")) -> 是 | W3: =IF($A3="","",IF(OR(M3>=3,I3<=-15%),"是","否")) -> 否 | X3: =IF($A3="","",IFERROR(maxifs(候选池!$AB:$AB,候选池!$A:$A,$A3),0)) -> 0 | Y3: =IF($A3="","",IF(OR(M3>=4,I3<=-8%),MAX(0,B3*60%-C3),IF(AND(ISNUMBER(AD3),B3>AD3),IF(B3<30000,0,IF(B3<100000,MAX(0,(B3-AD3)*0.2),MAX(0,(B3-AD3)*0.3))),0))) -> 0 | AA3: =IF($A3="","",IF($AA$2<>"",$AA$2,"")) -> 6683.54 | AB3: =IF($A3="","",IF(B3<30000,0.03,IF(B3<100000,0.02,0.015))) -> 0.03 | AC3: =IF($A3="","",IFERROR(DATEDIF($A$2,$A3,"m"),0)) -> 0 | AD3: =IF($A3="","",IF(OR(AA3="",AB3="",AC3=""),"",AA3*POWER(1+AB3,AC3))) -> 6683.54 | AE3: =IF($A3="","",IF(OR(AD3="",AD3=0),"",B3/AD3-1)) -> 0.42446219 | AF3: 1 | AG3: =IF($A3="","",IF(B3<30000,"婴儿",IF(B3<100000,"成长","成熟"))) -> 婴儿 | AH3: 0.5625 | AI3: 62 | AJ3: 1 | AK3: 0.2272 | AL3: 0 | AM3: 0 | AN3: 电子 | AO3: 中盘成长 | AP3: 是 | AQ3: =IF($A3="","",B3-$AA$2-SUM($F$2:F3)) -> 136.91 | AR3: =IF($A3="","",30000) -> 30000 | AS3: =IF($A3="","",AR3-B3) -> 20479.55 | AT3: =IF($A3="","",IFERROR(B3/AR3,0)) -> 0.31734833 | AU3: =IF($A3="","",IFERROR(B3*O3,0)) -> 3332.1575 | AV3: =IF($A3="","",IFERROR(C3/B3,0)) -> 0 | AW3: =IF($A3="","",MAX(0,R3-S3)) -> 0 | AX3: =IF($A3="","",IF(AW3>0,"优先降持仓数",IF(C3<=0,"现金不足","允许评估"))) -> 现金不足 | AY3: =IF($A3="","",IF(B3<30000,"婴儿阶段: 优先活下来,禁止单票失控,限制持仓数,服务3W目标","幼儿阶段达成")) -> 婴儿阶段: 优先活下来,禁止单票失控,限制持仓数,服务3W目标
A4: 2026-03-31 | B4: 11454.37 | C4: 0 | D4: =IF($A4="","",SUMIFS(持仓表!$J:$J,持仓表!$A:$A,$A4)) -> 0 | E4: =IFERROR(D4/B4,0) -> 0 | F4: 0 | G4: =IF($B4="","",MAX($B$2:B4)) -> 11454.37 | H4: =IFERROR((B4-$AA$2-SUM($F$2:F4))/($AA$2+SUM($F$2:F4)),0) -> 0.2206875 | I4: =IFERROR((B4-G4)/G4,0) -> 0 | J4: 弱 | K4: C | L4: 1 | M4: 3 | N4: =IF($B4="","",MIN(70%,IF($I4<=-15%,10%,IF($I4<=-10%,30%,IF($M4>=4,10%,IF($M4>=3,30%,IF($J4="强",IF($K4="A",70%,IF($K4="B",60%,40%)),IF($J4="中性",IF($K4="A",50%,IF($K4="B",40%,25%)),IF($K4="A",30%,IF($K4="B",20%,10%)))))))))) -> 0.3 | O4: =IF($B4="","",IF(B4<30000,35%,IF(B4<50000,30%,IF(B4<100000,25%,20%)))) -> 0.35 | P4: =IF($A4="","",COUNTIFS(持仓表!$A:$A,$A4,持仓表!$G:$G,">0")) -> 0 | Q4: =IF($A4="","",COUNTIFS(持仓表!$A:$A,$A4,持仓表!$D:$D,"是",持仓表!$G:$G,">0")) -> 0 | R4: =IF($A4="","",MAX(0,P4-Q4)) -> 0 | S4: =IF($B4="","",IF(B4<50000,3,IF(B4<100000,4,5))) -> 3 | T4: =IF($A4="","",IF(OR(M4>=4,I4<=-8%),"防守",IF(OR(M4>=2,I4<=-5%),"警戒","正常"))) -> 警戒 | U4: =IF($A4="","",IF(AND(L4>=3,M4<=2,T4<>"防守"),"是","否")) -> 否 | V4: =IF($A4="","",IF(AND(E4<N4,R4<S4,M4<=2,I4>-15%),"是","否")) -> 否 | W4: =IF($A4="","",IF(OR(M4>=3,I4<=-15%),"是","否")) -> 是 | X4: =IF($A4="","",IFERROR(maxifs(候选池!$AB:$AB,候选池!$A:$A,$A4),0)) -> 0 | Y4: =IF($A4="","",IF(OR(M4>=4,I4<=-8%),MAX(0,B4*60%-C4),IF(AND(ISNUMBER(AD4),B4>AD4),IF(B4<30000,0,IF(B4<100000,MAX(0,(B4-AD4)*0.2),MAX(0,(B4-AD4)*0.3))),0))) -> 0 | AA4: =IF($A4="","",IF($AA$2<>"",$AA$2,"")) -> 6683.54 | AB4: =IF($A4="","",IF(B4<30000,0.03,IF(B4<100000,0.02,0.015))) -> 0.03 | AC4: =IF($A4="","",IFERROR(DATEDIF($A$2,$A4,"m"),0)) -> 2 | AD4: =IF($A4="","",IF(OR(AA4="",AB4="",AC4=""),"",AA4*POWER(1+AB4,AC4))) -> 7090.5676 | AE4: =IF($A4="","",IF(OR(AD4="",AD4=0),"",B4/AD4-1)) -> 0.61543767 | AF4: 0 | AG4: =IF($A4="","",IF(B4<30000,"婴儿",IF(B4<100000,"成长","成熟"))) -> 婴儿 | AH4: 0.7306 | AI4: 0 | AJ4: 0 | AK4: 0 | AL4: 2 | AM4: 1 | AN4: 电子 | AO4: 中盘成长 | AP4: 是 | AQ4: =IF($A4="","",B4-$AA$2-SUM($F$2:F4)) -> 2070.83 | AR4: =IF($A4="","",30000) -> 30000 | AS4: =IF($A4="","",AR4-B4) -> 18545.63 | AT4: =IF($A4="","",IFERROR(B4/AR4,0)) -> 0.38181233 | AU4: =IF($A4="","",IFERROR(B4*O4,0)) -> 4009.0295 | AV4: =IF($A4="","",IFERROR(C4/B4,0)) -> 0 | AW4: =IF($A4="","",MAX(0,R4-S4)) -> 0 | AX4: =IF($A4="","",IF(AW4>0,"优先降持仓数",IF(C4<=0,"现金不足","允许评估"))) -> 现金不足 | AY4: =IF($A4="","",IF(B4<30000,"婴儿阶段: 优先活下来,禁止单票失控,限制持仓数,服务3W目标","幼儿阶段达成")) -> 婴儿阶段: 优先活下来,禁止单票失控,限制持仓数,服务3W目标
A5: 2026-04-30 | B5: 14148.37 | C5: 0 | D5: =IF($A5="","",SUMIFS(持仓表!$J:$J,持仓表!$A:$A,$A5)) -> 0 | E5: =IFERROR(D5/B5,0) -> 0 | F5: 0 | G5: =IF($B5="","",MAX($B$2:B5)) -> 14148.37 | H5: =IFERROR((B5-$AA$2-SUM($F$2:F5))/($AA$2+SUM($F$2:F5)),0) -> 0.50778597 | I5: =IFERROR((B5-G5)/G5,0) -> 0 | J5: 强 | K5: A | L5: 4 | M5: 1 | N5: =IF($B5="","",MIN(70%,IF($I5<=-15%,10%,IF($I5<=-10%,30%,IF($M5>=4,10%,IF($M5>=3,30%,IF($J5="强",IF($K5="A",70%,IF($K5="B",60%,40%)),IF($J5="中性",IF($K5="A",50%,IF($K5="B",40%,25%)),IF($K5="A",30%,IF($K5="B",20%,10%)))))))))) -> 0.7 | O5: =IF($B5="","",IF(B5<30000,35%,IF(B5<50000,30%,IF(B5<100000,25%,20%)))) -> 0.35 | P5: =IF($A5="","",COUNTIFS(持仓表!$A:$A,$A5,持仓表!$G:$G,">0")) -> 0 | Q5: =IF($A5="","",COUNTIFS(持仓表!$A:$A,$A5,持仓表!$D:$D,"是",持仓表!$G:$G,">0")) -> 0 | R5: =IF($A5="","",MAX(0,P5-Q5)) -> 0 | S5: =IF($B5="","",IF(B5<50000,3,IF(B5<100000,4,5))) -> 3 | T5: =IF($A5="","",IF(OR(M5>=4,I5<=-8%),"防守",IF(OR(M5>=2,I5<=-5%),"警戒","正常"))) -> 正常 | U5: =IF($A5="","",IF(AND(L5>=3,M5<=2,T5<>"防守"),"是","否")) -> 是 | V5: =IF($A5="","",IF(AND(E5<N5,R5<S5,M5<=2,I5>-15%),"是","否")) -> 是 | W5: =IF($A5="","",IF(OR(M5>=3,I5<=-15%),"是","否")) -> 否 | X5: =IF($A5="","",IFERROR(maxifs(候选池!$AB:$AB,候选池!$A:$A,$A5),0)) -> 0 | Y5: =IF($A5="","",IF(OR(M5>=4,I5<=-8%),MAX(0,B5*60%-C5),IF(AND(ISNUMBER(AD5),B5>AD5),IF(B5<30000,0,IF(B5<100000,MAX(0,(B5-AD5)*0.2),MAX(0,(B5-AD5)*0.3))),0))) -> 0 | AA5: =IF($A5="","",IF($AA$2<>"",$AA$2,"")) -> 6683.54 | AB5: =IF($A5="","",IF(B5<30000,0.03,IF(B5<100000,0.02,0.015))) -> 0.03 | AC5: =IF($A5="","",IFERROR(DATEDIF($A$2,$A5,"m"),0)) -> 2 | AD5: =IF($A5="","",IF(OR(AA5="",AB5="",AC5=""),"",AA5*POWER(1+AB5,AC5))) -> 7090.5676 | AE5: =IF($A5="","",IF(OR(AD5="",AD5=0),"",B5/AD5-1)) -> 0.99537905 | AF5: 2 | AG5: =IF($A5="","",IF(B5<30000,"婴儿",IF(B5<100000,"成长","成熟"))) -> 婴儿 | AH5: 0.7543 | AI5: 0 | AJ5: 0 | AK5: 0 | AL5: 0 | AM5: 0 | AN5: 电子 | AO5: 中盘成长 | AP5: 是 | AQ5: =IF($A5="","",B5-$AA$2-SUM($F$2:F5)) -> 4764.83 | AR5: =IF($A5="","",30000) -> 30000 | AS5: =IF($A5="","",AR5-B5) -> 15851.63 | AT5: =IF($A5="","",IFERROR(B5/AR5,0)) -> 0.47161233 | AU5: =IF($A5="","",IFERROR(B5*O5,0)) -> 4951.9295 | AV5: =IF($A5="","",IFERROR(C5/B5,0)) -> 0 | AW5: =IF($A5="","",MAX(0,R5-S5)) -> 0 | AX5: =IF($A5="","",IF(AW5>0,"优先降持仓数",IF(C5<=0,"现金不足","允许评估"))) -> 现金不足 | AY5: =IF($A5="","",IF(B5<30000,"婴儿阶段: 优先活下来,禁止单票失控,限制持仓数,服务3W目标","幼儿阶段达成")) -> 婴儿阶段: 优先活下来,禁止单票失控,限制持仓数,服务3W目标
A6: 2026-05-31 | B6: 17086.37 | C6: 0 | D6: =IF($A6="","",SUMIFS(持仓表!$J:$J,持仓表!$A:$A,$A6)) -> 0 | E6: =IFERROR(D6/B6,0) -> 0 | F6: 0 | G6: =IF($B6="","",MAX($B$2:B6)) -> 17086.37 | H6: =IFERROR((B6-$AA$2-SUM($F$2:F6))/($AA$2+SUM($F$2:F6)),0) -> 0.82088743 | I6: =IFERROR((B6-G6)/G6,0) -> 0 | J6: 强 | K6: A | L6: 4 | M6: 1 | N6: =IF($B6="","",MIN(70%,IF($I6<=-15%,10%,IF($I6<=-10%,30%,IF($M6>=4,10%,IF($M6>=3,30%,IF($J6="强",IF($K6="A",70%,IF($K6="B",60%,40%)),IF($J6="中性",IF($K6="A",50%,IF($K6="B",40%,25%)),IF($K6="A",30%,IF($K6="B",20%,10%)))))))))) -> 0.7 | O6: =IF($B6="","",IF(B6<30000,35%,IF(B6<50000,30%,IF(B6<100000,25%,20%)))) -> 0.35 | P6: =IF($A6="","",COUNTIFS(持仓表!$A:$A,$A6,持仓表!$G:$G,">0")) -> 0 | Q6: =IF($A6="","",COUNTIFS(持仓表!$A:$A,$A6,持仓表!$D:$D,"是",持仓表!$G:$G,">0")) -> 0 | R6: =IF($A6="","",MAX(0,P6-Q6)) -> 0 | S6: =IF($B6="","",IF(B6<50000,3,IF(B6<100000,4,5))) -> 3 | T6: =IF($A6="","",IF(OR(M6>=4,I6<=-8%),"防守",IF(OR(M6>=2,I6<=-5%),"警戒","正常"))) -> 正常 | U6: =IF($A6="","",IF(AND(L6>=3,M6<=2,T6<>"防守"),"是","否")) -> 是 | V6: =IF($A6="","",IF(AND(E6<N6,R6<S6,M6<=2,I6>-15%),"是","否")) -> 是 | W6: =IF($A6="","",IF(OR(M6>=3,I6<=-15%),"是","否")) -> 否 | X6: =IF($A6="","",IFERROR(maxifs(候选池!$AB:$AB,候选池!$A:$A,$A6),0)) -> 0 | Y6: =IF($A6="","",IF(OR(M6>=4,I6<=-8%),MAX(0,B6*60%-C6),IF(AND(ISNUMBER(AD6),B6>AD6),IF(B6<30000,0,IF(B6<100000,MAX(0,(B6-AD6)*0.2),MAX(0,(B6-AD6)*0.3))),0))) -> 0 | AA6: =IF($A6="","",IF($AA$2<>"",$AA$2,"")) -> 6683.54 | AB6: =IF($A6="","",IF(B6<30000,0.03,IF(B6<100000,0.02,0.015))) -> 0.03 | AC6: =IF($A6="","",IFERROR(DATEDIF($A$2,$A6,"m"),0)) -> 4 | AD6: =IF($A6="","",IF(OR(AA6="",AB6="",AC6=""),"",AA6*POWER(1+AB6,AC6))) -> 7522.3832 | AE6: =IF($A6="","",IF(OR(AD6="",AD6=0),"",B6/AD6-1)) -> 1.2714038 | AF6: 1 | AG6: =IF($A6="","",IF(B6<30000,"婴儿",IF(B6<100000,"成长","成熟"))) -> 婴儿 | AH6: 0.7849 | AI6: 0 | AJ6: 0 | AK6: 0 | AL6: 0 | AM6: 0 | AN6: 电力 | AO6: 中盘价值 | AP6: 是 | AQ6: =IF($A6="","",B6-$AA$2-SUM($F$2:F6)) -> 7702.83 | AR6: =IF($A6="","",30000) -> 30000 | AS6: =IF($A6="","",AR6-B6) -> 12913.63 | AT6: =IF($A6="","",IFERROR(B6/AR6,0)) -> 0.56954567 | AU6: =IF($A6="","",IFERROR(B6*O6,0)) -> 5980.2295 | AV6: =IF($A6="","",IFERROR(C6/B6,0)) -> 0 | AW6: =IF($A6="","",MAX(0,R6-S6)) -> 0 | AX6: =IF($A6="","",IF(AW6>0,"优先降持仓数",IF(C6<=0,"现金不足","允许评估"))) -> 现金不足 | AY6: =IF($A6="","",IF(B6<30000,"婴儿阶段: 优先活下来,禁止单票失控,限制持仓数,服务3W目标","幼儿阶段达成")) -> 婴儿阶段: 优先活下来,禁止单票失控,限制持仓数,服务3W目标
A7: 2026-06-30 | B7: 18504 | C7: 0 | D7: =IF($A7="","",SUMIFS(持仓表!$J:$J,持仓表!$A:$A,$A7)) -> 0 | E7: =IFERROR(D7/B7,0) -> 0 | F7: 0 | G7: =IF($B7="","",MAX($B$2:B7)) -> 18504 | H7: =IFERROR((B7-$AA$2-SUM($F$2:F7))/($AA$2+SUM($F$2:F7)),0) -> 0.97196367 | I7: =IFERROR((B7-G7)/G7,0) -> 0 | J7: 中性 | K7: B | L7: 3 | M7: 2 | N7: =IF($B7="","",MIN(70%,IF($I7<=-15%,10%,IF($I7<=-10%,30%,IF($M7>=4,10%,IF($M7>=3,30%,IF($J7="强",IF($K7="A",70%,IF($K7="B",60%,40%)),IF($J7="中性",IF($K7="A",50%,IF($K7="B",40%,25%)),IF($K7="A",30%,IF($K7="B",20%,10%)))))))))) -> 0.4 | O7: =IF($B7="","",IF(B7<30000,35%,IF(B7<50000,30%,IF(B7<100000,25%,20%)))) -> 0.35 | P7: =IF($A7="","",COUNTIFS(持仓表!$A:$A,$A7,持仓表!$G:$G,">0")) -> 0 | Q7: =IF($A7="","",COUNTIFS(持仓表!$A:$A,$A7,持仓表!$D:$D,"是",持仓表!$G:$G,">0")) -> 0 | R7: =IF($A7="","",MAX(0,P7-Q7)) -> 0 | S7: =IF($B7="","",IF(B7<50000,3,IF(B7<100000,4,5))) -> 3 | T7: =IF($A7="","",IF(OR(M7>=4,I7<=-8%),"防守",IF(OR(M7>=2,I7<=-5%),"警戒","正常"))) -> 警戒 | U7: =IF($A7="","",IF(AND(L7>=3,M7<=2,T7<>"防守"),"是","否")) -> 是 | V7: =IF($A7="","",IF(AND(E7<N7,R7<S7,M7<=2,I7>-15%),"是","否")) -> 是 | W7: =IF($A7="","",IF(OR(M7>=3,I7<=-15%),"是","否")) -> 否 | X7: =IF($A7="","",IFERROR(maxifs(候选池!$AB:$AB,候选池!$A:$A,$A7),0)) -> 0 | Y7: =IF($A7="","",IF(OR(M7>=4,I7<=-8%),MAX(0,B7*60%-C7),IF(AND(ISNUMBER(AD7),B7>AD7),IF(B7<30000,0,IF(B7<100000,MAX(0,(B7-AD7)*0.2),MAX(0,(B7-AD7)*0.3))),0))) -> 0 | AA7: =IF($A7="","",IF($AA$2<>"",$AA$2,"")) -> 6683.54 | AB7: =IF($A7="","",IF(B7<30000,0.03,IF(B7<100000,0.02,0.015))) -> 0.03 | AC7: =IF($A7="","",IFERROR(DATEDIF($A$2,$A7,"m"),0)) -> 4 | AD7: =IF($A7="","",IF(OR(AA7="",AB7="",AC7=""),"",AA7*POWER(1+AB7,AC7))) -> 7522.3832 | AE7: =IF($A7="","",IF(OR(AD7="",AD7=0),"",B7/AD7-1)) -> 1.4598587 | AF7: 2 | AG7: =IF($A7="","",IF(B7<30000,"婴儿",IF(B7<100000,"成长","成熟"))) -> 婴儿 | AH7: 0.7012 | AI7: 80 | AJ7: 1 | AK7: 0.3937 | AL7: 0 | AM7: 0 | AN7: 电力 | AO7: 中盘价值 | AP7: 是 | AQ7: =IF($A7="","",B7-$AA$2-SUM($F$2:F7)) -> 9120.46 | AR7: =IF($A7="","",30000) -> 30000 | AS7: =IF($A7="","",AR7-B7) -> 11496 | AT7: =IF($A7="","",IFERROR(B7/AR7,0)) -> 0.6168 | AU7: =IF($A7="","",IFERROR(B7*O7,0)) -> 6476.4 | AV7: =IF($A7="","",IFERROR(C7/B7,0)) -> 0 | AW7: =IF($A7="","",MAX(0,R7-S7)) -> 0 | AX7: =IF($A7="","",IF(AW7>0,"优先降持仓数",IF(C7<=0,"现金不足","允许评估"))) -> 现金不足 | AY7: =IF($A7="","",IF(B7<30000,"婴儿阶段: 优先活下来,禁止单票失控,限制持仓数,服务3W目标","幼儿阶段达成")) -> 婴儿阶段: 优先活下来,禁止单票失控,限制持仓数,服务3W目标
A8: 46224 | B8: 20326.12 | C8: 7847.12 | D8: =IF($A8="","",SUMIFS(持仓表!$J:$J,持仓表!$A:$A,$A8)) -> 0 | E8: =IFERROR(D8/B8,0) -> 0 | F8: 1309 | G8: =IF($B8="","",MAX($B$2:B8)) -> 20326.12 | H8: =IFERROR((B8-$AA$2-SUM($F$2:F8))/($AA$2+SUM($F$2:F8)),0) -> 0.90096273 | I8: =IFERROR((B8-G8)/G8,0) -> 0 | J8: 中性 | K8: B | L8: 3 | M8: 2 | N8: =IF($B8="","",MIN(70%,IF($I8<=-15%,10%,IF($I8<=-10%,30%,IF($M8>=4,10%,IF($M8>=3,30%,IF($J8="强",IF($K8="A",70%,IF($K8="B",60%,40%)),IF($J8="中性",IF($K8="A",50%,IF($K8="B",40%,25%)),IF($K8="A",30%,IF($K8="B",20%,10%)))))))))) -> 0.4 | O8: =IF($B8="","",IF(B8<30000,35%,IF(B8<50000,30%,IF(B8<100000,25%,20%)))) -> 0.35 | P8: =IF($A8="","",COUNTIFS(持仓表!$A:$A,$A8,持仓表!$G:$G,">0")) -> 0 | Q8: =IF($A8="","",COUNTIFS(持仓表!$A:$A,$A8,持仓表!$D:$D,"是",持仓表!$G:$G,">0")) -> 0 | R8: =IF($A8="","",MAX(0,P8-Q8)) -> 0 | S8: =IF($B8="","",IF(B8<50000,3,IF(B8<100000,4,5))) -> 3 | T8: =IF($A8="","",IF(OR(M8>=4,I8<=-8%),"防守",IF(OR(M8>=2,I8<=-5%),"警戒","正常"))) -> 警戒 | U8: =IF($A8="","",IF(AND(L8>=3,M8<=2,T8<>"防守"),"是","否")) -> 是 | V8: =IF($A8="","",IF(AND(E8<N8,R8<S8,M8<=2,I8>-15%),"是","否")) -> 是 | W8: =IF($A8="","",IF(OR(M8>=3,I8<=-15%),"是","否")) -> 否 | X8: =IF($A8="","",IFERROR(maxifs(候选池!$AB:$AB,候选池!$A:$A,$A8),0)) -> 0 | Y8: =IF($A8="","",IF(OR(M8>=4,I8<=-8%),MAX(0,B8*60%-C8),IF(AND(ISNUMBER(AD8),B8>AD8),IF(B8<30000,0,IF(B8<100000,MAX(0,(B8-AD8)*0.2),MAX(0,(B8-AD8)*0.3))),0))) -> 0 | Z8: 12:36录入,当日盈亏-143元 | AA8: =IF($A8="","",IF($AA$2<>"",$AA$2,"")) -> 6683.54 | AB8: =IF($A8="","",IF(B8<30000,0.03,IF(B8<100000,0.02,0.015))) -> 0.03 | AC8: =IF($A8="","",IFERROR(DATEDIF($A$2,$A8,"m"),0)) -> 5 | AD8: =IF($A8="","",IF(OR(AA8="",AB8="",AC8=""),"",AA8*POWER(1+AB8,AC8))) -> 7748.0546 | AE8: =IF($A8="","",IF(OR(AD8="",AD8=0),"",B8/AD8-1)) -> 1.6233837 | AF8: 2 | AG8: =IF($A8="","",IF(B8<30000,"婴儿",IF(B8<100000,"成长","成熟"))) -> 婴儿 | AH8: 0.3423 | AI8: 5 | AJ8: 1 | AK8: 0.0058 | AL8: 1 | AM8: 0 | AN8: 化工 | AO8: 大盘价值 | AP8: 是 | AQ8: =IF($A8="","",B8-$AA$2-SUM($F$2:F8)) -> 9633.58 | AR8: =IF($A8="","",30000) -> 30000 | AS8: =IF($A8="","",AR8-B8) -> 9673.88 | AT8: =IF($A8="","",IFERROR(B8/AR8,0)) -> 0.67753733 | AU8: =IF($A8="","",IFERROR(B8*O8,0)) -> 7114.142 | AV8: =IF($A8="","",IFERROR(C8/B8,0)) -> 0.38606089 | AW8: =IF($A8="","",MAX(0,R8-S8)) -> 0 | AX8: =IF($A8="","",IF(AW8>0,"优先降持仓数",IF(C8<=0,"现金不足","允许评估"))) -> 允许评估 | AY8: =IF($A8="","",IF(B8<30000,"婴儿阶段: 优先活下来,禁止单票失控,限制持仓数,服务3W目标","幼儿阶段达成")) -> 婴儿阶段: 优先活下来,禁止单票失控,限制持仓数,服务3W目标
A9: 46225 | B9: 20798.12 | C9: 7847.12 | D9: =IF($A9="","",SUMIFS(持仓表!$J:$J,持仓表!$A:$A,$A9)) -> 0 | E9: =IFERROR(D9/B9,0) -> 0 | G9: =IF($B9="","",MAX($B$2:B9)) -> 20798.12 | H9: =IFERROR((B9-$AA$2-SUM($F$2:F9))/($AA$2+SUM($F$2:F9)),0) -> 0.94510565 | I9: =IFERROR((B9-G9)/G9,0) -> 0 | N9: =IF($B9="","",MIN(70%,IF($I9<=-15%,10%,IF($I9<=-10%,30%,IF($M9>=4,10%,IF($M9>=3,30%,IF($J9="强",IF($K9="A",70%,IF($K9="B",60%,40%)),IF($J9="中性",IF($K9="A",50%,IF($K9="B",40%,25%)),IF($K9="A",30%,IF($K9="B",20%,10%)))))))))) -> 0.1 | O9: =IF($B9="","",IF(B9<30000,35%,IF(B9<50000,30%,IF(B9<100000,25%,20%)))) -> 0.35 | P9: =IF($A9="","",COUNTIFS(持仓表!$A:$A,$A9,持仓表!$G:$G,">0")) -> 0 | Q9: =IF($A9="","",COUNTIFS(持仓表!$A:$A,$A9,持仓表!$D:$D,"是",持仓表!$G:$G,">0")) -> 0 | R9: =IF($A9="","",MAX(0,P9-Q9)) -> 0 | S9: =IF($B9="","",IF(B9<50000,3,IF(B9<100000,4,5))) -> 3 | T9: =IF($A9="","",IF(OR(M9>=4,I9<=-8%),"防守",IF(OR(M9>=2,I9<=-5%),"警戒","正常"))) -> 正常 | U9: =IF($A9="","",IF(AND(L9>=3,M9<=2,T9<>"防守"),"是","否")) -> 否 | V9: =IF($A9="","",IF(AND(E9<N9,R9<S9,M9<=2,I9>-15%),"是","否")) -> 是 | W9: =IF($A9="","",IF(OR(M9>=3,I9<=-15%),"是","否")) -> 否 | X9: =IF($A9="","",IFERROR(maxifs(候选池!$AB:$AB,候选池!$A:$A,$A9),0)) -> 0 | Y9: =IF($A9="","",IF(OR(M9>=4,I9<=-8%),MAX(0,B9*60%-C9),IF(AND(ISNUMBER(AD9),B9>AD9),IF(B9<30000,0,IF(B9<100000,MAX(0,(B9-AD9)*0.2),MAX(0,(B9-AD9)*0.3))),0))) -> 0 | AA9: =IF($A9="","",IF($AA$2<>"",$AA$2,"")) -> 6683.54 | AB9: =IF($A9="","",IF(B9<30000,0.03,IF(B9<100000,0.02,0.015))) -> 0.03 | AC9: =IF($A9="","",IFERROR(DATEDIF($A$2,$A9,"m"),0)) -> 5 | AD9: =IF($A9="","",IF(OR(AA9="",AB9="",AC9=""),"",AA9*POWER(1+AB9,AC9))) -> 7748.0546 | AE9: =IF($A9="","",IF(OR(AD9="",AD9=0),"",B9/AD9-1)) -> 1.6843022 | AG9: =IF($A9="","",IF(B9<30000,"婴儿",IF(B9<100000,"成长","成熟"))) -> 婴儿 | AQ9: =IF($A9="","",B9-$AA$2-SUM($F$2:F9)) -> 10105.58 | AR9: =IF($A9="","",30000) -> 30000 | AS9: =IF($A9="","",AR9-B9) -> 9201.88 | AT9: =IF($A9="","",IFERROR(B9/AR9,0)) -> 0.69327067 | AU9: =IF($A9="","",IFERROR(B9*O9,0)) -> 7279.342 | AV9: =IF($A9="","",IFERROR(C9/B9,0)) -> 0.37729949 | AW9: =IF($A9="","",MAX(0,R9-S9)) -> 0 | AX9: =IF($A9="","",IF(AW9>0,"优先降持仓数",IF(C9<=0,"现金不足","允许评估"))) -> 允许评估 | AY9: =IF($A9="","",IF(B9<30000,"婴儿阶段: 优先活下来,禁止单票失控,限制持仓数,服务3W目标","幼儿阶段达成")) -> 婴儿阶段: 优先活下来,禁止单票失控,限制持仓数,服务3W目标
A10: 46226 | B10: 21004.83 | C10: 10362.83 | D10: =IF($A10="","",SUMIFS(持仓表!$J:$J,持仓表!$A:$A,$A10)) -> 0 | E10: =IFERROR(D10/B10,0) -> 0 | G10: =IF($B10="","",MAX($B$2:B10)) -> 21004.83 | H10: =IFERROR((B10-$AA$2-SUM($F$2:F10))/($AA$2+SUM($F$2:F10)),0) -> 0.96443782 | I10: =IFERROR((B10-G10)/G10,0) -> 0 | N10: =IF($B10="","",MIN(70%,IF($I10<=-15%,10%,IF($I10<=-10%,30%,IF($M10>=4,10%,IF($M10>=3,30%,IF($J10="强",IF($K10="A",70%,IF($K10="B",60%,40%)),IF($J10="中性",IF($K10="A",50%,IF($K10="B",40%,25%)),IF($K10="A",30%,IF($K10="B",20%,10%)))))))))) -> 0.1 | O10: =IF($B10="","",IF(B10<30000,35%,IF(B10<50000,30%,IF(B10<100000,25%,20%)))) -> 0.35 | P10: =IF($A10="","",COUNTIFS(持仓表!$A:$A,$A10,持仓表!$G:$G,">0")) -> 0 | Q10: =IF($A10="","",COUNTIFS(持仓表!$A:$A,$A10,持仓表!$D:$D,"是",持仓表!$G:$G,">0")) -> 0 | R10: =IF($A10="","",MAX(0,P10-Q10)) -> 0 | S10: =IF($B10="","",IF(B10<50000,3,IF(B10<100000,4,5))) -> 3 | T10: =IF($A10="","",IF(OR(M10>=4,I10<=-8%),"防守",IF(OR(M10>=2,I10<=-5%),"警戒","正常"))) -> 正常 | U10: =IF($A10="","",IF(AND(L10>=3,M10<=2,T10<>"防守"),"是","否")) -> 否 | V10: =IF($A10="","",IF(AND(E10<N10,R10<S10,M10<=2,I10>-15%),"是","否")) -> 是 | W10: =IF($A10="","",IF(OR(M10>=3,I10<=-15%),"是","否")) -> 否 | X10: =IF($A10="","",IFERROR(maxifs(候选池!$AB:$AB,候选池!$A:$A,$A10),0)) -> 0 | Y10: =IF($A10="","",IF(OR(M10>=4,I10<=-8%),MAX(0,B10*60%-C10),IF(AND(ISNUMBER(AD10),B10>AD10),IF(B10<30000,0,IF(B10<100000,MAX(0,(B10-AD10)*0.2),MAX(0,(B10-AD10)*0.3))),0))) -> 0 | AA10: =IF($A10="","",IF($AA$2<>"",$AA$2,"")) -> 6683.54 | AB10: =IF($A10="","",IF(B10<30000,0.03,IF(B10<100000,0.02,0.015))) -> 0.03 | AC10: =IF($A10="","",IFERROR(DATEDIF($A$2,$A10,"m"),0)) -> 5 | AD10: =IF($A10="","",IF(OR(AA10="",AB10="",AC10=""),"",AA10*POWER(1+AB10,AC10))) -> 7748.0546 | AE10: =IF($A10="","",IF(OR(AD10="",AD10=0),"",B10/AD10-1)) -> 1.7109811 | AG10: =IF($A10="","",IF(B10<30000,"婴儿",IF(B10<100000,"成长","成熟"))) -> 婴儿 | AQ10: =IF($A10="","",B10-$AA$2-SUM($F$2:F10)) -> 10312.29 | AR10: =IF($A10="","",30000) -> 30000 | AS10: =IF($A10="","",AR10-B10) -> 8995.17 | AT10: =IF($A10="","",IFERROR(B10/AR10,0)) -> 0.700161 | AU10: =IF($A10="","",IFERROR(B10*O10,0)) -> 7351.6905 | AV10: =IF($A10="","",IFERROR(C10/B10,0)) -> 0.49335462 | AW10: =IF($A10="","",MAX(0,R10-S10)) -> 0 | AX10: =IF($A10="","",IF(AW10>0,"优先降持仓数",IF(C10<=0,"现金不足","允许评估"))) -> 允许评估 | AY10: =IF($A10="","",IF(B10<30000,"婴儿阶段: 优先活下来,禁止单票失控,限制持仓数,服务3W目标","幼儿阶段达成")) -> 婴儿阶段: 优先活下来,禁止单票失控,限制持仓数,服务3W目标
A11: 46227 | B11: 20842.32 | C11: 12358.32 | D11: =IF($A11="","",SUMIFS(持仓表!$J:$J,持仓表!$A:$A,$A11)) -> 540 | E11: =IFERROR(D11/B11,0) -> 0.025908824 | F11: 0 | G11: =IF($B11="","",MAX($B$2:B11)) -> 21004.83 | H11: =IFERROR((B11-$AA$2-SUM($F$2:F11))/($AA$2+SUM($F$2:F11)),0) -> 0.94923938 | I11: =IFERROR((B11-G11)/G11,0) -> -0.007736792 | N11: =IF($B11="","",MIN(70%,IF($I11<=-15%,10%,IF($I11<=-10%,30%,IF($M11>=4,10%,IF($M11>=3,30%,IF($J11="强",IF($K11="A",70%,IF($K11="B",60%,40%)),IF($J11="中性",IF($K11="A",50%,IF($K11="B",40%,25%)),IF($K11="A",30%,IF($K11="B",20%,10%)))))))))) -> 0.1 | O11: =IF($B11="","",IF(B11<30000,35%,IF(B11<50000,30%,IF(B11<100000,25%,20%)))) -> 0.35 | P11: =IF($A11="","",COUNTIFS(持仓表!$A:$A,$A11,持仓表!$G:$G,">0")) -> 1 | Q11: =IF($A11="","",COUNTIFS(持仓表!$A:$A,$A11,持仓表!$D:$D,"是",持仓表!$G:$G,">0")) -> 1 | R11: =IF($A11="","",MAX(0,P11-Q11)) -> 0 | S11: =IF($B11="","",IF(B11<50000,3,IF(B11<100000,4,5))) -> 3 | T11: =IF($A11="","",IF(OR(M11>=4,I11<=-8%),"防守",IF(OR(M11>=2,I11<=-5%),"警戒","正常"))) -> 正常 | U11: =IF($A11="","",IF(AND(L11>=3,M11<=2,T11<>"防守"),"是","否")) -> 否 | V11: =IF($A11="","",IF(AND(E11<N11,R11<S11,M11<=2,I11>-15%),"是","否")) -> 是 | W11: =IF($A11="","",IF(OR(M11>=3,I11<=-15%),"是","否")) -> 否 | X11: =IF($A11="","",IFERROR(maxifs(候选池!$AB:$AB,候选池!$A:$A,$A11),0)) -> 0 | Y11: =IF($A11="","",IF(OR(M11>=4,I11<=-8%),MAX(0,B11*60%-C11),IF(AND(ISNUMBER(AD11),B11>AD11),IF(B11<30000,0,IF(B11<100000,MAX(0,(B11-AD11)*0.2),MAX(0,(B11-AD11)*0.3))),0))) -> 0 | AA11: =IF($A11="","",IF($AA$2<>"",$AA$2,"")) -> 6683.54 | AB11: =IF($A11="","",IF(B11<30000,0.03,IF(B11<100000,0.02,0.015))) -> 0.03 | AC11: =IF($A11="","",IFERROR(DATEDIF($A$2,$A11,"m"),0)) -> 5 | AD11: =IF($A11="","",IF(OR(AA11="",AB11="",AC11=""),"",AA11*POWER(1+AB11,AC11))) -> 7748.0546 | AE11: =IF($A11="","",IF(OR(AD11="",AD11=0),"",B11/AD11-1)) -> 1.6900068 | AG11: =IF($A11="","",IF(B11<30000,"婴儿",IF(B11<100000,"成长","成熟"))) -> 婴儿 | AQ11: =IF($A11="","",B11-$AA$2-SUM($F$2:F11)) -> 10149.78 | AR11: =IF($A11="","",30000) -> 30000 | AS11: =IF($A11="","",AR11-B11) -> 9157.68 | AT11: =IF($A11="","",IFERROR(B11/AR11,0)) -> 0.694744 | AU11: =IF($A11="","",IFERROR(B11*O11,0)) -> 7294.812 | AV11: =IF($A11="","",IFERROR(C11/B11,0)) -> 0.59294359 | AW11: =IF($A11="","",MAX(0,R11-S11)) -> 0 | AX11: =IF($A11="","",IF(AW11>0,"优先降持仓数",IF(C11<=0,"现金不足","允许评估"))) -> 允许评估 | AY11: =IF($A11="","",IF(B11<30000,"婴儿阶段: 优先活下来,禁止单票失控,限制持仓数,服务3W目标","幼儿阶段达成")) -> 婴儿阶段: 优先活下来,禁止单票失控,限制持仓数,服务3W目标
A12: 46230 | B12: 20842.92 | C12: 12599.63 | D12: =IF($A12="","",SUMIFS(持仓表!$J:$J,持仓表!$A:$A,$A12)) -> 2384 | E12: =IFERROR(D12/B12,0) -> 0.11437937 | G12: =IF($B12="","",MAX($B$2:B12)) -> 21004.83 | H12: =IFERROR((B12-$AA$2-SUM($F$2:F12))/($AA$2+SUM($F$2:F12)),0) -> 0.94929549 | I12: =IFERROR((B12-G12)/G12,0) -> -0.0077082271 | N12: =IF($B12="","",MIN(70%,IF($I12<=-15%,10%,IF($I12<=-10%,30%,IF($M12>=4,10%,IF($M12>=3,30%,IF($J12="强",IF($K12="A",70%,IF($K12="B",60%,40%)),IF($J12="中性",IF($K12="A",50%,IF($K12="B",40%,25%)),IF($K12="A",30%,IF($K12="B",20%,10%)))))))))) -> 0.1 | O12: =IF($B12="","",IF(B12<30000,35%,IF(B12<50000,30%,IF(B12<100000,25%,20%)))) -> 0.35 | P12: =IF($A12="","",COUNTIFS(持仓表!$A:$A,$A12,持仓表!$G:$G,">0")) -> 2 | Q12: =IF($A12="","",COUNTIFS(持仓表!$A:$A,$A12,持仓表!$D:$D,"是",持仓表!$G:$G,">0")) -> 0 | R12: =IF($A12="","",MAX(0,P12-Q12)) -> 2 | S12: =IF($B12="","",IF(B12<50000,3,IF(B12<100000,4,5))) -> 3 | T12: =IF($A12="","",IF(OR(M12>=4,I12<=-8%),"防守",IF(OR(M12>=2,I12<=-5%),"警戒","正常"))) -> 正常 | U12: =IF($A12="","",IF(AND(L12>=3,M12<=2,T12<>"防守"),"是","否")) -> 否 | V12: =IF($A12="","",IF(AND(E12<N12,R12<S12,M12<=2,I12>-15%),"是","否")) -> 否 | W12: =IF($A12="","",IF(OR(M12>=3,I12<=-15%),"是","否")) -> 否 | X12: =IF($A12="","",IFERROR(maxifs(候选池!$AB:$AB,候选池!$A:$A,$A12),0)) -> 0 | Y12: =IF($A12="","",IF(OR(M12>=4,I12<=-8%),MAX(0,B12*60%-C12),IF(AND(ISNUMBER(AD12),B12>AD12),IF(B12<30000,0,IF(B12<100000,MAX(0,(B12-AD12)*0.2),MAX(0,(B12-AD12)*0.3))),0))) -> 0 | AA12: =IF($A12="","",IF($AA$2<>"",$AA$2,"")) -> 6683.54 | AB12: =IF($A12="","",IF(B12<30000,0.03,IF(B12<100000,0.02,0.015))) -> 0.03 | AC12: =IF($A12="","",IFERROR(DATEDIF($A$2,$A12,"m"),0)) -> 5 | AD12: =IF($A12="","",IF(OR(AA12="",AB12="",AC12=""),"",AA12*POWER(1+AB12,AC12))) -> 7748.0546 | AE12: =IF($A12="","",IF(OR(AD12="",AD12=0),"",B12/AD12-1)) -> 1.6900843 | AG12: =IF($A12="","",IF(B12<30000,"婴儿",IF(B12<100000,"成长","成熟"))) -> 婴儿 | AQ12: =IF($A12="","",B12-$AA$2-SUM($F$2:F12)) -> 10150.38 | AR12: =IF($A12="","",30000) -> 30000 | AS12: =IF($A12="","",AR12-B12) -> 9157.08 | AT12: =IF($A12="","",IFERROR(B12/AR12,0)) -> 0.694764 | AU12: =IF($A12="","",IFERROR(B12*O12,0)) -> 7295.022 | AV12: =IF($A12="","",IFERROR(C12/B12,0)) -> 0.60450407 | AW12: =IF($A12="","",MAX(0,R12-S12)) -> 0 | AX12: =IF($A12="","",IF(AW12>0,"优先降持仓数",IF(C12<=0,"现金不足","允许评估"))) -> 允许评估 | AY12: =IF($A12="","",IF(B12<30000,"婴儿阶段: 优先活下来,禁止单票失控,限制持仓数,服务3W目标","幼儿阶段达成")) -> 婴儿阶段: 优先活下来,禁止单票失控,限制持仓数,服务3W目标
A13: 46231 | B13: 21142.56 | C13: 13615.56 | D13: =IF($A13="","",SUMIFS(持仓表!$J:$J,持仓表!$A:$A,$A13)) -> 7544 | E13: =IFERROR(D13/B13,0) -> 0.35681583 | F13: 0 | G13: =IF($B13="","",MAX($B$2:B13)) -> 21142.56 | H13: =IFERROR((B13-$AA$2-SUM($F$2:F13))/($AA$2+SUM($F$2:F13)),0) -> 0.97731877 | I13: =IFERROR((B13-G13)/G13,0) -> 0 | J13: 中性偏弱 | K13: B | L13: 2 | M13: 2 | N13: =IF($B13="","",MIN(70%,IF($I13<=-15%,10%,IF($I13<=-10%,30%,IF($M13>=4,10%,IF($M13>=3,30%,IF($J13="强",IF($K13="A",70%,IF($K13="B",60%,40%)),IF($J13="中性",IF($K13="A",50%,IF($K13="B",40%,25%)),IF($K13="A",30%,IF($K13="B",20%,10%)))))))))) -> 0.2 | O13: =IF($B13="","",IF(B13<30000,35%,IF(B13<50000,30%,IF(B13<100000,25%,20%)))) -> 0.35 | P13: =IF($A13="","",COUNTIFS(持仓表!$A:$A,$A13,持仓表!$G:$G,">0")) -> 6 | Q13: =IF($A13="","",COUNTIFS(持仓表!$A:$A,$A13,持仓表!$D:$D,"是",持仓表!$G:$G,">0")) -> 2 | R13: =IF($A13="","",MAX(0,P13-Q13)) -> 4 | S13: =IF($B13="","",IF(B13<50000,3,IF(B13<100000,4,5))) -> 3 | T13: =IF($A13="","",IF(OR(M13>=4,I13<=-8%),"防守",IF(OR(M13>=2,I13<=-5%),"警戒","正常"))) -> 警戒 | U13: =IF($A13="","",IF(AND(L13>=3,M13<=2,T13<>"防守"),"是","否")) -> 否 | V13: =IF($A13="","",IF(AND(E13<N13,R13<S13,M13<=2,I13>-15%),"是","否")) -> 否 | W13: =IF($A13="","",IF(OR(M13>=3,I13<=-15%),"是","否")) -> 否 | X13: =IF($A13="","",IFERROR(maxifs(候选池!$AB:$AB,候选池!$A:$A,$A13),0)) -> 0 | Y13: 合规审查: 2项违规(沃华医药违规买入+三力士违规卖出), 建议撤单 | AA13: =IF($A13="","",IF($AA$2<>"",$AA$2,"")) -> 6683.54 | AB13: =IF($A13="","",IF(B13<30000,0.03,IF(B13<100000,0.02,0.015))) -> 0.03 | AC13: =IF($A13="","",IFERROR(DATEDIF($A$2,$A13,"m"),0)) -> 5 | AD13: =IF($A13="","",IF(OR(AA13="",AB13="",AC13=""),"",AA13*POWER(1+AB13,AC13))) -> 7748.0546 | AE13: =IF($A13="","",IF(OR(AD13="",AD13=0),"",B13/AD13-1)) -> 1.7287572 | AG13: =IF($A13="","",IF(B13<30000,"婴儿",IF(B13<100000,"成长","成熟"))) -> 婴儿 | AQ13: =IF($A13="","",B13-$AA$2-SUM($F$2:F13)) -> 10450.02 | AR13: =IF($A13="","",30000) -> 30000 | AS13: =IF($A13="","",AR13-B13) -> 8857.44 | AT13: =IF($A13="","",IFERROR(B13/AR13,0)) -> 0.704752 | AU13: =IF($A13="","",IFERROR(B13*O13,0)) -> 7399.896 | AV13: =IF($A13="","",IFERROR(C13/B13,0)) -> 0.64398824 | AW13: =IF($A13="","",MAX(0,R13-S13)) -> 1 | AX13: =IF($A13="","",IF(AW13>0,"优先降持仓数",IF(C13<=0,"现金不足","允许评估"))) -> 优先降持仓数 | AY13: =IF($A13="","",IF(B13<30000,"婴儿阶段: 优先活下来,禁止单票失控,限制持仓数,服务3W目标","幼儿阶段达成")) -> 婴儿阶段: 优先活下来,禁止单票失控,限制持仓数,服务3W目标
A14: 46232 | B14: 21311.32 | C14: 9793.32 | D14: 11514 | E14: =IFERROR(D14/B14,0) -> 0.54027625 | F14: 8 | G14: =IF($B14="","",MAX($B$2:B14)) -> 21311.32 | H14: =IFERROR((B14-$AA$2-SUM($F$2:F14))/($AA$2+SUM($F$2:F14)),0) -> 0.99161164 | I14: =IFERROR((B14-G14)/G14,0) -> 0 | N14: =IF($B14="","",MIN(70%,IF($I14<=-15%,10%,IF($I14<=-10%,30%,IF($M14>=4,10%,IF($M14>=3,30%,IF($J14="强",IF($K14="A",70%,IF($K14="B",60%,40%)),IF($J14="中性",IF($K14="A",50%,IF($K14="B",40%,25%)),IF($K14="A",30%,IF($K14="B",20%,10%)))))))))) -> 0.1 | O14: =IF($B14="","",IF(B14<30000,35%,IF(B14<50000,30%,IF(B14<100000,25%,20%)))) -> 0.35 | P14: =IF($A14="","",COUNTIFS(持仓表!$A:$A,$A14,持仓表!$G:$G,">0")) -> 6 | Q14: =IF($A14="","",COUNTIFS(持仓表!$A:$A,$A14,持仓表!$D:$D,"是",持仓表!$G:$G,">0")) -> 1 | R14: =IF($A14="","",MAX(0,P14-Q14)) -> 5 | S14: =IF($B14="","",IF(B14<50000,3,IF(B14<100000,4,5))) -> 3 | T14: =IF($A14="","",IF(OR(M14>=4,I14<=-8%),"防守",IF(OR(M14>=2,I14<=-5%),"警戒","正常"))) -> 正常 | U14: =IF($A14="","",IF(AND(L14>=3,M14<=2,T14<>"防守"),"是","否")) -> 否 | V14: =IF($A14="","",IF(AND(E14<N14,R14<S14,M14<=2,I14>-15%),"是","否")) -> 否 | W14: =IF($A14="","",IF(OR(M14>=3,I14<=-15%),"是","否")) -> 否 | X14: =IF($A14="","",IFERROR(maxifs(候选池!$AB:$AB,候选池!$A:$A,$A14),0)) -> 0 | Y14: =IF($A14="","",IF(OR(M14>=4,I14<=-8%),MAX(0,B14*60%-C14),IF(AND(ISNUMBER(AD14),B14>AD14),IF(B14<30000,0,IF(B14<100000,MAX(0,(B14-AD14)*0.2),MAX(0,(B14-AD14)*0.3))),0))) -> 0 | AA14: =IF($A14="","",IF($AA$2<>"",$AA$2,"")) -> 6683.54 | AB14: =IF($A14="","",IF(B14<30000,0.03,IF(B14<100000,0.02,0.015))) -> 0.03 | AC14: =IF($A14="","",IFERROR(DATEDIF($A$2,$A14,"m"),0)) -> 5 | AD14: =IF($A14="","",IF(OR(AA14="",AB14="",AC14=""),"",AA14*POWER(1+AB14,AC14))) -> 7748.0546 | AE14: =IF($A14="","",IF(OR(AD14="",AD14=0),"",B14/AD14-1)) -> 1.7505382 | AG14: =IF($A14="","",IF(B14<30000,"婴儿",IF(B14<100000,"成长","成熟"))) -> 婴儿 | AQ14: =IF($A14="","",B14-$AA$2-SUM($F$2:F17)) -> 10610.78 | AR14: =IF($A14="","",30000) -> 30000 | AS14: =IF($A14="","",AR14-B14) -> 8688.68 | AT14: =IF($A14="","",IFERROR(B14/AR14,0)) -> 0.71037733 | AU14: =IF($A14="","",IFERROR(B14*O14,0)) -> 7458.962 | AV14: =IF($A14="","",IFERROR(C14/B14,0)) -> 0.45953606 | AW14: =IF($A14="","",MAX(0,R14-S14)) -> 2 | AX14: =IF($A14="","",IF(AW14>0,"优先降持仓数",IF(C14<=0,"现金不足","允许评估"))) -> 优先降持仓数 | AY14: =IF($A14="","",IF(B14<30000,"婴儿阶段: 优先活下来,禁止单票失控,限制持仓数,服务3W目标","幼儿阶段达成")) -> 婴儿阶段: 优先活下来,禁止单票失控,限制持仓数,服务3W目标
A15: 46233.739 | B15: 21220.1 | C15: 13376.1 | D15: 7844 | E15: =IFERROR(D15/B15,0) -> 0.36964953 | F15: 0 | G15: =IF($B15="","",MAX($B$2:B16)) -> 21311.32 | H15: =IFERROR((B15-$AA$2-SUM($F$2:F16))/($AA$2+SUM($F$2:F16)),0) -> 0.98308683 | I15: =IFERROR((B15-G15)/G15,0) -> -0.0042803543 | N15: =IF($B15="","",MIN(70%,IF($I15<=-15%,10%,IF($I15<=-10%,30%,IF($M15>=4,10%,IF($M15>=3,30%,IF($J15="强",IF($K15="A",70%,IF($K15="B",60%,40%)),IF($J15="中性",IF($K15="A",50%,IF($K15="B",40%,25%)),IF($K15="A",30%,IF($K15="B",20%,10%)))))))))) -> 0.1 | O15: =IF($B15="","",IF(B15<30000,35%,IF(B15<50000,30%,IF(B15<100000,25%,20%)))) -> 0.35 | P15: =IF($A15="","",COUNTIFS(持仓表!$A:$A,$A15,持仓表!$G:$G,">0")) -> 0 | Q15: =IF($A15="","",COUNTIFS(持仓表!$A:$A,$A15,持仓表!$D:$D,"是",持仓表!$G:$G,">0")) -> 0 | R15: =IF($A15="","",MAX(0,P15-Q15)) -> 0 | S15: =IF($B15="","",IF(B15<50000,3,IF(B15<100000,4,5))) -> 3 | T15: =IF($A15="","",IF(OR(M15>=4,I15<=-8%),"防守",IF(OR(M15>=2,I15<=-5%),"警戒","正常"))) -> 正常 | U15: =IF($A15="","",IF(AND(L15>=3,M15<=2,T15<>"防守"),"是","否")) -> 否 | V15: =IF($A15="","",IF(AND(E15<N15,R15<S15,M15<=2,I15>-15%),"是","否")) -> 否 | W15: =IF($A15="","",IF(OR(M15>=3,I15<=-15%),"是","否")) -> 否 | X15: =IF($A15="","",IFERROR(maxifs(候选池!$AB:$AB,候选池!$A:$A,$A15),0)) -> 0 | Y15: =IF($A15="","",IF(OR(M15>=4,I15<=-8%),MAX(0,B15*60%-C15),IF(AND(ISNUMBER(AD15),B15>AD15),IF(B15<30000,0,IF(B15<100000,MAX(0,(B15-AD15)*0.2),MAX(0,(B15-AD15)*0.3))),0))) -> 0 | Z15: 当日盈亏: -82.22 | AA15: =IF($A15="","",IF($AA$2<>"",$AA$2,"")) -> 6683.54 | AB15: =IF($A15="","",IF(B15<30000,0.03,IF(B15<100000,0.02,0.015))) -> 0.03 | AC15: =IF($A15="","",IFERROR(DATEDIF($A$2,$A15,"m"),0)) -> 5 | AD15: =IF($A15="","",IF(OR(AA15="",AB15="",AC15=""),"",AA15*POWER(1+AB15,AC15))) -> 7748.0546 | AE15: =IF($A15="","",IF(OR(AD15="",AD15=0),"",B15/AD15-1)) -> 1.7387649 | AG15: =IF($A15="","",IF(B15<30000,"婴儿",IF(B15<100000,"成长","成熟"))) -> 婴儿 | AQ15: =IF($A15="","",B15-$AA$2-SUM($F$2:F17)) -> 10519.56 | AR15: =IF($A15="","",30000) -> 30000 | AS15: =IF($A15="","",AR15-B15) -> 8779.9 | AT15: =IF($A15="","",IFERROR(B15/AR15,0)) -> 0.70733667 | AU15: =IF($A15="","",IFERROR(B15*O15,0)) -> 7427.035 | AV15: =IF($A15="","",IFERROR(C15/B15,0)) -> 0.63035047 | AW15: =IF($A15="","",MAX(0,R15-S15)) -> 0 | AX15: =IF($A15="","",IF(AW15>0,"优先降持仓数",IF(C15<=0,"现金不足","允许评估"))) -> 允许评估 | AY15: =IF($A15="","",IF(B15<30000,"婴儿阶段: 优先活下来,禁止单票失控,限制持仓数,服务3W目标","幼儿阶段达成")) -> 婴儿阶段: 优先活下来,禁止单票失控,限制持仓数,服务3W目标
D16: =IF($A21="","",SUMIFS(持仓表!$J:$J,持仓表!$A:$A,$A21)) | E16: =IFERROR(D21/B21,0) -> 0 | G16: =IF($B21="","",MAX($B$2:B21)) | H16: =IFERROR((B21-F21)/F21,0) -> 0 | I16: =IFERROR((B21-G21)/G21,0) -> 0 | N16: =IF($B21="","",MIN(70%,IF($I21<=-15%,10%,IF($I21<=-10%,30%,IF($M21>=4,10%,IF($M21>=3,30%,IF($J21="强",IF($K21="A",70%,IF($K21="B",60%,40%)),IF($J21="中性",IF($K21="A",50%,IF($K21="B",40%,25%)),IF($K21="A",30%,IF($K21="B",20%,10%)))))))))) | O16: =IF($B21="","",IF(B21<30000,35%,IF(B21<50000,30%,IF(B21<100000,25%,20%)))) | P16: =IF($A21="","",COUNTIFS(持仓表!$A:$A,$A21,持仓表!$G:$G,">0")) | Q16: =IF($A21="","",COUNTIFS(持仓表!$A:$A,$A21,持仓表!$D:$D,"是",持仓表!$G:$G,">0")) | R16: =IF($A21="","",MAX(0,P21-Q21)) | S16: =IF($B21="","",IF(B21<50000,3,IF(B21<100000,4,5))) | T16: =IF($A21="","",IF(OR(M21>=4,I21<=-8%),"防守",IF(OR(M21>=2,I21<=-5%),"警戒","正常"))) | U16: =IF($A21="","",IF(AND(L21>=3,M21<=2,T21<>"防守"),"是","否")) | V16: =IF($A21="","",IF(AND(E21<N21,R21<S21,M21<=2,I21>-15%),"是","否")) | W16: =IF($A21="","",IF(OR(M21>=3,I21<=-15%),"是","否")) | X16: =IF($A21="","",IFERROR(maxifs(候选池!$AB:$AB,候选池!$A:$A,$A21),0)) | Y16: =IF($A21="","",IF(OR(M21>=4,I21<=-8%),MAX(0,B21*60%-C21),IF(AND(ISNUMBER(AD21),B21>AD21),IF(B21<30000,0,IF(B21<100000,MAX(0,(B21-AD21)*0.2),MAX(0,(B21-AD21)*0.3))),0))) | AA16: =IF($A21="","",IF($AA$2<>"",$AA$2,"")) | AB16: =IF($A21="","",IF(B21<30000,0.03,IF(B21<100000,0.02,0.015))) | AC16: =IF($A21="","",IFERROR(DATEDIF($A$2,$A21,"m"),0)) | AD16: =IF($A21="","",IF(OR(AA21="",AB21="",AC21=""),"",AA21*POWER(1+AB21,AC21))) | AE16: =IF($A21="","",IF(OR(AD21="",AD21=0),"",B21/AD21-1)) | AG16: =IF($A21="","",IF(B21<30000,"婴儿",IF(B21<100000,"成长","成熟"))) | AQ16: =IF($A21="","",B21-$AA$2-SUM($F$2:F21)) | AR16: =IF($A20="","",30000) | AS16: =IF($A20="","",AR20-B20) | AT16: =IF($A20="","",IFERROR(B20/AR20,0)) | AU16: =IF($A20="","",IFERROR(B20*O20,0)) | AV16: =IF($A20="","",IFERROR(C20/B20,0)) | AW16: =IF($A20="","",MAX(0,R20-S20)) | AX16: =IF($A20="","",IF(AW20>0,"优先降持仓数",IF(C20<=0,"现金不足","允许评估"))) | AY16: =IF($A20="","",IF(B20<30000,"婴儿阶段: 优先活下来,禁止单票失控,限制持仓数,服务3W目标","幼儿阶段达成"))
D17: =IF($A22="","",SUMIFS(持仓表!$J:$J,持仓表!$A:$A,$A22)) | E17: =IFERROR(D22/B22,0) -> 0 | G17: =IF($B22="","",MAX($B$2:B22)) | H17: =IFERROR((B22-F22)/F22,0) -> 0 | I17: =IFERROR((B22-G22)/G22,0) -> 0 | N17: =IF($B22="","",MIN(70%,IF($I22<=-15%,10%,IF($I22<=-10%,30%,IF($M22>=4,10%,IF($M22>=3,30%,IF($J22="强",IF($K22="A",70%,IF($K22="B",60%,40%)),IF($J22="中性",IF($K22="A",50%,IF($K22="B",40%,25%)),IF($K22="A",30%,IF($K22="B",20%,10%)))))))))) | O17: =IF($B22="","",IF(B22<30000,35%,IF(B22<50000,30%,IF(B22<100000,25%,20%)))) | P17: =IF($A22="","",COUNTIFS(持仓表!$A:$A,$A22,持仓表!$G:$G,">0")) | Q17: =IF($A22="","",COUNTIFS(持仓表!$A:$A,$A22,持仓表!$D:$D,"是",持仓表!$G:$G,">0")) | R17: =IF($A22="","",MAX(0,P22-Q22)) | S17: =IF($B22="","",IF(B22<50000,3,IF(B22<100000,4,5))) | T17: =IF($A22="","",IF(OR(M22>=4,I22<=-8%),"防守",IF(OR(M22>=2,I22<=-5%),"警戒","正常"))) | U17: =IF($A22="","",IF(AND(L22>=3,M22<=2,T22<>"防守"),"是","否")) | V17: =IF($A22="","",IF(AND(E22<N22,R22<S22,M22<=2,I22>-15%),"是","否")) | W17: =IF($A22="","",IF(OR(M22>=3,I22<=-15%),"是","否")) | X17: =IF($A22="","",IFERROR(maxifs(候选池!$AB:$AB,候选池!$A:$A,$A22),0)) | Y17: =IF($A22="","",IF(OR(M22>=4,I22<=-8%),MAX(0,B22*60%-C22),IF(AND(ISNUMBER(AD22),B22>AD22),IF(B22<30000,0,IF(B22<100000,MAX(0,(B22-AD22)*0.2),MAX(0,(B22-AD22)*0.3))),0))) | AA17: =IF($A22="","",IF($AA$2<>"",$AA$2,"")) | AB17: =IF($A22="","",IF(B22<30000,0.03,IF(B22<100000,0.02,0.015))) | AC17: =IF($A22="","",IFERROR(DATEDIF($A$2,$A22,"m"),0)) | AD17: =IF($A22="","",IF(OR(AA22="",AB22="",AC22=""),"",AA22*POWER(1+AB22,AC22))) | AE17: =IF($A22="","",IF(OR(AD22="",AD22=0),"",B22/AD22-1)) | AG17: =IF($A22="","",IF(B22<30000,"婴儿",IF(B22<100000,"成长","成熟"))) | AQ17: =IF($A22="","",B22-$AA$2-SUM($F$2:F22)) | AR17: =IF($A21="","",30000) | AS17: =IF($A21="","",AR21-B21) | AT17: =IF($A21="","",IFERROR(B21/AR21,0)) | AU17: =IF($A21="","",IFERROR(B21*O21,0)) | AV17: =IF($A21="","",IFERROR(C21/B21,0)) | AW17: =IF($A21="","",MAX(0,R21-S21)) | AX17: =IF($A21="","",IF(AW21>0,"优先降持仓数",IF(C21<=0,"现金不足","允许评估"))) | AY17: =IF($A21="","",IF(B21<30000,"婴儿阶段: 优先活下来,禁止单票失控,限制持仓数,服务3W目标","幼儿阶段达成"))
D18: =IF($A23="","",SUMIFS(持仓表!$J:$J,持仓表!$A:$A,$A23)) | E18: =IFERROR(D23/B23,0) -> 0 | G18: =IF($B23="","",MAX($B$2:B23)) | H18: =IFERROR((B23-F23)/F23,0) -> 0 | I18: =IFERROR((B23-G23)/G23,0) -> 0 | N18: =IF($B23="","",MIN(70%,IF($I23<=-15%,10%,IF($I23<=-10%,30%,IF($M23>=4,10%,IF($M23>=3,30%,IF($J23="强",IF($K23="A",70%,IF($K23="B",60%,40%)),IF($J23="中性",IF($K23="A",50%,IF($K23="B",40%,25%)),IF($K23="A",30%,IF($K23="B",20%,10%)))))))))) | O18: =IF($B23="","",IF(B23<30000,35%,IF(B23<50000,30%,IF(B23<100000,25%,20%)))) | P18: =IF($A23="","",COUNTIFS(持仓表!$A:$A,$A23,持仓表!$G:$G,">0")) | Q18: =IF($A23="","",COUNTIFS(持仓表!$A:$A,$A23,持仓表!$D:$D,"是",持仓表!$G:$G,">0")) | R18: =IF($A23="","",MAX(0,P23-Q23)) | S18: =IF($B23="","",IF(B23<50000,3,IF(B23<100000,4,5))) | T18: =IF($A23="","",IF(OR(M23>=4,I23<=-8%),"防守",IF(OR(M23>=2,I23<=-5%),"警戒","正常"))) | U18: =IF($A23="","",IF(AND(L23>=3,M23<=2,T23<>"防守"),"是","否")) | V18: =IF($A23="","",IF(AND(E23<N23,R23<S23,M23<=2,I23>-15%),"是","否")) | W18: =IF($A23="","",IF(OR(M23>=3,I23<=-15%),"是","否")) | X18: =IF($A23="","",IFERROR(maxifs(候选池!$AB:$AB,候选池!$A:$A,$A23),0)) | Y18: =IF($A23="","",IF(OR(M23>=4,I23<=-8%),MAX(0,B23*60%-C23),IF(AND(ISNUMBER(AD23),B23>AD23),IF(B23<30000,0,IF(B23<100000,MAX(0,(B23-AD23)*0.2),MAX(0,(B23-AD23)*0.3))),0))) | AA18: =IF($A23="","",IF($AA$2<>"",$AA$2,"")) | AB18: =IF($A23="","",IF(B23<30000,0.03,IF(B23<100000,0.02,0.015))) | AC18: =IF($A23="","",IFERROR(DATEDIF($A$2,$A23,"m"),0)) | AD18: =IF($A23="","",IF(OR(AA23="",AB23="",AC23=""),"",AA23*POWER(1+AB23,AC23))) | AE18: =IF($A23="","",IF(OR(AD23="",AD23=0),"",B23/AD23-1)) | AG18: =IF($A23="","",IF(B23<30000,"婴儿",IF(B23<100000,"成长","成熟"))) | AQ18: =IF($A23="","",B23-$AA$2-SUM($F$2:F23)) | AR18: =IF($A22="","",30000) | AS18: =IF($A22="","",AR22-B22) | AT18: =IF($A22="","",IFERROR(B22/AR22,0)) | AU18: =IF($A22="","",IFERROR(B22*O22,0)) | AV18: =IF($A22="","",IFERROR(C22/B22,0)) | AW18: =IF($A22="","",MAX(0,R22-S22)) | AX18: =IF($A22="","",IF(AW22>0,"优先降持仓数",IF(C22<=0,"现金不足","允许评估"))) | AY18: =IF($A22="","",IF(B22<30000,"婴儿阶段: 优先活下来,禁止单票失控,限制持仓数,服务3W目标","幼儿阶段达成"))
D19: =IF($A24="","",SUMIFS(持仓表!$J:$J,持仓表!$A:$A,$A24)) | E19: =IFERROR(D24/B24,0) -> 0 | G19: =IF($B24="","",MAX($B$2:B24)) | H19: =IFERROR((B24-F24)/F24,0) -> 0 | I19: =IFERROR((B24-G24)/G24,0) -> 0 | N19: =IF($B24="","",MIN(70%,IF($I24<=-15%,10%,IF($I24<=-10%,30%,IF($M24>=4,10%,IF($M24>=3,30%,IF($J24="强",IF($K24="A",70%,IF($K24="B",60%,40%)),IF($J24="中性",IF($K24="A",50%,IF($K24="B",40%,25%)),IF($K24="A",30%,IF($K24="B",20%,10%)))))))))) | O19: =IF($B24="","",IF(B24<30000,35%,IF(B24<50000,30%,IF(B24<100000,25%,20%)))) | P19: =IF($A24="","",COUNTIFS(持仓表!$A:$A,$A24,持仓表!$G:$G,">0")) | Q19: =IF($A24="","",COUNTIFS(持仓表!$A:$A,$A24,持仓表!$D:$D,"是",持仓表!$G:$G,">0")) | R19: =IF($A24="","",MAX(0,P24-Q24)) | S19: =IF($B24="","",IF(B24<50000,3,IF(B24<100000,4,5))) | T19: =IF($A24="","",IF(OR(M24>=4,I24<=-8%),"防守",IF(OR(M24>=2,I24<=-5%),"警戒","正常"))) | U19: =IF($A24="","",IF(AND(L24>=3,M24<=2,T24<>"防守"),"是","否")) | V19: =IF($A24="","",IF(AND(E24<N24,R24<S24,M24<=2,I24>-15%),"是","否")) | W19: =IF($A24="","",IF(OR(M24>=3,I24<=-15%),"是","否")) | X19: =IF($A24="","",IFERROR(maxifs(候选池!$AB:$AB,候选池!$A:$A,$A24),0)) | Y19: =IF($A24="","",IF(OR(M24>=4,I24<=-8%),MAX(0,B24*60%-C24),IF(AND(ISNUMBER(AD24),B24>AD24),IF(B24<30000,0,IF(B24<100000,MAX(0,(B24-AD24)*0.2),MAX(0,(B24-AD24)*0.3))),0))) | AA19: =IF($A24="","",IF($AA$2<>"",$AA$2,"")) | AB19: =IF($A24="","",IF(B24<30000,0.03,IF(B24<100000,0.02,0.015))) | AC19: =IF($A24="","",IFERROR(DATEDIF($A$2,$A24,"m"),0)) | AD19: =IF($A24="","",IF(OR(AA24="",AB24="",AC24=""),"",AA24*POWER(1+AB24,AC24))) | AE19: =IF($A24="","",IF(OR(AD24="",AD24=0),"",B24/AD24-1)) | AG19: =IF($A24="","",IF(B24<30000,"婴儿",IF(B24<100000,"成长","成熟"))) | AQ19: =IF($A24="","",B24-$AA$2-SUM($F$2:F24)) | AR19: =IF($A23="","",30000) | AS19: =IF($A23="","",AR23-B23) | AT19: =IF($A23="","",IFERROR(B23/AR23,0)) | AU19: =IF($A23="","",IFERROR(B23*O23,0)) | AV19: =IF($A23="","",IFERROR(C23/B23,0)) | AW19: =IF($A23="","",MAX(0,R23-S23)) | AX19: =IF($A23="","",IF(AW23>0,"优先降持仓数",IF(C23<=0,"现金不足","允许评估"))) | AY19: =IF($A23="","",IF(B23<30000,"婴儿阶段: 优先活下来,禁止单票失控,限制持仓数,服务3W目标","幼儿阶段达成"))
D20: =IF($A25="","",SUMIFS(持仓表!$J:$J,持仓表!$A:$A,$A25)) | E20: =IFERROR(D25/B25,0) -> 0 | G20: =IF($B25="","",MAX($B$2:B25)) | H20: =IFERROR((B25-F25)/F25,0) -> 0 | I20: =IFERROR((B25-G25)/G25,0) -> 0 | N20: =IF($B25="","",MIN(70%,IF($I25<=-15%,10%,IF($I25<=-10%,30%,IF($M25>=4,10%,IF($M25>=3,30%,IF($J25="强",IF($K25="A",70%,IF($K25="B",60%,40%)),IF($J25="中性",IF($K25="A",50%,IF($K25="B",40%,25%)),IF($K25="A",30%,IF($K25="B",20%,10%)))))))))) | O20: =IF($B25="","",IF(B25<30000,35%,IF(B25<50000,30%,IF(B25<100000,25%,20%)))) | P20: =IF($A25="","",COUNTIFS(持仓表!$A:$A,$A25,持仓表!$G:$G,">0")) | Q20: =IF($A25="","",COUNTIFS(持仓表!$A:$A,$A25,持仓表!$D:$D,"是",持仓表!$G:$G,">0")) | R20: =IF($A25="","",MAX(0,P25-Q25)) | S20: =IF($B25="","",IF(B25<50000,3,IF(B25<100000,4,5))) | T20: =IF($A25="","",IF(OR(M25>=4,I25<=-8%),"防守",IF(OR(M25>=2,I25<=-5%),"警戒","正常"))) | U20: =IF($A25="","",IF(AND(L25>=3,M25<=2,T25<>"防守"),"是","否")) | V20: =IF($A25="","",IF(AND(E25<N25,R25<S25,M25<=2,I25>-15%),"是","否")) | W20: =IF($A25="","",IF(OR(M25>=3,I25<=-15%),"是","否")) | X20: =IF($A25="","",IFERROR(maxifs(候选池!$AB:$AB,候选池!$A:$A,$A25),0)) | Y20: =IF($A25="","",IF(OR(M25>=4,I25<=-8%),MAX(0,B25*60%-C25),IF(AND(ISNUMBER(AD25),B25>AD25),IF(B25<30000,0,IF(B25<100000,MAX(0,(B25-AD25)*0.2),MAX(0,(B25-AD25)*0.3))),0))) | AA20: =IF($A25="","",IF($AA$2<>"",$AA$2,"")) | AB20: =IF($A25="","",IF(B25<30000,0.03,IF(B25<100000,0.02,0.015))) | AC20: =IF($A25="","",IFERROR(DATEDIF($A$2,$A25,"m"),0)) | AD20: =IF($A25="","",IF(OR(AA25="",AB25="",AC25=""),"",AA25*POWER(1+AB25,AC25))) | AE20: =IF($A25="","",IF(OR(AD25="",AD25=0),"",B25/AD25-1)) | AG20: =IF($A25="","",IF(B25<30000,"婴儿",IF(B25<100000,"成长","成熟"))) | AQ20: =IF($A25="","",B25-$AA$2-SUM($F$2:F25)) | AR20: =IF($A24="","",30000) | AS20: =IF($A24="","",AR24-B24) | AT20: =IF($A24="","",IFERROR(B24/AR24,0)) | AU20: =IF($A24="","",IFERROR(B24*O24,0)) | AV20: =IF($A24="","",IFERROR(C24/B24,0)) | AW20: =IF($A24="","",MAX(0,R24-S24)) | AX20: =IF($A24="","",IF(AW24>0,"优先降持仓数",IF(C24<=0,"现金不足","允许评估"))) | AY20: =IF($A24="","",IF(B24<30000,"婴儿阶段: 优先活下来,禁止单票失控,限制持仓数,服务3W目标","幼儿阶段达成"))
D21: =IF($A26="","",SUMIFS(持仓表!$J:$J,持仓表!$A:$A,$A26)) | E21: =IFERROR(D26/B26,0) -> 0 | G21: =IF($B26="","",MAX($B$2:B26)) | H21: =IFERROR((B26-F26)/F26,0) -> 0 | I21: =IFERROR((B26-G26)/G26,0) -> 0 | N21: =IF($B26="","",MIN(70%,IF($I26<=-15%,10%,IF($I26<=-10%,30%,IF($M26>=4,10%,IF($M26>=3,30%,IF($J26="强",IF($K26="A",70%,IF($K26="B",60%,40%)),IF($J26="中性",IF($K26="A",50%,IF($K26="B",40%,25%)),IF($K26="A",30%,IF($K26="B",20%,10%)))))))))) | O21: =IF($B26="","",IF(B26<30000,35%,IF(B26<50000,30%,IF(B26<100000,25%,20%)))) | P21: =IF($A26="","",COUNTIFS(持仓表!$A:$A,$A26,持仓表!$G:$G,">0")) | Q21: =IF($A26="","",COUNTIFS(持仓表!$A:$A,$A26,持仓表!$D:$D,"是",持仓表!$G:$G,">0")) | R21: =IF($A26="","",MAX(0,P26-Q26)) | S21: =IF($B26="","",IF(B26<50000,3,IF(B26<100000,4,5))) | T21: =IF($A26="","",IF(OR(M26>=4,I26<=-8%),"防守",IF(OR(M26>=2,I26<=-5%),"警戒","正常"))) | U21: =IF($A26="","",IF(AND(L26>=3,M26<=2,T26<>"防守"),"是","否")) | V21: =IF($A26="","",IF(AND(E26<N26,R26<S26,M26<=2,I26>-15%),"是","否")) | W21: =IF($A26="","",IF(OR(M26>=3,I26<=-15%),"是","否")) | X21: =IF($A26="","",IFERROR(maxifs(候选池!$AB:$AB,候选池!$A:$A,$A26),0)) | Y21: =IF($A26="","",IF(OR(M26>=4,I26<=-8%),MAX(0,B26*60%-C26),IF(AND(ISNUMBER(AD26),B26>AD26),IF(B26<30000,0,IF(B26<100000,MAX(0,(B26-AD26)*0.2),MAX(0,(B26-AD26)*0.3))),0))) | AA21: =IF($A26="","",IF($AA$2<>"",$AA$2,"")) | AB21: =IF($A26="","",IF(B26<30000,0.03,IF(B26<100000,0.02,0.015))) | AC21: =IF($A26="","",IFERROR(DATEDIF($A$2,$A26,"m"),0)) | AD21: =IF($A26="","",IF(OR(AA26="",AB26="",AC26=""),"",AA26*POWER(1+AB26,AC26))) | AE21: =IF($A26="","",IF(OR(AD26="",AD26=0),"",B26/AD26-1)) | AG21: =IF($A26="","",IF(B26<30000,"婴儿",IF(B26<100000,"成长","成熟"))) | AQ21: =IF($A26="","",B26-$AA$2-SUM($F$2:F26)) | AR21: =IF($A25="","",30000) | AS21: =IF($A25="","",AR25-B25) | AT21: =IF($A25="","",IFERROR(B25/AR25,0)) | AU21: =IF($A25="","",IFERROR(B25*O25,0)) | AV21: =IF($A25="","",IFERROR(C25/B25,0)) | AW21: =IF($A25="","",MAX(0,R25-S25)) | AX21: =IF($A25="","",IF(AW25>0,"优先降持仓数",IF(C25<=0,"现金不足","允许评估"))) | AY21: =IF($A25="","",IF(B25<30000,"婴儿阶段: 优先活下来,禁止单票失控,限制持仓数,服务3W目标","幼儿阶段达成"))
D22: =IF($A27="","",SUMIFS(持仓表!$J:$J,持仓表!$A:$A,$A27)) | E22: =IFERROR(D27/B27,0) -> 0 | G22: =IF($B27="","",MAX($B$2:B27)) | H22: =IFERROR((B27-F27)/F27,0) -> 0 | I22: =IFERROR((B27-G27)/G27,0) -> 0 | N22: =IF($B27="","",MIN(70%,IF($I27<=-15%,10%,IF($I27<=-10%,30%,IF($M27>=4,10%,IF($M27>=3,30%,IF($J27="强",IF($K27="A",70%,IF($K27="B",60%,40%)),IF($J27="中性",IF($K27="A",50%,IF($K27="B",40%,25%)),IF($K27="A",30%,IF($K27="B",20%,10%)))))))))) | O22: =IF($B27="","",IF(B27<30000,35%,IF(B27<50000,30%,IF(B27<100000,25%,20%)))) | P22: =IF($A27="","",COUNTIFS(持仓表!$A:$A,$A27,持仓表!$G:$G,">0")) | Q22: =IF($A27="","",COUNTIFS(持仓表!$A:$A,$A27,持仓表!$D:$D,"是",持仓表!$G:$G,">0")) | R22: =IF($A27="","",MAX(0,P27-Q27)) | S22: =IF($B27="","",IF(B27<50000,3,IF(B27<100000,4,5))) | T22: =IF($A27="","",IF(OR(M27>=4,I27<=-8%),"防守",IF(OR(M27>=2,I27<=-5%),"警戒","正常"))) | U22: =IF($A27="","",IF(AND(L27>=3,M27<=2,T27<>"防守"),"是","否")) | V22: =IF($A27="","",IF(AND(E27<N27,R27<S27,M27<=2,I27>-15%),"是","否")) | W22: =IF($A27="","",IF(OR(M27>=3,I27<=-15%),"是","否")) | X22: =IF($A27="","",IFERROR(maxifs(候选池!$AB:$AB,候选池!$A:$A,$A27),0)) | Y22: =IF($A27="","",IF(OR(M27>=4,I27<=-8%),MAX(0,B27*60%-C27),IF(AND(ISNUMBER(AD27),B27>AD27),IF(B27<30000,0,IF(B27<100000,MAX(0,(B27-AD27)*0.2),MAX(0,(B27-AD27)*0.3))),0))) | AA22: =IF($A27="","",IF($AA$2<>"",$AA$2,"")) | AB22: =IF($A27="","",IF(B27<30000,0.03,IF(B27<100000,0.02,0.015))) | AC22: =IF($A27="","",IFERROR(DATEDIF($A$2,$A27,"m"),0)) | AD22: =IF($A27="","",IF(OR(AA27="",AB27="",AC27=""),"",AA27*POWER(1+AB27,AC27))) | AE22: =IF($A27="","",IF(OR(AD27="",AD27=0),"",B27/AD27-1)) | AG22: =IF($A27="","",IF(B27<30000,"婴儿",IF(B27<100000,"成长","成熟"))) | AQ22: =IF($A27="","",B27-$AA$2-SUM($F$2:F27)) | AR22: =IF($A26="","",30000) | AS22: =IF($A26="","",AR26-B26) | AT22: =IF($A26="","",IFERROR(B26/AR26,0)) | AU22: =IF($A26="","",IFERROR(B26*O26,0)) | AV22: =IF($A26="","",IFERROR(C26/B26,0)) | AW22: =IF($A26="","",MAX(0,R26-S26)) | AX22: =IF($A26="","",IF(AW26>0,"优先降持仓数",IF(C26<=0,"现金不足","允许评估"))) | AY22: =IF($A26="","",IF(B26<30000,"婴儿阶段: 优先活下来,禁止单票失控,限制持仓数,服务3W目标","幼儿阶段达成"))
D23: =IF($A28="","",SUMIFS(持仓表!$J:$J,持仓表!$A:$A,$A28)) | E23: =IFERROR(D28/B28,0) -> 0 | G23: =IF($B28="","",MAX($B$2:B28)) | H23: =IFERROR((B28-F28)/F28,0) -> 0 | I23: =IFERROR((B28-G28)/G28,0) -> 0 | N23: =IF($B28="","",MIN(70%,IF($I28<=-15%,10%,IF($I28<=-10%,30%,IF($M28>=4,10%,IF($M28>=3,30%,IF($J28="强",IF($K28="A",70%,IF($K28="B",60%,40%)),IF($J28="中性",IF($K28="A",50%,IF($K28="B",40%,25%)),IF($K28="A",30%,IF($K28="B",20%,10%)))))))))) | O23: =IF($B28="","",IF(B28<30000,35%,IF(B28<50000,30%,IF(B28<100000,25%,20%)))) | P23: =IF($A28="","",COUNTIFS(持仓表!$A:$A,$A28,持仓表!$G:$G,">0")) | Q23: =IF($A28="","",COUNTIFS(持仓表!$A:$A,$A28,持仓表!$D:$D,"是",持仓表!$G:$G,">0")) | R23: =IF($A28="","",MAX(0,P28-Q28)) | S23: =IF($B28="","",IF(B28<50000,3,IF(B28<100000,4,5))) | T23: =IF($A28="","",IF(OR(M28>=4,I28<=-8%),"防守",IF(OR(M28>=2,I28<=-5%),"警戒","正常"))) | U23: =IF($A28="","",IF(AND(L28>=3,M28<=2,T28<>"防守"),"是","否")) | V23: =IF($A28="","",IF(AND(E28<N28,R28<S28,M28<=2,I28>-15%),"是","否")) | W23: =IF($A28="","",IF(OR(M28>=3,I28<=-15%),"是","否")) | X23: =IF($A28="","",IFERROR(maxifs(候选池!$AB:$AB,候选池!$A:$A,$A28),0)) | Y23: =IF($A28="","",IF(OR(M28>=4,I28<=-8%),MAX(0,B28*60%-C28),IF(AND(ISNUMBER(AD28),B28>AD28),IF(B28<30000,0,IF(B28<100000,MAX(0,(B28-AD28)*0.2),MAX(0,(B28-AD28)*0.3))),0))) | AA23: =IF($A28="","",IF($AA$2<>"",$AA$2,"")) | AB23: =IF($A28="","",IF(B28<30000,0.03,IF(B28<100000,0.02,0.015))) | AC23: =IF($A28="","",IFERROR(DATEDIF($A$2,$A28,"m"),0)) | AD23: =IF($A28="","",IF(OR(AA28="",AB28="",AC28=""),"",AA28*POWER(1+AB28,AC28))) | AE23: =IF($A28="","",IF(OR(AD28="",AD28=0),"",B28/AD28-1)) | AG23: =IF($A28="","",IF(B28<30000,"婴儿",IF(B28<100000,"成长","成熟"))) | AQ23: =IF($A28="","",B28-$AA$2-SUM($F$2:F28)) | AR23: =IF($A27="","",30000) | AS23: =IF($A27="","",AR27-B27) | AT23: =IF($A27="","",IFERROR(B27/AR27,0)) | AU23: =IF($A27="","",IFERROR(B27*O27,0)) | AV23: =IF($A27="","",IFERROR(C27/B27,0)) | AW23: =IF($A27="","",MAX(0,R27-S27)) | AX23: =IF($A27="","",IF(AW27>0,"优先降持仓数",IF(C27<=0,"现金不足","允许评估"))) | AY23: =IF($A27="","",IF(B27<30000,"婴儿阶段: 优先活下来,禁止单票失控,限制持仓数,服务3W目标","幼儿阶段达成"))
D24: =IF($A29="","",SUMIFS(持仓表!$J:$J,持仓表!$A:$A,$A29)) | E24: =IFERROR(D29/B29,0) -> 0 | G24: =IF($B29="","",MAX($B$2:B29)) | H24: =IFERROR((B29-F29)/F29,0) -> 0 | I24: =IFERROR((B29-G29)/G29,0) -> 0 | N24: =IF($B29="","",MIN(70%,IF($I29<=-15%,10%,IF($I29<=-10%,30%,IF($M29>=4,10%,IF($M29>=3,30%,IF($J29="强",IF($K29="A",70%,IF($K29="B",60%,40%)),IF($J29="中性",IF($K29="A",50%,IF($K29="B",40%,25%)),IF($K29="A",30%,IF($K29="B",20%,10%)))))))))) | O24: =IF($B29="","",IF(B29<30000,35%,IF(B29<50000,30%,IF(B29<100000,25%,20%)))) | P24: =IF($A29="","",COUNTIFS(持仓表!$A:$A,$A29,持仓表!$G:$G,">0")) | Q24: =IF($A29="","",COUNTIFS(持仓表!$A:$A,$A29,持仓表!$D:$D,"是",持仓表!$G:$G,">0")) | R24: =IF($A29="","",MAX(0,P29-Q29)) | S24: =IF($B29="","",IF(B29<50000,3,IF(B29<100000,4,5))) | T24: =IF($A29="","",IF(OR(M29>=4,I29<=-8%),"防守",IF(OR(M29>=2,I29<=-5%),"警戒","正常"))) | U24: =IF($A29="","",IF(AND(L29>=3,M29<=2,T29<>"防守"),"是","否")) | V24: =IF($A29="","",IF(AND(E29<N29,R29<S29,M29<=2,I29>-15%),"是","否")) | W24: =IF($A29="","",IF(OR(M29>=3,I29<=-15%),"是","否")) | X24: =IF($A29="","",IFERROR(maxifs(候选池!$AB:$AB,候选池!$A:$A,$A29),0)) | Y24: =IF($A29="","",IF(OR(M29>=4,I29<=-8%),MAX(0,B29*60%-C29),IF(AND(ISNUMBER(AD29),B29>AD29),IF(B29<30000,0,IF(B29<100000,MAX(0,(B29-AD29)*0.2),MAX(0,(B29-AD29)*0.3))),0))) | AA24: =IF($A29="","",IF($AA$2<>"",$AA$2,"")) | AB24: =IF($A29="","",IF(B29<30000,0.03,IF(B29<100000,0.02,0.015))) | AC24: =IF($A29="","",IFERROR(DATEDIF($A$2,$A29,"m"),0)) | AD24: =IF($A29="","",IF(OR(AA29="",AB29="",AC29=""),"",AA29*POWER(1+AB29,AC29))) | AE24: =IF($A29="","",IF(OR(AD29="",AD29=0),"",B29/AD29-1)) | AG24: =IF($A29="","",IF(B29<30000,"婴儿",IF(B29<100000,"成长","成熟"))) | AQ24: =IF($A29="","",B29-$AA$2-SUM($F$2:F29)) | AR24: =IF($A28="","",30000) | AS24: =IF($A28="","",AR28-B28) | AT24: =IF($A28="","",IFERROR(B28/AR28,0)) | AU24: =IF($A28="","",IFERROR(B28*O28,0)) | AV24: =IF($A28="","",IFERROR(C28/B28,0)) | AW24: =IF($A28="","",MAX(0,R28-S28)) | AX24: =IF($A28="","",IF(AW28>0,"优先降持仓数",IF(C28<=0,"现金不足","允许评估"))) | AY24: =IF($A28="","",IF(B28<30000,"婴儿阶段: 优先活下来,禁止单票失控,限制持仓数,服务3W目标","幼儿阶段达成"))
