Workbook

Sheet 执行清单
A1: 流程 | B1: 检查项 | C1: 判断依据 | D1: 自动结论 | E1: 手动确认 | F1: 不通过动作 | G1: 备注
A2: 周末 | B2: 赚钱效应分数已更新 | C2: 账户总表!赚钱效应分数 | F2: 未更新则不生成下周买入计划
A3: 周末 | B3: 亏钱效应分数已更新 | C3: 账户总表!亏钱效应分数 | F3: 未更新则默认按警戒处理
A4: 周末 | B4: 候选池已生成 | C4: ratio / DL_P / valid / SignalType | F4: 没有候选池则周一不新开仓
A5: 周一盘前 | B5: 账户状态不是防守 | C5: 当前状态 <> 防守 | D5: =IFERROR(IF(LOOKUP(2,1/(账户总表!$A:$A<>""),账户总表!$T:$T)<>"防守","是","否"),"否") -> 是 | F5: 防守状态只处理持仓风险
A6: 周一盘前 | B6: 允许新开仓 | C6: 账户总表!是否允许新开仓 | D6: =IFERROR(LOOKUP(2,1/(账户总表!$A:$A<>""),账户总表!$V:$V),"否") -> 否 | F6: 不允许则取消新增买入
A7: 周一盘前 | B7: 未暂停买入 | C7: 账户总表!是否暂停买入 = 否 | D7: =IFERROR(IF(LOOKUP(2,1/(账户总表!$A:$A<>""),账户总表!$W:$W)="否","是","否"),"否") -> 是 | F7: 暂停买入时只允许卖出/减仓
A8: 周一盘前 | B8: 总仓位未超上限 | C8: 总仓位 <= 总仓位上限 | D8: =IFERROR(IF(LOOKUP(2,1/(账户总表!$A:$A<>""),账户总表!$E:$E)<=LOOKUP(2,1/(账户总表!$A:$A<>""),账户总表!$N:$N),"是","否"),"否") -> 否 | F8: 超限先减仓，不新买
A9: 周一盘前 | B9: 有效持仓数未超上限 | C9: 有效持仓数 <= 有效持仓上限 | D9: =IFERROR(IF(LOOKUP(2,1/(账户总表!$A:$A<>""),账户总表!$R:$R)<=LOOKUP(2,1/(账户总表!$A:$A<>""),账户总表!$S:$S),"是","否"),"否") -> 否 | F9: 超限则不新增标的
A10: 周一盘前 | B10: 亏钱效应可控 | C10: 亏钱效应分数 <= 2 | D10: =IFERROR(IF(LOOKUP(2,1/(账户总表!$A:$A<>""),账户总表!$M:$M)<=2,"是","否"),"否") -> 是 | F10: 亏钱效应偏高则暂停转入/新开
A11: 周一盘前 | B11: 存在最终可买候选 | C11: 候选池!最终是否可买 = 是 | D11: =IFERROR(IF(COUNTIFS(候选池!$A:$A,LOOKUP(2,1/(账户总表!$A:$A<>""),账户总表!$A:$A),候选池!$AC:$AC,"是")>0,"是","否"),"否") -> 否 | F11: 没有可买候选则不下单
A12: 盘中买入 | B12: 只买最终可买=是的标的 | C12: 候选池!最终是否可买 | F12: 任一条件为否则不买
A13: 盘中买入 | B13: 止损价和失效条件已写 | C13: StopPrice > 0 且 InvalidationCondition 非空 | F13: 没写清楚不下单
A14: 盘中买入 | B14: 不是追价情绪单 | C14: Price <= SignalPrice * 1.02 或回踩确认 | F14: 追价则取消委托
A15: 持仓处理 | B15: 没有必须卖出的持仓 | C15: 执行结论不含立即卖出/次日卖出 | D15: =IFERROR(IF(COUNTIFS(持仓表!$A:$A,LOOKUP(2,1/(账户总表!$A:$A<>""),账户总表!$A:$A),持仓表!$AB:$AB,"立即卖出")+COUNTIFS(持仓表!$A:$A,LOOKUP(2,1/(账户总表!$A:$A<>""),账户总表!$A:$A),持仓表!$AB:$AB,"次日卖出")=0,"是","否"),"否") -> 是 | F15: 先卖出，再考虑新买
A16: 持仓处理 | B16: RiskWatch 已复核 | C16: RiskWatch = 是的持仓逐只检查 | F16: 观察股不加仓，重点看止损
A17: 转入转出 | B17: 转入只服务合规缺口 | C17: 是否允许转入=是 且 候选池提示缺口 | D17: =IFERROR(IF(AND(LOOKUP(2,1/(账户总表!$A:$A<>""),账户总表!$U:$U)="是",maxifs(候选池!$AB:$AB,候选池!$A:$A,LOOKUP(2,1/(账户总表!$A:$A<>""),账户总表!$A:$A))>0),"是","不适用"),"不适用") -> 不适用 | F17: 先有合规候选，再转入
A18: 转入转出 | B18: 防守转出已检查 | C18: 账户计划转出金额 | D18: =IFERROR(IF(LOOKUP(2,1/(账户总表!$A:$A<>""),账户总表!$Y:$Y)>0,"是","不适用"),"不适用") -> 不适用 | F18: 防守/利润转出分开处理
A19: 收盘后 | B19: 交易记录已补全 | C19: 成交价/股数/金额/止损/原因 | F19: 不记录则次日不新增交易
A20: 收盘后 | B20: 持仓表已更新 | C20: Close / ratio / DL_P / valid | F20: 未更新则不依赖次日公式结论
A21: 周复盘 | B21: 本周最大问题只写一条 | C21: 周复盘!本周最大问题 | F21: 只修最主要的执行偏差
A22: 每日 | B22: 心态日志已填写 | C22: 盘中看盘/情绪/执行 | F22: 未填写则心态得分缺失
A23: 每日 | B23: 盘中看盘次数<=1 | C23: 心态日志!盘中看盘次数 | F23: 超1次需说明原因
A24: 每日 | B24: 无止损外操作 | C24: 心态日志!是否有止损外操作 | F24: 偏离系统=心态偏离
A25: 每周 | B25: 心态趋势已复盘 | C25: 心态日志!心态趋势 | F25: 连续恶化需调整策略
A26: 每周 | B26: 连续达标天数>=3 | C26: 心态日志!连续达标天数 | F26: 低于3天需加强纪律

Sheet 关键变量表
A1: 类型 | B1: 变量名 | C1: Excel字段 | D1: 计算方式 | E1: 触发阈值 | F1: 影响动作 | G1: 复盘频率 | H1: 备注
A2: 生存变量 | B2: MaxDrawdown | C2: 账户总表!最大回撤 | D2: (TotalAsset-PeakAsset)/PeakAsset | E2: <=-10%, <=-15% | F2: 降总仓位/禁止新买入 | G2: 每日+周复盘 | H2: 决定系统是否降速
A3: 生存变量 | B3: 单笔止损 | C3: 持仓表!止损价 | D3: max(BuyPointLow*0.98, EntryPrice*0.92) | E3: Price<=StopPrice | F3: 次日卖出或立即卖出 | G3: 每日 | H3: 买前必须定义
A4: 生存变量 | B4: 连续亏损 | C4: 交易记录!结果分类 | D4: 近5笔亏损数 | E4: >=3笔 | F4: 暂停新开仓5个交易日 | G4: 每次成交后 | H4: 后续可扩展公式
A5: 扩张变量 | B5: 赚钱效应分数 | C5: 账户总表!赚钱效应分数 | D5: 0-5分 | E5: >=3 | F5: 允许转入/扩大执行 | G5: 周末 | H5: 强时按系数放大转入
A6: 扩张变量 | B6: 合规候选数量 | C6: 候选池!最终是否可买 | D6: COUNTIF(...,"是") | E6: >=1 | F6: 准备买入计划 | G6: 周末+盘前 | H6: 只统计规则通过标的
A7: 收缩变量 | B7: 亏钱效应分数 | C7: 账户总表!亏钱效应分数 | D7: 0-6分 | E7: >=3警戒, >=4防守 | F7: 暂停转入/提高现金 | G7: 每日+周末 | H7: 优先级高于赚钱效应
A8: 收缩变量 | B8: RiskWatch | C8: 持仓表!RiskWatch | D8: Close<EntryPrice AND DL_P<0.8 | E8: True | F8: 重点盯防 | G8: 每日 | H8: 观察不等于立即卖出
A9: 仓位变量 | B9: TotalPositionCap | C9: 账户总表!总仓位上限 | D9: 市场状态+信号等级+回撤保护 | E9: 最高70% | F9: 限制新增买入 | G9: 周一盘前 | H9: 硬性仓位上限
A10: 仓位变量 | B10: SingleStockCap | C10: 账户总表!单股上限 | D10: 按总资产分档 | E10: 20%-35% | F10: 限制单票暴露 | G10: 每日 | H10: 非WAIVED适用
A11: 仓位变量 | B11: MaxShares/MinShares | C11: 候选池!最大/最小可买股数 | D11: 100股整数约束 | E11: Max>=Min | F11: 决定是否可落地交易 | G11: 盘前 | H11: A股最小单位适配
A12: 执行变量 | B12: NotChasing | C12: 候选池!是否未追价 | D12: Price<=SignalPrice*1.02 | E12: 是 | F12: 禁止情绪追价 | G12: 盘前+盘中 | H12: 高开无回踩不买
... A22: 心态变量 | B22: 盘中看盘次数 | C22: 心态日志!盘中看盘次数 | D22: 每日看盘次数 | E22: 0次=满分 | F22: 目标逐步降至0次 | G22: 每日 | H22: 信息节食核心指标

Sheet 账户总表
A1: 日期 | B1: 总资产 TotalAsset | C1: 可用现金 CashAvailable | D1: 持仓市值 | E1: 总仓位 TotalPositionRatio | F1: 净入金 NetDeposit | G1: 阶段高点资产 PeakAsset | H1: 账户收益率 AccountReturn | I1: 最大回撤 MaxDrawdown | J1: 当前市场状态 MarketState | K1: 本周最高信号等级 | L1: 赚钱效应分数 | M1: 亏钱效应分数 | N1: 总仓位上限 TotalPositionCap | O1: 单股上限 SingleStockCap | P1: 总持仓数 | Q1: WAIVED数 | R1: 有效持仓数 | S1: 有效持仓上限 | T1: 当前状态 | U1: 是否允许转入 | V1: 是否允许新开仓 | W1: 是否暂停买入 | X1: 本周计划转入金额 | Y1: 本周计划转出金额 | Z1: 备注 | AA1: 初始本金 Principal | AB1: 目标年化收益率 TargetAnnualReturn | AC1: 运行月数 MonthsRunning | AD1: 目标资产 TargetAsset | AE1: 复利偏离度 CompoundDeviation | AF1: 交易股票数 TradeCount | AG1: 账户阶段 | AH1: 平均仓位 AvgPosition | AI1: 平均持仓天数 AvgHoldDays | AJ1: 交易成功率 SuccessRate | AK1: 资金周转率 CapitalTurnover | AL1: 做T次数 T0Count | AM1: 做T成功率 T0SuccessRate | AN1: 重仓行业 HeavySector | AO1: 投资风格 Style | AP1: 跑赢上证 BeatIndex | AQ1: 净入金后累计盈利 RealPnL
A2: 2026-01-31 | B2: 6683.54 | C2: 0 | D2: =IF($A2="","",SUMIFS(持仓表!$J:$J,持仓表!$A:$A,$A2)) -> 0 | E2: =IFERROR(D2/B2,0) -> 0 | F2: 2700 | G2: =IF($B2="","",MAX($B$2:B2)) -> 6683.54 | H2: =IFERROR((B2-F2)/F2,0) -> 1.4753852 | I2: =IFERROR((B2-G2)/G2,0) -> 0 | J2: 中性 | K2: B | L2: 2 | M2: 2 | N2: =IF($B2="","",MIN(70%,IF($I2<=-15%,10%,IF($I2<=-10%,30%,IF($M2>=4,10%,IF($M2>=3,30%,IF($J2="强",IF($K2="A",70%,IF($K2="B",60%,40%)),IF($J2="中性",IF($K2="A",50%,IF($K2="B",40%,25%)),IF($K2="A",30%,IF($K2="B",20%,10%)))))))))) -> 0.4 | O2: =IF($B2="","",IF(B2<30000,35%,IF(B2<50000,30%,IF(B2<100000,25%,20%)))) -> 0.35 | P2: =IF($A2="","",COUNTIFS(持仓表!$A:$A,$A2,持仓表!$G:$G,">0")) -> 0 | Q2: =IF($A2="","",COUNTIFS(持仓表!$A:$A,$A2,持仓表!$D:$D,"是",持仓表!$G:$G,">0")) -> 0 | R2: =IF($A2="","",MAX(0,P2-Q2)) -> 0 | S2: =IF($B2="","",IF(B2<50000,3,IF(B2<100000,4,5))) -> 3 | T2: =IF($A2="","",IF(OR(M2>=4,I2<=-8%),"防守",IF(OR(M2>=2,I2<=-5%),"警戒","正常"))) -> 警戒 | U2: =IF($A2="","",IF(AND(L2>=3,M2<=2,T2<>"防守"),"是","否")) -> 否 | V2: =IF($A2="","",IF(AND(E2<N2,R2<S2,M2<=2,I2>-15%),"是","否")) -> 是 | W2: =IF($A2="","",IF(OR(M2>=3,I2<=-15%),"是","否")) -> 否 | X2: =IF($A2="","",IFERROR(maxifs(候选池!$AB:$AB,候选池!$A:$A,$A2),0)) -> 0 | Y2: =IF($A2="","",IF(OR(M2>=4,I2<=-8%),MAX(0,B2*60%-C2),IF(AND(ISNUMBER(AD2),B2>AD2),IF(B2<30000,0,IF(B2<100000,MAX(0,(B2-AD2)*0.2),MAX(0,(B2-AD2)*0.3))),0))) -> 0 | AA2: 6683.54 | AB2: =IF($A2="","",IF(B2<30000,0.03,IF(B2<100000,0.02,0.015))) -> 0.03 | AC2: =IF($A2="","",IFERROR(DATEDIF($A$2,$A2,"m"),0)) -> 0 | AD2: =IF($A2="","",IF(OR(AA2="",AB2="",AC2=""),"",AA2*POWER(1+AB2,AC2))) -> 6683.54 | AE2: =IF($A2="","",IF(OR(AD2="",AD2=0),"",B2/AD2-1)) -> 0 | AF2: 2 | AG2: =IF($A2="","",IF(B2<30000,"婴儿",IF(B2<100000,"成长","成熟"))) -> 婴儿 | AH2: 0.7073 | AI2: 38 | AJ2: 1 | AK2: 0.0002 | AL2: 0 | AM2: 0 | AN2: 汽车 | AO2: 小盘 | AP2: 否 | AQ2: =IF($A2="","",B2-$AA$2-SUM($F$2:F2)) -> -2700
A3: 2026-02-28 | B3: 9520.45 | C3: 0 | D3: =IF($A3="","",SUMIFS(持仓表!$J:$J,持仓表!$A:$A,$A3)) -> 0 | E3: =IFERROR(D3/B3,0) -> 0 | F3: 0 | G3: =IF($B3="","",MAX($B$2:B3)) -> 9520.45 | H3: =IFERROR((B3-F3)/F3,0) -> 0 | I3: =IFERROR((B3-G3)/G3,0) -> 0 | J3: 强 | K3: A | L3: 3 | M3: 1 | N3: =IF($B3="","",MIN(70%,IF($I3<=-15%,10%,IF($I3<=-10%,30%,IF($M3>=4,10%,IF($M3>=3,30%,IF($J3="强",IF($K3="A",70%,IF($K3="B",60%,40%)),IF($J3="中性",IF($K3="A",50%,IF($K3="B",40%,25%)),IF($K3="A",30%,IF($K3="B",20%,10%)))))))))) -> 0.7 | O3: =IF($B3="","",IF(B3<30000,35%,IF(B3<50000,30%,IF(B3<100000,25%,20%)))) -> 0.35 | P3: =IF($A3="","",COUNTIFS(持仓表!$A:$A,$A3,持仓表!$G:$G,">0")) -> 0 | Q3: =IF($A3="","",COUNTIFS(持仓表!$A:$A,$A3,持仓表!$D:$D,"是",持仓表!$G:$G,">0")) -> 0 | R3: =IF($A3="","",MAX(0,P3-Q3)) -> 0 | S3: =IF($B3="","",IF(B3<50000,3,IF(B3<100000,4,5))) -> 3 | T3: =IF($A3="","",IF(OR(M3>=4,I3<=-8%),"防守",IF(OR(M3>=2,I3<=-5%),"警戒","正常"))) -> 正常 | U3: =IF($A3="","",IF(AND(L3>=3,M3<=2,T3<>"防守"),"是","否")) -> 是 | V3: =IF($A3="","",IF(AND(E3<N3,R3<S3,M3<=2,I3>-15%),"是","否")) -> 是 | W3: =IF($A3="","",IF(OR(M3>=3,I3<=-15%),"是","否")) -> 否 | X3: =IF($A3="","",IFERROR(maxifs(候选池!$AB:$AB,候选池!$A:$A,$A3),0)) -> 0 | Y3: =IF($A3="","",IF(OR(M3>=4,I3<=-8%),MAX(0,B3*60%-C3),IF(AND(ISNUMBER(AD3),B3>AD3),IF(B3<30000,0,IF(B3<100000,MAX(0,(B3-AD3)*0.2),MAX(0,(B3-AD3)*0.3))),0))) -> 0 | AA3: =IF($A3="","",IF($AA$2<>"",$AA$2,"")) -> 6683.54 | AB3: =IF($A3="","",IF(B3<30000,0.03,IF(B3<100000,0.02,0.015))) -> 0.03 | AC3: =IF($A3="","",IFERROR(DATEDIF($A$2,$A3,"m"),0)) -> 0 | AD3: =IF($A3="","",IF(OR(AA3="",AB3="",AC3=""),"",AA3*POWER(1+AB3,AC3))) -> 6683.54 | AE3: =IF($A3="","",IF(OR(AD3="",AD3=0),"",B3/AD3-1)) -> 0.42446219 | AF3: 1 | AG3: =IF($A3="","",IF(B3<30000,"婴儿",IF(B3<100000,"成长","成熟"))) -> 婴儿 | AH3: 0.5625 | AI3: 62 | AJ3: 1 | AK3: 0.2272 | AL3: 0 | AM3: 0 | AN3: 电子 | AO3: 中盘成长 | AP3: 是 | AQ3: =IF($A3="","",B3-$AA$2-SUM($F$2:F3)) -> 136.91
A4: 2026-03-31 | B4: 11454.37 | C4: 0 | D4: =IF($A4="","",SUMIFS(持仓表!$J:$J,持仓表!$A:$A,$A4)) -> 0 | E4: =IFERROR(D4/B4,0) -> 0 | F4: 0 | G4: =IF($B4="","",MAX($B$2:B4)) -> 11454.37 | H4: =IFERROR((B4-F4)/F4,0) -> 0 | I4: =IFERROR((B4-G4)/G4,0) -> 0 | J4: 弱 | K4: C | L4: 1 | M4: 3 | N4: =IF($B4="","",MIN(70%,IF($I4<=-15%,10%,IF($I4<=-10%,30%,IF($M4>=4,10%,IF($M4>=3,30%,IF($J4="强",IF($K4="A",70%,IF($K4="B",60%,40%)),IF($J4="中性",IF($K4="A",50%,IF($K4="B",40%,25%)),IF($K4="A",30%,IF($K4="B",20%,10%)))))))))) -> 0.3 | O4: =IF($B4="","",IF(B4<30000,35%,IF(B4<50000,30%,IF(B4<100000,25%,20%)))) -> 0.35 | P4: =IF($A4="","",COUNTIFS(持仓表!$A:$A,$A4,持仓表!$G:$G,">0")) -> 0 | Q4: =IF($A4="","",COUNTIFS(持仓表!$A:$A,$A4,持仓表!$D:$D,"是",持仓表!$G:$G,">0")) -> 0 | R4: =IF($A4="","",MAX(0,P4-Q4)) -> 0 | S4: =IF($B4="","",IF(B4<50000,3,IF(B4<100000,4,5))) -> 3 | T4: =IF($A4="","",IF(OR(M4>=4,I4<=-8%),"防守",IF(OR(M4>=2,I4<=-5%),"警戒","正常"))) -> 警戒 | U4: =IF($A4="","",IF(AND(L4>=3,M4<=2,T4<>"防守"),"是","否")) -> 否 | V4: =IF($A4="","",IF(AND(E4<N4,R4<S4,M4<=2,I4>-15%),"是","否")) -> 否 | W4: =IF($A4="","",IF(OR(M4>=3,I4<=-15%),"是","否")) -> 是 | X4: =IF($A4="","",IFERROR(maxifs(候选池!$AB:$AB,候选池!$A:$A,$A4),0)) -> 0 | Y4: =IF($A4="","",IF(OR(M4>=4,I4<=-8%),MAX(0,B4*60%-C4),IF(AND(ISNUMBER(AD4),B4>AD4),IF(B4<30000,0,IF(B4<100000,MAX(0,(B4-AD4)*0.2),MAX(0,(B4-AD4)*0.3))),0))) -> 0 | AA4: =IF($A4="","",IF($AA$2<>"",$AA$2,"")) -> 6683.54 | AB4: =IF($A4="","",IF(B4<30000,0.03,IF(B4<100000,0.02,0.015))) -> 0.03 | AC4: =IF($A4="","",IFERROR(DATEDIF($A$2,$A4,"m"),0)) -> 2 | AD4: =IF($A4="","",IF(OR(AA4="",AB4="",AC4=""),"",AA4*POWER(1+AB4,AC4))) -> 7090.5676 | AE4: =IF($A4="","",IF(OR(AD4="",AD4=0),"",B4/AD4-1)) -> 0.61543767 | AF4: 0 | AG4: =IF($A4="","",IF(B4<30000,"婴儿",IF(B4<100000,"成长","成熟"))) -> 婴儿 | AH4: 0.7306 | AI4: 0 | AJ4: 0 | AK4: 0 | AL4: 2 | AM4: 1 | AN4: 电子 | AO4: 中盘成长 | AP4: 是 | AQ4: =IF($A4="","",B4-$AA$2-SUM($F$2:F4)) -> 2070.83
A5: 2026-04-30 | B5: 14148.37 | C5: 0 | D5: =IF($A5="","",SUMIFS(持仓表!$J:$J,持仓表!$A:$A,$A5)) -> 0 | E5: =IFERROR(D5/B5,0) -> 0 | F5: 0 | G5: =IF($B5="","",MAX($B$2:B5)) -> 14148.37 | H5: =IFERROR((B5-F5)/F5,0) -> 0 | I5: =IFERROR((B5-G5)/G5,0) -> 0 | J5: 强 | K5: A | L5: 4 | M5: 1 | N5: =IF($B5="","",MIN(70%,IF($I5<=-15%,10%,IF($I5<=-10%,30%,IF($M5>=4,10%,IF($M5>=3,30%,IF($J5="强",IF($K5="A",70%,IF($K5="B",60%,40%)),IF($J5="中性",IF($K5="A",50%,IF($K5="B",40%,25%)),IF($K5="A",30%,IF($K5="B",20%,10%)))))))))) -> 0.7 | O5: =IF($B5="","",IF(B5<30000,35%,IF(B5<50000,30%,IF(B5<100000,25%,20%)))) -> 0.35 | P5: =IF($A5="","",COUNTIFS(持仓表!$A:$A,$A5,持仓表!$G:$G,">0")) -> 0 | Q5: =IF($A5="","",COUNTIFS(持仓表!$A:$A,$A5,持仓表!$D:$D,"是",持仓表!$G:$G,">0")) -> 0 | R5: =IF($A5="","",MAX(0,P5-Q5)) -> 0 | S5: =IF($B5="","",IF(B5<50000,3,IF(B5<100000,4,5))) -> 3 | T5: =IF($A5="","",IF(OR(M5>=4,I5<=-8%),"防守",IF(OR(M5>=2,I5<=-5%),"警戒","正常"))) -> 正常 | U5: =IF($A5="","",IF(AND(L5>=3,M5<=2,T5<>"防守"),"是","否")) -> 是 | V5: =IF($A5="","",IF(AND(E5<N5,R5<S5,M5<=2,I5>-15%),"是","否")) -> 是 | W5: =IF($A5="","",IF(OR(M5>=3,I5<=-15%),"是","否")) -> 否 | X5: =IF($A5="","",IFERROR(maxifs(候选池!$AB:$AB,候选池!$A:$A,$A5),0)) -> 0 | Y5: =IF($A5="","",IF(OR(M5>=4,I5<=-8%),MAX(0,B5*60%-C5),IF(AND(ISNUMBER(AD5),B5>AD5),IF(B5<30000,0,IF(B5<100000,MAX(0,(B5-AD5)*0.2),MAX(0,(B5-AD5)*0.3))),0))) -> 0 | AA5: =IF($A5="","",IF($AA$2<>"",$AA$2,"")) -> 6683.54 | AB5: =IF($A5="","",IF(B5<30000,0.03,IF(B5<100000,0.02,0.015))) -> 0.03 | AC5: =IF($A5="","",IFERROR(DATEDIF($A$2,$A5,"m"),0)) -> 2 | AD5: =IF($A5="","",IF(OR(AA5="",AB5="",AC5=""),"",AA5*POWER(1+AB5,AC5))) -> 7090.5676 | AE5: =IF($A5="","",IF(OR(AD5="",AD5=0),"",B5/AD5-1)) -> 0.99537905 | AF5: 2 | AG5: =IF($A5="","",IF(B5<30000,"婴儿",IF(B5<100000,"成长","成熟"))) -> 婴儿 | AH5: 0.7543 | AI5: 0 | AJ5: 0 | AK5: 0 | AL5: 0 | AM5: 0 | AN5: 电子 | AO5: 中盘成长 | AP5: 是 | AQ5: =IF($A5="","",B5-$AA$2-SUM($F$2:F5)) -> 4764.83
A6: 2026-05-31 | B6: 17086.37 | C6: 0 | D6: =IF($A6="","",SUMIFS(持仓表!$J:$J,持仓表!$A:$A,$A6)) -> 0 | E6: =IFERROR(D6/B6,0) -> 0 | F6: 0 | G6: =IF($B6="","",MAX($B$2:B6)) -> 17086.37 | H6: =IFERROR((B6-F6)/F6,0) -> 0 | I6: =IFERROR((B6-G6)/G6,0) -> 0 | J6: 强 | K6: A | L6: 4 | M6: 1 | N6: =IF($B6="","",MIN(70%,IF($I6<=-15%,10%,IF($I6<=-10%,30%,IF($M6>=4,10%,IF($M6>=3,30%,IF($J6="强",IF($K6="A",70%,IF($K6="B",60%,40%)),IF($J6="中性",IF($K6="A",50%,IF($K6="B",40%,25%)),IF($K6="A",30%,IF($K6="B",20%,10%)))))))))) -> 0.7 | O6: =IF($B6="","",IF(B6<30000,35%,IF(B6<50000,30%,IF(B6<100000,25%,20%)))) -> 0.35 | P6: =IF($A6="","",COUNTIFS(持仓表!$A:$A,$A6,持仓表!$G:$G,">0")) -> 0 | Q6: =IF($A6="","",COUNTIFS(持仓表!$A:$A,$A6,持仓表!$D:$D,"是",持仓表!$G:$G,">0")) -> 0 | R6: =IF($A6="","",MAX(0,P6-Q6)) -> 0 | S6: =IF($B6="","",IF(B6<50000,3,IF(B6<100000,4,5))) -> 3 | T6: =IF($A6="","",IF(OR(M6>=4,I6<=-8%),"防守",IF(OR(M6>=2,I6<=-5%),"警戒","正常"))) -> 正常 | U6: =IF($A6="","",IF(AND(L6>=3,M6<=2,T6<>"防守"),"是","否")) -> 是 | V6: =IF($A6="","",IF(AND(E6<N6,R6<S6,M6<=2,I6>-15%),"是","否")) -> 是 | W6: =IF($A6="","",IF(OR(M6>=3,I6<=-15%),"是","否")) -> 否 | X6: =IF($A6="","",IFERROR(maxifs(候选池!$AB:$AB,候选池!$A:$A,$A6),0)) -> 0 | Y6: =IF($A6="","",IF(OR(M6>=4,I6<=-8%),MAX(0,B6*60%-C6),IF(AND(ISNUMBER(AD6),B6>AD6),IF(B6<30000,0,IF(B6<100000,MAX(0,(B6-AD6)*0.2),MAX(0,(B6-AD6)*0.3))),0))) -> 0 | AA6: =IF($A6="","",IF($AA$2<>"",$AA$2,"")) -> 6683.54 | AB6: =IF($A6="","",IF(B6<30000,0.03,IF(B6<100000,0.02,0.015))) -> 0.03 | AC6: =IF($A6="","",IFERROR(DATEDIF($A$2,$A6,"m"),0)) -> 4 | AD6: =IF($A6="","",IF(OR(AA6="",AB6="",AC6=""),"",AA6*POWER(1+AB6,AC6))) -> 7522.3832 | AE6: =IF($A6="","",IF(OR(AD6="",AD6=0),"",B6/AD6-1)) -> 1.2714038 | AF6: 1 | AG6: =IF($A6="","",IF(B6<30000,"婴儿",IF(B6<100000,"成长","成熟"))) -> 婴儿 | AH6: 0.7849 | AI6: 0 | AJ6: 0 | AK6: 0 | AL6: 0 | AM6: 0 | AN6: 电力 | AO6: 中盘价值 | AP6: 是 | AQ6: =IF($A6="","",B6-$AA$2-SUM($F$2:F6)) -> 7702.83
A7: 2026-06-30 | B7: 18504 | C7: 0 | D7: =IF($A7="","",SUMIFS(持仓表!$J:$J,持仓表!$A:$A,$A7)) -> 0 | E7: =IFERROR(D7/B7,0) -> 0 | F7: 0 | G7: =IF($B7="","",MAX($B$2:B7)) -> 18504 | H7: =IFERROR((B7-F7)/F7,0) -> 0 | I7: =IFERROR((B7-G7)/G7,0) -> 0 | J7: 中性 | K7: B | L7: 3 | M7: 2 | N7: =IF($B7="","",MIN(70%,IF($I7<=-15%,10%,IF($I7<=-10%,30%,IF($M7>=4,10%,IF($M7>=3,30%,IF($J7="强",IF($K7="A",70%,IF($K7="B",60%,40%)),IF($J7="中性",IF($K7="A",50%,IF($K7="B",40%,25%)),IF($K7="A",30%,IF($K7="B",20%,10%)))))))))) -> 0.4 | O7: =IF($B7="","",IF(B7<30000,35%,IF(B7<50000,30%,IF(B7<100000,25%,20%)))) -> 0.35 | P7: =IF($A7="","",COUNTIFS(持仓表!$A:$A,$A7,持仓表!$G:$G,">0")) -> 0 | Q7: =IF($A7="","",COUNTIFS(持仓表!$A:$A,$A7,持仓表!$D:$D,"是",持仓表!$G:$G,">0")) -> 0 | R7: =IF($A7="","",MAX(0,P7-Q7)) -> 0 | S7: =IF($B7="","",IF(B7<50000,3,IF(B7<100000,4,5))) -> 3 | T7: =IF($A7="","",IF(OR(M7>=4,I7<=-8%),"防守",IF(OR(M7>=2,I7<=-5%),"警戒","正常"))) -> 警戒 | U7: =IF($A7="","",IF(AND(L7>=3,M7<=2,T7<>"防守"),"是","否")) -> 是 | V7: =IF($A7="","",IF(AND(E7<N7,R7<S7,M7<=2,I7>-15%),"是","否")) -> 是 | W7: =IF($A7="","",IF(OR(M7>=3,I7<=-15%),"是","否")) -> 否 | X7: =IF($A7="","",IFERROR(maxifs(候选池!$AB:$AB,候选池!$A:$A,$A7),0)) -> 0 | Y7: =IF($A7="","",IF(OR(M7>=4,I7<=-8%),MAX(0,B7*60%-C7),IF(AND(ISNUMBER(AD7),B7>AD7),IF(B7<30000,0,IF(B7<100000,MAX(0,(B7-AD7)*0.2),MAX(0,(B7-AD7)*0.3))),0))) -> 0 | AA7: =IF($A7="","",IF($AA$2<>"",$AA$2,"")) -> 6683.54 | AB7: =IF($A7="","",IF(B7<30000,0.03,IF(B7<100000,0.02,0.015))) -> 0.03 | AC7: =IF($A7="","",IFERROR(DATEDIF($A$2,$A7,"m"),0)) -> 4 | AD7: =IF($A7="","",IF(OR(AA7="",AB7="",AC7=""),"",AA7*POWER(1+AB7,AC7))) -> 7522.3832 | AE7: =IF($A7="","",IF(OR(AD7="",AD7=0),"",B7/AD7-1)) -> 1.4598587 | AF7: 2 | AG7: =IF($A7="","",IF(B7<30000,"婴儿",IF(B7<100000,"成长","成熟"))) -> 婴儿 | AH7: 0.7012 | AI7: 80 | AJ7: 1 | AK7: 0.3937 | AL7: 0 | AM7: 0 | AN7: 电力 | AO7: 中盘价值 | AP7: 是 | AQ7: =IF($A7="","",B7-$AA$2-SUM($F$2:F7)) -> 9120.46
A8: 46224 | B8: 20326.12 | C8: 7847.12 | D8: =IF($A8="","",SUMIFS(持仓表!$J:$J,持仓表!$A:$A,$A8)) -> 10642 | E8: =IFERROR(D8/B8,0) -> 0.52356279 | F8: 1309 | G8: =IF($B8="","",MAX($B$2:B8)) -> 20326.12 | H8: =IFERROR((B8-F8)/F8,0) -> 14.527976 | I8: =IFERROR((B8-G8)/G8,0) -> 0 | J8: 中性 | K8: B | L8: 3 | M8: 2 | N8: =IF($B8="","",MIN(70%,IF($I8<=-15%,10%,IF($I8<=-10%,30%,IF($M8>=4,10%,IF($M8>=3,30%,IF($J8="强",IF($K8="A",70%,IF($K8="B",60%,40%)),IF($J8="中性",IF($K8="A",50%,IF($K8="B",40%,25%)),IF($K8="A",30%,IF($K8="B",20%,10%)))))))))) -> 0.4 | O8: =IF($B8="","",IF(B8<30000,35%,IF(B8<50000,30%,IF(B8<100000,25%,20%)))) -> 0.35 | P8: =IF($A8="","",COUNTIFS(持仓表!$A:$A,$A8,持仓表!$G:$G,">0")) -> 3 | Q8: =IF($A8="","",COUNTIFS(持仓表!$A:$A,$A8,持仓表!$D:$D,"是",持仓表!$G:$G,">0")) -> 1 | R8: =IF($A8="","",MAX(0,P8-Q8)) -> 2 | S8: =IF($B8="","",IF(B8<50000,3,IF(B8<100000,4,5))) -> 3 | T8: =IF($A8="","",IF(OR(M8>=4,I8<=-8%),"防守",IF(OR(M8>=2,I8<=-5%),"警戒","正常"))) -> 警戒 | U8: =IF($A8="","",IF(AND(L8>=3,M8<=2,T8<>"防守"),"是","否")) -> 是 | V8: =IF($A8="","",IF(AND(E8<N8,R8<S8,M8<=2,I8>-15%),"是","否")) -> 否 | W8: =IF($A8="","",IF(OR(M8>=3,I8<=-15%),"是","否")) -> 否 | X8: =IF($A8="","",IFERROR(maxifs(候选池!$AB:$AB,候选池!$A:$A,$A8),0)) -> 0 | Y8: =IF($A8="","",IF(OR(M8>=4,I8<=-8%),MAX(0,B8*60%-C8),IF(AND(ISNUMBER(AD8),B8>AD8),IF(B8<30000,0,IF(B8<100000,MAX(0,(B8-AD8)*0.2),MAX(0,(B8-AD8)*0.3))),0))) -> 0 | Z8: 12:36录入,当日盈亏-143元 | AA8: =IF($A8="","",IF($AA$2<>"",$AA$2,"")) -> 6683.54 | AB8: =IF($A8="","",IF(B8<30000,0.03,IF(B8<100000,0.02,0.015))) -> 0.03 | AC8: =IF($A8="","",IFERROR(DATEDIF($A$2,$A8,"m"),0)) -> 5 | AD8: =IF($A8="","",IF(OR(AA8="",AB8="",AC8=""),"",AA8*POWER(1+AB8,AC8))) -> 7748.0546 | AE8: =IF($A8="","",IF(OR(AD8="",AD8=0),"",B8/AD8-1)) -> 1.6233837 | AF8: 2 | AG8: =IF($A8="","",IF(B8<30000,"婴儿",IF(B8<100000,"成长","成熟"))) -> 婴儿 | AH8: 0.3423 | AI8: 5 | AJ8: 1 | AK8: 0.0058 | AL8: 1 | AM8: 0 | AN8: 化工 | AO8: 大盘价值 | AP8: 是 | AQ8: =IF($A8="","",B8-$AA$2-SUM($F$2:F8)) -> 9633.58
A9: 46225 | B9: 20798.12 | C9: 7847.12 | D9: =IF($A9="","",SUMIFS(持仓表!$J:$J,持仓表!$A:$A,$A9)) -> 0 | E9: =IFERROR(D9/B9,0) -> 0 | G9: =IF($B9="","",MAX($B$2:B9)) -> 20798.12 | H9: =IFERROR((B9-F9)/F9,0) -> 0 | I9: =IFERROR((B9-G9)/G9,0) -> 0 | N9: =IF($B9="","",MIN(70%,IF($I9<=-15%,10%,IF($I9<=-10%,30%,IF($M9>=4,10%,IF($M9>=3,30%,IF($J9="强",IF($K9="A",70%,IF($K9="B",60%,40%)),IF($J9="中性",IF($K9="A",50%,IF($K9="B",40%,25%)),IF($K9="A",30%,IF($K9="B",20%,10%)))))))))) -> 0.1 | O9: =IF($B9="","",IF(B9<30000,35%,IF(B9<50000,30%,IF(B9<100000,25%,20%)))) -> 0.35 | P9: =IF($A9="","",COUNTIFS(持仓表!$A:$A,$A9,持仓表!$G:$G,">0")) -> 0 | Q9: =IF($A9="","",COUNTIFS(持仓表!$A:$A,$A9,持仓表!$D:$D,"是",持仓表!$G:$G,">0")) -> 0 | R9: =IF($A9="","",MAX(0,P9-Q9)) -> 0 | S9: =IF($B9="","",IF(B9<50000,3,IF(B9<100000,4,5))) -> 3 | T9: =IF($A9="","",IF(OR(M9>=4,I9<=-8%),"防守",IF(OR(M9>=2,I9<=-5%),"警戒","正常"))) -> 正常 | U9: =IF($A9="","",IF(AND(L9>=3,M9<=2,T9<>"防守"),"是","否")) -> 否 | V9: =IF($A9="","",IF(AND(E9<N9,R9<S9,M9<=2,I9>-15%),"是","否")) -> 是 | W9: =IF($A9="","",IF(OR(M9>=3,I9<=-15%),"是","否")) -> 否 | X9: =IF($A9="","",IFERROR(maxifs(候选池!$AB:$AB,候选池!$A:$A,$A9),0)) -> 0 | Y9: =IF($A9="","",IF(OR(M9>=4,I9<=-8%),MAX(0,B9*60%-C9),IF(AND(ISNUMBER(AD9),B9>AD9),IF(B9<30000,0,IF(B9<100000,MAX(0,(B9-AD9)*0.2),MAX(0,(B9-AD9)*0.3))),0))) -> 0 | AA9: =IF($A9="","",IF($AA$2<>"",$AA$2,"")) -> 6683.54 | AB9: =IF($A9="","",IF(B9<30000,0.03,IF(B9<100000,0.02,0.015))) -> 0.03 | AC9: =IF($A9="","",IFERROR(DATEDIF($A$2,$A9,"m"),0)) -> 5 | AD9: =IF($A9="","",IF(OR(AA9="",AB9="",AC9=""),"",AA9*POWER(1+AB9,AC9))) -> 7748.0546 | AE9: =IF($A9="","",IF(OR(AD9="",AD9=0),"",B9/AD9-1)) -> 1.6843022 | AG9: =IF($A9="","",IF(B9<30000,"婴儿",IF(B9<100000,"成长","成熟"))) -> 婴儿 | AQ9: =IF($A9="","",B9-$AA$2-SUM($F$2:F9)) -> 10105.58
A10: 46226 | B10: 20959.73 | C10: 10362.73 | D10: =IF($A10="","",SUMIFS(持仓表!$J:$J,持仓表!$A:$A,$A10)) -> 0 | E10: =IFERROR(D10/B10,0) -> 0 | G10: =IF($B10="","",MAX($B$2:B10)) -> 20959.73 | H10: =IFERROR((B10-F10)/F10,0) -> 0 | I10: =IFERROR((B10-G10)/G10,0) -> 0 | N10: =IF($B10="","",MIN(70%,IF($I10<=-15%,10%,IF($I10<=-10%,30%,IF($M10>=4,10%,IF($M10>=3,30%,IF($J10="强",IF($K10="A",70%,IF($K10="B",60%,40%)),IF($J10="中性",IF($K10="A",50%,IF($K10="B",40%,25%)),IF($K10="A",30%,IF($K10="B",20%,10%)))))))))) -> 0.1 | O10: =IF($B10="","",IF(B10<30000,35%,IF(B10<50000,30%,IF(B10<100000,25%,20%)))) -> 0.35 | P10: =IF($A10="","",COUNTIFS(持仓表!$A:$A,$A10,持仓表!$G:$G,">0")) -> 0 | Q10: =IF($A10="","",COUNTIFS(持仓表!$A:$A,$A10,持仓表!$D:$D,"是",持仓表!$G:$G,">0")) -> 0 | R10: =IF($A10="","",MAX(0,P10-Q10)) -> 0 | S10: =IF($B10="","",IF(B10<50000,3,IF(B10<100000,4,5))) -> 3 | T10: =IF($A10="","",IF(OR(M10>=4,I10<=-8%),"防守",IF(OR(M10>=2,I10<=-5%),"警戒","正常"))) -> 正常 | U10: =IF($A10="","",IF(AND(L10>=3,M10<=2,T10<>"防守"),"是","否")) -> 否 | V10: =IF($A10="","",IF(AND(E10<N10,R10<S10,M10<=2,I10>-15%),"是","否")) -> 是 | W10: =IF($A10="","",IF(OR(M10>=3,I10<=-15%),"是","否")) -> 否 | X10: =IF($A10="","",IFERROR(maxifs(候选池!$AB:$AB,候选池!$A:$A,$A10),0)) -> 0 | Y10: =IF($A10="","",IF(OR(M10>=4,I10<=-8%),MAX(0,B10*60%-C10),IF(AND(ISNUMBER(AD10),B10>AD10),IF(B10<30000,0,IF(B10<100000,MAX(0,(B10-AD10)*0.2),MAX(0,(B10-AD10)*0.3))),0))) -> 0 | AA10: =IF($A10="","",IF($AA$2<>"",$AA$2,"")) -> 6683.54 | AB10: =IF($A10="","",IF(B10<30000,0.03,IF(B10<100000,0.02,0.015))) -> 0.03 | AC10: =IF($A10="","",IFERROR(DATEDIF($A$2,$A10,"m"),0)) -> 5 | AD10: =IF($A10="","",IF(OR(AA10="",AB10="",AC10=""),"",AA10*POWER(1+AB10,AC10))) -> 7748.0546 | AE10: =IF($A10="","",IF(OR(AD10="",AD10=0),"",B10/AD10-1)) -> 1.7051603 | AG10: =IF($A10="","",IF(B10<30000,"婴儿",IF(B10<100000,"成长","成熟"))) -> 婴儿 | AQ10: =IF($A10="","",B10-$AA$2-SUM($F$2:F10)) -> 10267.19
A11: 46226 | B11: 21004.83 | C11: 10362.83 | D11: =IF($A11="","",SUMIFS(持仓表!$J:$J,持仓表!$A:$A,$A11)) -> 0 | E11: =IFERROR(D11/B11,0) -> 0 | G11: =IF($B11="","",MAX($B$2:B11)) -> 21004.83 | H11: =IFERROR((B11-F11)/F11,0) -> 0 | I11: =IFERROR((B11-G11)/G11,0) -> 0 | N11: =IF($B11="","",MIN(70%,IF($I11<=-15%,10%,IF($I11<=-10%,30%,IF($M11>=4,10%,IF($M11>=3,30%,IF($J11="强",IF($K11="A",70%,IF($K11="B",60%,40%)),IF($J11="中性",IF($K11="A",50%,IF($K11="B",40%,25%)),IF($K11="A",30%,IF($K11="B",20%,10%)))))))))) -> 0.1 | O11: =IF($B11="","",IF(B11<30000,35%,IF(B11<50000,30%,IF(B11<100000,25%,20%)))) -> 0.35 | P11: =IF($A11="","",COUNTIFS(持仓表!$A:$A,$A11,持仓表!$G:$G,">0")) -> 0 | Q11: =IF($A11="","",COUNTIFS(持仓表!$A:$A,$A11,持仓表!$D:$D,"是",持仓表!$G:$G,">0")) -> 0 | R11: =IF($A11="","",MAX(0,P11-Q11)) -> 0 | S11: =IF($B11="","",IF(B11<50000,3,IF(B11<100000,4,5))) -> 3 | T11: =IF($A11="","",IF(OR(M11>=4,I11<=-8%),"防守",IF(OR(M11>=2,I11<=-5%),"警戒","正常"))) -> 正常 | U11: =IF($A11="","",IF(AND(L11>=3,M11<=2,T11<>"防守"),"是","否")) -> 否 | V11: =IF($A11="","",IF(AND(E11<N11,R11<S11,M11<=2,I11>-15%),"是","否")) -> 是 | W11: =IF($A11="","",IF(OR(M11>=3,I11<=-15%),"是","否")) -> 否 | X11: =IF($A11="","",IFERROR(maxifs(候选池!$AB:$AB,候选池!$A:$A,$A11),0)) -> 0 | Y11: =IF($A11="","",IF(OR(M11>=4,I11<=-8%),MAX(0,B11*60%-C11),IF(AND(ISNUMBER(AD11),B11>AD11),IF(B11<30000,0,IF(B11<100000,MAX(0,(B11-AD11)*0.2),MAX(0,(B11-AD11)*0.3))),0))) -> 0 | AA11: =IF($A11="","",IF($AA$2<>"",$AA$2,"")) -> 6683.54 | AB11: =IF($A11="","",IF(B11<30000,0.03,IF(B11<100000,0.02,0.015))) -> 0.03 | AC11: =IF($A11="","",IFERROR(DATEDIF($A$2,$A11,"m"),0)) -> 5 | AD11: =IF($A11="","",IF(OR(AA11="",AB11="",AC11=""),"",AA11*POWER(1+AB11,AC11))) -> 7748.0546 | AE11: =IF($A11="","",IF(OR(AD11="",AD11=0),"",B11/AD11-1)) -> 1.7109811 | AG11: =IF($A11="","",IF(B11<30000,"婴儿",IF(B11<100000,"成长","成熟"))) -> 婴儿 | AQ11: =IF($A11="","",B11-$AA$2-SUM($F$2:F11)) -> 10312.29
A12: 46227 | B12: 20842.32 | C12: 12358.32 | D12: =IF($A12="","",SUMIFS(持仓表!$J:$J,持仓表!$A:$A,$A12)) -> 8484 | E12: =IFERROR(D12/B12,0) -> 0.40705641 | F12: 0 | G12: =IF($B12="","",MAX($B$2:B12)) -> 21004.83 | H12: =IFERROR((B12-F12)/F12,0) -> 0 | I12: =IFERROR((B12-G12)/G12,0) -> -0.007736792 | N12: =IF($B12="","",MIN(70%,IF($I12<=-15%,10%,IF($I12<=-10%,30%,IF($M12>=4,10%,IF($M12>=3,30%,IF($J12="强",IF($K12="A",70%,IF($K12="B",60%,40%)),IF($J12="中性",IF($K12="A",50%,IF($K12="B",40%,25%)),IF($K12="A",30%,IF($K12="B",20%,10%)))))))))) -> 0.1 | O12: =IF($B12="","",IF(B12<30000,35%,IF(B12<50000,30%,IF(B12<100000,25%,20%)))) -> 0.35 | P12: =IF($A12="","",COUNTIFS(持仓表!$A:$A,$A12,持仓表!$G:$G,">0")) -> 7 | Q12: =IF($A12="","",COUNTIFS(持仓表!$A:$A,$A12,持仓表!$D:$D,"是",持仓表!$G:$G,">0")) -> 1 | R12: =IF($A12="","",MAX(0,P12-Q12)) -> 6 | S12: =IF($B12="","",IF(B12<50000,3,IF(B12<100000,4,5))) -> 3 | T12: =IF($A12="","",IF(OR(M12>=4,I12<=-8%),"防守",IF(OR(M12>=2,I12<=-5%),"警戒","正常"))) -> 正常 | U12: =IF($A12="","",IF(AND(L12>=3,M12<=2,T12<>"防守"),"是","否")) -> 否 | V12: =IF($A12="","",IF(AND(E12<N12,R12<S12,M12<=2,I12>-15%),"是","否")) -> 否 | W12: =IF($A12="","",IF(OR(M12>=3,I12<=-15%),"是","否")) -> 否 | X12: =IF($A12="","",IFERROR(maxifs(候选池!$AB:$AB,候选池!$A:$A,$A12),0)) -> 0 | Y12: =IF($A12="","",IF(OR(M12>=4,I12<=-8%),MAX(0,B12*60%-C12),IF(AND(ISNUMBER(AD12),B12>AD12),IF(B12<30000,0,IF(B12<100000,MAX(0,(B12-AD12)*0.2),MAX(0,(B12-AD12)*0.3))),0))) -> 0 | AA12: =IF($A12="","",IF($AA$2<>"",$AA$2,"")) -> 6683.54 | AB12: =IF($A12="","",IF(B12<30000,0.03,IF(B12<100000,0.02,0.015))) -> 0.03 | AC12: =IF($A12="","",IFERROR(DATEDIF($A$2,$A12,"m"),0)) -> 5 | AD12: =IF($A12="","",IF(OR(AA12="",AB12="",AC12=""),"",AA12*POWER(1+AB12,AC12))) -> 7748.0546 | AE12: =IF($A12="","",IF(OR(AD12="",AD12=0),"",B12/AD12-1)) -> 1.6900068 | AG12: =IF($A12="","",IF(B12<30000,"婴儿",IF(B12<100000,"成长","成熟"))) -> 婴儿 | AQ12: =IF($A12="","",B12-$AA$2-SUM($F$2:F12)) -> 10149.78
D13: =IF($A13="","",SUMIFS(持仓表!$J:$J,持仓表!$A:$A,$A13)) | E13: =IFERROR(D13/B13,0) -> 0 | G13: =IF($B13="","",MAX($B$2:B13)) | H13: =IFERROR((B13-F13)/F13,0) -> 0 | I13: =IFERROR((B13-G13)/G13,0) -> 0 | N13: =IF($B13="","",MIN(70%,IF($I13<=-15%,10%,IF($I13<=-10%,30%,IF($M13>=4,10%,IF($M13>=3,30%,IF($J13="强",IF($K13="A",70%,IF($K13="B",60%,40%)),IF($J13="中性",IF($K13="A",50%,IF($K13="B",40%,25%)),IF($K13="A",30%,IF($K13="B",20%,10%)))))))))) | O13: =IF($B13="","",IF(B13<30000,35%,IF(B13<50000,30%,IF(B13<100000,25%,20%)))) | P13: =IF($A13="","",COUNTIFS(持仓表!$A:$A,$A13,持仓表!$G:$G,">0")) | Q13: =IF($A13="","",COUNTIFS(持仓表!$A:$A,$A13,持仓表!$D:$D,"是",持仓表!$G:$G,">0")) | R13: =IF($A13="","",MAX(0,P13-Q13)) | S13: =IF($B13="","",IF(B13<50000,3,IF(B13<100000,4,5))) | T13: =IF($A13="","",IF(OR(M13>=4,I13<=-8%),"防守",IF(OR(M13>=2,I13<=-5%),"警戒","正常"))) | U13: =IF($A13="","",IF(AND(L13>=3,M13<=2,T13<>"防守"),"是","否")) | V13: =IF($A13="","",IF(AND(E13<N13,R13<S13,M13<=2,I13>-15%),"是","否")) | W13: =IF($A13="","",IF(OR(M13>=3,I13<=-15%),"是","否")) | X13: =IF($A13="","",IFERROR(maxifs(候选池!$AB:$AB,候选池!$A:$A,$A13),0)) | Y13: =IF($A13="","",IF(OR(M13>=4,I13<=-8%),MAX(0,B13*60%-C13),IF(AND(ISNUMBER(AD13),B13>AD13),IF(B13<30000,0,IF(B13<100000,MAX(0,(B13-AD13)*0.2),MAX(0,(B13-AD13)*0.3))),0))) | AA13: =IF($A13="","",IF($AA$2<>"",$AA$2,"")) | AB13: =IF($A13="","",IF(B13<30000,0.03,IF(B13<100000,0.02,0.015))) | AC13: =IF($A13="","",IFERROR(DATEDIF($A$2,$A13,"m"),0)) | AD13: =IF($A13="","",IF(OR(AA13="",AB13="",AC13=""),"",AA13*POWER(1+AB13,AC13))) | AE13: =IF($A13="","",IF(OR(AD13="",AD13=0),"",B13/AD13-1)) | AG13: =IF($A13="","",IF(B13<30000,"婴儿",IF(B13<100000,"成长","成熟"))) | AQ13: =IF($A13="","",B13-$AA$2-SUM($F$2:F13))
D14: =IF($A14="","",SUMIFS(持仓表!$J:$J,持仓表!$A:$A,$A14)) | E14: =IFERROR(D14/B14,0) -> 0 | G14: =IF($B14="","",MAX($B$2:B14)) | H14: =IFERROR((B14-F14)/F14,0) -> 0 | I14: =IFERROR((B14-G14)/G14,0) -> 0 | N14: =IF($B14="","",MIN(70%,IF($I14<=-15%,10%,IF($I14<=-10%,30%,IF($M14>=4,10%,IF($M14>=3,30%,IF($J14="强",IF($K14="A",70%,IF($K14="B",60%,40%)),IF($J14="中性",IF($K14="A",50%,IF($K14="B",40%,25%)),IF($K14="A",30%,IF($K14="B",20%,10%)))))))))) | O14: =IF($B14="","",IF(B14<30000,35%,IF(B14<50000,30%,IF(B14<100000,25%,20%)))) | P14: =IF($A14="","",COUNTIFS(持仓表!$A:$A,$A14,持仓表!$G:$G,">0")) | Q14: =IF($A14="","",COUNTIFS(持仓表!$A:$A,$A14,持仓表!$D:$D,"是",持仓表!$G:$G,">0")) | R14: =IF($A14="","",MAX(0,P14-Q14)) | S14: =IF($B14="","",IF(B14<50000,3,IF(B14<100000,4,5))) | T14: =IF($A14="","",IF(OR(M14>=4,I14<=-8%),"防守",IF(OR(M14>=2,I14<=-5%),"警戒","正常"))) | U14: =IF($A14="","",IF(AND(L14>=3,M14<=2,T14<>"防守"),"是","否")) | V14: =IF($A14="","",IF(AND(E14<N14,R14<S14,M14<=2,I14>-15%),"是","否")) | W14: =IF($A14="","",IF(OR(M14>=3,I14<=-15%),"是","否")) | X14: =IF($A14="","",IFERROR(maxifs(候选池!$AB:$AB,候选池!$A:$A,$A14),0)) | Y14: =IF($A14="","",IF(OR(M14>=4,I14<=-8%),MAX(0,B14*60%-C14),IF(AND(ISNUMBER(AD14),B14>AD14),IF(B14<30000,0,IF(B14<100000,MAX(0,(B14-AD14)*0.2),MAX(0,(B14-AD14)*0.3))),0))) | AA14: =IF($A14="","",IF($AA$2<>"",$AA$2,"")) | AB14: =IF($A14="","",IF(B14<30000,0.03,IF(B14<100000,0.02,0.015))) | AC14: =IF($A14="","",IFERROR(DATEDIF($A$2,$A14,"m"),0)) | AD14: =IF($A14="","",IF(OR(AA14="",AB14="",AC14=""),"",AA14*POWER(1+AB14,AC14))) | AE14: =IF($A14="","",IF(OR(AD14="",AD14=0),"",B14/AD14-1)) | AG14: =IF($A14="","",IF(B14<30000,"婴儿",IF(B14<100000,"成长","成熟"))) | AQ14: =IF($A14="","",B14-$AA$2-SUM($F$2:F14))
D15: =IF($A15="","",SUMIFS(持仓表!$J:$J,持仓表!$A:$A,$A15)) | E15: =IFERROR(D15/B15,0) -> 0 | G15: =IF($B15="","",MAX($B$2:B15)) | H15: =IFERROR((B15-F15)/F15,0) -> 0 | I15: =IFERROR((B15-G15)/G15,0) -> 0 | N15: =IF($B15="","",MIN(70%,IF($I15<=-15%,10%,IF($I15<=-10%,30%,IF($M15>=4,10%,IF($M15>=3,30%,IF($J15="强",IF($K15="A",70%,IF($K15="B",60%,40%)),IF($J15="中性",IF($K15="A",50%,IF($K15="B",40%,25%)),IF($K15="A",30%,IF($K15="B",20%,10%)))))))))) | O15: =IF($B15="","",IF(B15<30000,35%,IF(B15<50000,30%,IF(B15<100000,25%,20%)))) | P15: =IF($A15="","",COUNTIFS(持仓表!$A:$A,$A15,持仓表!$G:$G,">0")) | Q15: =IF($A15="","",COUNTIFS(持仓表!$A:$A,$A15,持仓表!$D:$D,"是",持仓表!$G:$G,">0")) | R15: =IF($A15="","",MAX(0,P15-Q15)) | S15: =IF($B15="","",IF(B15<50000,3,IF(B15<100000,4,5))) | T15: =IF($A15="","",IF(OR(M15>=4,I15<=-8%),"防守",IF(OR(M15>=2,I15<=-5%),"警戒","正常"))) | U15: =IF($A15="","",IF(AND(L15>=3,M15<=2,T15<>"防守"),"是","否")) | V15: =IF($A15="","",IF(AND(E15<N15,R15<S15,M15<=2,I15>-15%),"是","否")) | W15: =IF($A15="","",IF(OR(M15>=3,I15<=-15%),"是","否")) | X15: =IF($A15="","",IFERROR(maxifs(候选池!$AB:$AB,候选池!$A:$A,$A15),0)) | Y15: =IF($A15="","",IF(OR(M15>=4,I15<=-8%),MAX(0,B15*60%-C15),IF(AND(ISNUMBER(AD15),B15>AD15),IF(B15<30000,0,IF(B15<100000,MAX(0,(B15-AD15)*0.2),MAX(0,(B15-AD15)*0.3))),0))) | AA15: =IF($A15="","",IF($AA$2<>"",$AA$2,"")) | AB15: =IF($A15="","",IF(B15<30000,0.03,IF(B15<100000,0.02,0.015))) | AC15: =IF($A15="","",IFERROR(DATEDIF($A$2,$A15,"m"),0)) | AD15: =IF($A15="","",IF(OR(AA15="",AB15="",AC15=""),"",AA15*POWER(1+AB15,AC15))) | AE15: =IF($A15="","",IF(OR(AD15="",AD15=0),"",B15/AD15-1)) | AG15: =IF($A15="","",IF(B15<30000,"婴儿",IF(B15<100000,"成长","成熟"))) | AQ15: =IF($A15="","",B15-$AA$2-SUM($F$2:F15))
D16: =IF($A16="","",SUMIFS(持仓表!$J:$J,持仓表!$A:$A,$A16)) | E16: =IFERROR(D16/B16,0) -> 0 | G16: =IF($B16="","",MAX($B$2:B16)) | H16: =IFERROR((B16-F16)/F16,0) -> 0 | I16: =IFERROR((B16-G16)/G16,0) -> 0 | N16: =IF($B16="","",MIN(70%,IF($I16<=-15%,10%,IF($I16<=-10%,30%,IF($M16>=4,10%,IF($M16>=3,30%,IF($J16="强",IF($K16="A",70%,IF($K16="B",60%,40%)),IF($J16="中性",IF($K16="A",50%,IF($K16="B",40%,25%)),IF($K16="A",30%,IF($K16="B",20%,10%)))))))))) | O16: =IF($B16="","",IF(B16<30000,35%,IF(B16<50000,30%,IF(B16<100000,25%,20%)))) | P16: =IF($A16="","",COUNTIFS(持仓表!$A:$A,$A16,持仓表!$G:$G,">0")) | Q16: =IF($A16="","",COUNTIFS(持仓表!$A:$A,$A16,持仓表!$D:$D,"是",持仓表!$G:$G,">0")) | R16: =IF($A16="","",MAX(0,P16-Q16)) | S16: =IF($B16="","",IF(B16<50000,3,IF(B16<100000,4,5))) | T16: =IF($A16="","",IF(OR(M16>=4,I16<=-8%),"防守",IF(OR(M16>=2,I16<=-5%),"警戒","正常"))) | U16: =IF($A16="","",IF(AND(L16>=3,M16<=2,T16<>"防守"),"是","否")) | V16: =IF($A16="","",IF(AND(E16<N16,R16<S16,M16<=2,I16>-15%),"是","否")) | W16: =IF($A16="","",IF(OR(M16>=3,I16<=-15%),"是","否")) | X16: =IF($A16="","",IFERROR(maxifs(候选池!$AB:$AB,候选池!$A:$A,$A16),0)) | Y16: =IF($A16="","",IF(OR(M16>=4,I16<=-8%),MAX(0,B16*60%-C16),IF(AND(ISNUMBER(AD16),B16>AD16),IF(B16<30000,0,IF(B16<100000,MAX(0,(B16-AD16)*0.2),MAX(0,(B16-AD16)*0.3))),0))) | AA16: =IF($A16="","",IF($AA$2<>"",$AA$2,"")) | AB16: =IF($A16="","",IF(B16<30000,0.03,IF(B16<100000,0.02,0.015))) | AC16: =IF($A16="","",IFERROR(DATEDIF($A$2,$A16,"m"),0)) | AD16: =IF($A16="","",IF(OR(AA16="",AB16="",AC16=""),"",AA16*POWER(1+AB16,AC16))) | AE16: =IF($A16="","",IF(OR(AD16="",AD16=0),"",B16/AD16-1)) | AG16: =IF($A16="","",IF(B16<30000,"婴儿",IF(B16<100000,"成长","成熟"))) | AQ16: =IF($A16="","",B16-$AA$2-SUM($F$2:F16))
D17: =IF($A17="","",SUMIFS(持仓表!$J:$J,持仓表!$A:$A,$A17)) | E17: =IFERROR(D17/B17,0) -> 0 | G17: =IF($B17="","",MAX($B$2:B17)) | H17: =IFERROR((B17-F17)/F17,0) -> 0 | I17: =IFERROR((B17-G17)/G17,0) -> 0 | N17: =IF($B17="","",MIN(70%,IF($I17<=-15%,10%,IF($I17<=-10%,30%,IF($M17>=4,10%,IF($M17>=3,30%,IF($J17="强",IF($K17="A",70%,IF($K17="B",60%,40%)),IF($J17="中性",IF($K17="A",50%,IF($K17="B",40%,25%)),IF($K17="A",30%,IF($K17="B",20%,10%)))))))))) | O17: =IF($B17="","",IF(B17<30000,35%,IF(B17<50000,30%,IF(B17<100000,25%,20%)))) | P17: =IF($A17="","",COUNTIFS(持仓表!$A:$A,$A17,持仓表!$G:$G,">0")) | Q17: =IF($A17="","",COUNTIFS(持仓表!$A:$A,$A17,持仓表!$D:$D,"是",持仓表!$G:$G,">0")) | R17: =IF($A17="","",MAX(0,P17-Q17)) | S17: =IF($B17="","",IF(B17<50000,3,IF(B17<100000,4,5))) | T17: =IF($A17="","",IF(OR(M17>=4,I17<=-8%),"防守",IF(OR(M17>=2,I17<=-5%),"警戒","正常"))) | U17: =IF($A17="","",IF(AND(L17>=3,M17<=2,T17<>"防守"),"是","否")) | V17: =IF($A17="","",IF(AND(E17<N17,R17<S17,M17<=2,I17>-15%),"是","否")) | W17: =IF($A17="","",IF(OR(M17>=3,I17<=-15%),"是","否")) | X17: =IF($A17="","",IFERROR(maxifs(候选池!$AB:$AB,候选池!$A:$A,$A17),0)) | Y17: =IF($A17="","",IF(OR(M17>=4,I17<=-8%),MAX(0,B17*60%-C17),IF(AND(ISNUMBER(AD17),B17>AD17),IF(B17<30000,0,IF(B17<100000,MAX(0,(B17-AD17)*0.2),MAX(0,(B17-AD17)*0.3))),0))) | AA17: =IF($A17="","",IF($AA$2<>"",$AA$2,"")) | AB17: =IF($A17="","",IF(B17<30000,0.03,IF(B17<100000,0.02,0.015))) | AC17: =IF($A17="","",IFERROR(DATEDIF($A$2,$A17,"m"),0)) | AD17: =IF($A17="","",IF(OR(AA17="",AB17="",AC17=""),"",AA17*POWER(1+AB17,AC17))) | AE17: =IF($A17="","",IF(OR(AD17="",AD17=0),"",B17/AD17-1)) | AG17: =IF($A17="","",IF(B17<30000,"婴儿",IF(B17<100000,"成长","成熟"))) | AQ17: =IF($A17="","",B17-$AA$2-SUM($F$2:F17))
D18: =IF($A18="","",SUMIFS(持仓表!$J:$J,持仓表!$A:$A,$A18)) | E18: =IFERROR(D18/B18,0) -> 0 | G18: =IF($B18="","",MAX($B$2:B18)) | H18: =IFERROR((B18-F18)/F18,0) -> 0 | I18: =IFERROR((B18-G18)/G18,0) -> 0 | N18: =IF($B18="","",MIN(70%,IF($I18<=-15%,10%,IF($I18<=-10%,30%,IF($M18>=4,10%,IF($M18>=3,30%,IF($J18="强",IF($K18="A",70%,IF($K18="B",60%,40%)),IF($J18="中性",IF($K18="A",50%,IF($K18="B",40%,25%)),IF($K18="A",30%,IF($K18="B",20%,10%)))))))))) | O18: =IF($B18="","",IF(B18<30000,35%,IF(B18<50000,30%,IF(B18<100000,25%,20%)))) | P18: =IF($A18="","",COUNTIFS(持仓表!$A:$A,$A18,持仓表!$G:$G,">0")) | Q18: =IF($A18="","",COUNTIFS(持仓表!$A:$A,$A18,持仓表!$D:$D,"是",持仓表!$G:$G,">0")) | R18: =IF($A18="","",MAX(0,P18-Q18)) | S18: =IF($B18="","",IF(B18<50000,3,IF(B18<100000,4,5))) | T18: =IF($A18="","",IF(OR(M18>=4,I18<=-8%),"防守",IF(OR(M18>=2,I18<=-5%),"警戒","正常"))) | U18: =IF($A18="","",IF(AND(L18>=3,M18<=2,T18<>"防守"),"是","否")) | V18: =IF($A18="","",IF(AND(E18<N18,R18<S18,M18<=2,I18>-15%),"是","否")) | W18: =IF($A18="","",IF(OR(M18>=3,I18<=-15%),"是","否")) | X18: =IF($A18="","",IFERROR(maxifs(候选池!$AB:$AB,候选池!$A:$A,$A18),0)) | Y18: =IF($A18="","",IF(OR(M18>=4,I18<=-8%),MAX(0,B18*60%-C18),IF(AND(ISNUMBER(AD18),B18>AD18),IF(B18<30000,0,IF(B18<100000,MAX(0,(B18-AD18)*0.2),MAX(0,(B18-AD18)*0.3))),0))) | AA18: =IF($A18="","",IF($AA$2<>"",$AA$2,"")) | AB18: =IF($A18="","",IF(B18<30000,0.03,IF(B18<100000,0.02,0.015))) | AC18: =IF($A18="","",IFERROR(DATEDIF($A$2,$A18,"m"),0)) | AD18: =IF($A18="","",IF(OR(AA18="",AB18="",AC18=""),"",AA18*POWER(1+AB18,AC18))) | AE18: =IF($A18="","",IF(OR(AD18="",AD18=0),"",B18/AD18-1)) | AG18: =IF($A18="","",IF(B18<30000,"婴儿",IF(B18<100000,"成长","成熟"))) | AQ18: =IF($A18="","",B18-$AA$2-SUM($F$2:F18))
D19: =IF($A19="","",SUMIFS(持仓表!$J:$J,持仓表!$A:$A,$A19)) | E19: =IFERROR(D19/B19,0) -> 0 | G19: =IF($B19="","",MAX($B$2:B19)) | H19: =IFERROR((B19-F19)/F19,0) -> 0 | I19: =IFERROR((B19-G19)/G19,0) -> 0 | N19: =IF($B19="","",MIN(70%,IF($I19<=-15%,10%,IF($I19<=-10%,30%,IF($M19>=4,10%,IF($M19>=3,30%,IF($J19="强",IF($K19="A",70%,IF($K19="B",60%,40%)),IF($J19="中性",IF($K19="A",50%,IF($K19="B",40%,25%)),IF($K19="A",30%,IF($K19="B",20%,10%)))))))))) | O19: =IF($B19="","",IF(B19<30000,35%,IF(B19<50000,30%,IF(B19<100000,25%,20%)))) | P19: =IF($A19="","",COUNTIFS(持仓表!$A:$A,$A19,持仓表!$G:$G,">0")) | Q19: =IF($A19="","",COUNTIFS(持仓表!$A:$A,$A19,持仓表!$D:$D,"是",持仓表!$G:$G,">0")) | R19: =IF($A19="","",MAX(0,P19-Q19)) | S19: =IF($B19="","",IF(B19<50000,3,IF(B19<100000,4,5))) | T19: =IF($A19="","",IF(OR(M19>=4,I19<=-8%),"防守",IF(OR(M19>=2,I19<=-5%),"警戒","正常"))) | U19: =IF($A19="","",IF(AND(L19>=3,M19<=2,T19<>"防守"),"是","否")) | V19: =IF($A19="","",IF(AND(E19<N19,R19<S19,M19<=2,I19>-15%),"是","否")) | W19: =IF($A19="","",IF(OR(M19>=3,I19<=-15%),"是","否")) | X19: =IF($A19="","",IFERROR(maxifs(候选池!$AB:$AB,候选池!$A:$A,$A19),0)) | Y19: =IF($A19="","",IF(OR(M19>=4,I19<=-8%),MAX(0,B19*60%-C19),IF(AND(ISNUMBER(AD19),B19>AD19),IF(B19<30000,0,IF(B19<100000,MAX(0,(B19-AD19)*0.2),MAX(0,(B19-AD19)*0.3))),0))) | AA19: =IF($A19="","",IF($AA$2<>"",$AA$2,"")) | AB19: =IF($A19="","",IF(B19<30000,0.03,IF(B19<100000,0.02,0.015))) | AC19: =IF($A19="","",IFERROR(DATEDIF($A$2,$A19,"m"),0)) | AD19: =IF($A19="","",IF(OR(AA19="",AB19="",AC19=""),"",AA19*POWER(1+AB19,AC19))) | AE19: =IF($A19="","",IF(OR(AD19="",AD19=0),"",B19/AD19-1)) | AG19: =IF($A19="","",IF(B19<30000,"婴儿",IF(B19<100000,"成长","成熟"))) | AQ19: =IF($A19="","",B19-$AA$2-SUM($F$2:F19))
D20: =IF($A20="","",SUMIFS(持仓表!$J:$J,持仓表!$A:$A,$A20)) | E20: =IFERROR(D20/B20,0) -> 0 | G20: =IF($B20="","",MAX($B$2:B20)) | H20: =IFERROR((B20-F20)/F20,0) -> 0 | I20: =IFERROR((B20-G20)/G20,0) -> 0 | N20: =IF($B20="","",MIN(70%,IF($I20<=-15%,10%,IF($I20<=-10%,30%,IF($M20>=4,10%,IF($M20>=3,30%,IF($J20="强",IF($K20="A",70%,IF($K20="B",60%,40%)),IF($J20="中性",IF($K20="A",50%,IF($K20="B",40%,25%)),IF($K20="A",30%,IF($K20="B",20%,10%)))))))))) | O20: =IF($B20="","",IF(B20<30000,35%,IF(B20<50000,30%,IF(B20<100000,25%,20%)))) | P20: =IF($A20="","",COUNTIFS(持仓表!$A:$A,$A20,持仓表!$G:$G,">0")) | Q20: =IF($A20="","",COUNTIFS(持仓表!$A:$A,$A20,持仓表!$D:$D,"是",持仓表!$G:$G,">0")) | R20: =IF($A20="","",MAX(0,P20-Q20)) | S20: =IF($B20="","",IF(B20<50000,3,IF(B20<100000,4,5))) | T20: =IF($A20="","",IF(OR(M20>=4,I20<=-8%),"防守",IF(OR(M20>=2,I20<=-5%),"警戒","正常"))) | U20: =IF($A20="","",IF(AND(L20>=3,M20<=2,T20<>"防守"),"是","否")) | V20: =IF($A20="","",IF(AND(E20<N20,R20<S20,M20<=2,I20>-15%),"是","否")) | W20: =IF($A20="","",IF(OR(M20>=3,I20<=-15%),"是","否")) | X20: =IF($A20="","",IFERROR(maxifs(候选池!$AB:$AB,候选池!$A:$A,$A20),0)) | Y20: =IF($A20="","",IF(OR(M20>=4,I20<=-8%),MAX(0,B20*60%-C20),IF(AND(ISNUMBER(AD20),B20>AD20),IF(B20<30000,0,IF(B20<100000,MAX(0,(B20-AD20)*0.2),MAX(0,(B20-AD20)*0.3))),0))) | AA20: =IF($A20="","",IF($AA$2<>"",$AA$2,"")) | AB20: =IF($A20="","",IF(B20<30000,0.03,IF(B20<100000,0.02,0.015))) | AC20: =IF($A20="","",IFERROR(DATEDIF($A$2,$A20,"m"),0)) | AD20: =IF($A20="","",IF(OR(AA20="",AB20="",AC20=""),"",AA20*POWER(1+AB20,AC20))) | AE20: =IF($A20="","",IF(OR(AD20="",AD20=0),"",B20/AD20-1)) | AG20: =IF($A20="","",IF(B20<30000,"婴儿",IF(B20<100000,"成长","成熟"))) | AQ20: =IF($A20="","",B20-$AA$2-SUM($F$2:F20))
D21: =IF($A21="","",SUMIFS(持仓表!$J:$J,持仓表!$A:$A,$A21)) | E21: =IFERROR(D21/B21,0) -> 0 | G21: =IF($B21="","",MAX($B$2:B21)) | H21: =IFERROR((B21-F21)/F21,0) -> 0 | I21: =IFERROR((B21-G21)/G21,0) -> 0 | N21: =IF($B21="","",MIN(70%,IF($I21<=-15%,10%,IF($I21<=-10%,30%,IF($M21>=4,10%,IF($M21>=3,30%,IF($J21="强",IF($K21="A",70%,IF($K21="B",60%,40%)),IF($J21="中性",IF($K21="A",50%,IF($K21="B",40%,25%)),IF($K21="A",30%,IF($K21="B",20%,10%)))))))))) | O21: =IF($B21="","",IF(B21<30000,35%,IF(B21<50000,30%,IF(B21<100000,25%,20%)))) | P21: =IF($A21="","",COUNTIFS(持仓表!$A:$A,$A21,持仓表!$G:$G,">0")) | Q21: =IF($A21="","",COUNTIFS(持仓表!$A:$A,$A21,持仓表!$D:$D,"是",持仓表!$G:$G,">0")) | R21: =IF($A21="","",MAX(0,P21-Q21)) | S21: =IF($B21="","",IF(B21<50000,3,IF(B21<100000,4,5))) | T21: =IF($A21="","",IF(OR(M21>=4,I21<=-8%),"防守",IF(OR(M21>=2,I21<=-5%),"警戒","正常"))) | U21: =IF($A21="","",IF(AND(L21>=3,M21<=2,T21<>"防守"),"是","否")) | V21: =IF($A21="","",IF(AND(E21<N21,R21<S21,M21<=2,I21>-15%),"是","否")) | W21: =IF($A21="","",IF(OR(M21>=3,I21<=-15%),"是","否")) | X21: =IF($A21="","",IFERROR(maxifs(候选池!$AB:$AB,候选池!$A:$A,$A21),0)) | Y21: =IF($A21="","",IF(OR(M21>=4,I21<=-8%),MAX(0,B21*60%-C21),IF(AND(ISNUMBER(AD21),B21>AD21),IF(B21<30000,0,IF(B21<100000,MAX(0,(B21-AD21)*0.2),MAX(0,(B21-AD21)*0.3))),0))) | AA21: =IF($A21="","",IF($AA$2<>"",$AA$2,"")) | AB21: =IF($A21="","",IF(B21<30000,0.03,IF(B21<100000,0.02,0.015))) | AC21: =IF($A21="","",IFERROR(DATEDIF($A$2,$A21,"m"),0)) | AD21: =IF($A21="","",IF(OR(AA21="",AB21="",AC21=""),"",AA21*POWER(1+AB21,AC21))) | AE21: =IF($A21="","",IF(OR(AD21="",AD21=0),"",B21/AD21-1)) | AG21: =IF($A21="","",IF(B21<30000,"婴儿",IF(B21<100000,"成长","成熟"))) | AQ21: =IF($A21="","",B21-$AA$2-SUM($F$2:F21))
D22: =IF($A22="","",SUMIFS(持仓表!$J:$J,持仓表!$A:$A,$A22)) | E22: =IFERROR(D22/B22,0) -> 0 | G22: =IF($B22="","",MAX($B$2:B22)) | H22: =IFERROR((B22-F22)/F22,0) -> 0 | I22: =IFERROR((B22-G22)/G22,0) -> 0 | N22: =IF($B22="","",MIN(70%,IF($I22<=-15%,10%,IF($I22<=-10%,30%,IF($M22>=4,10%,IF($M22>=3,30%,IF($J22="强",IF($K22="A",70%,IF($K22="B",60%,40%)),IF($J22="中性",IF($K22="A",50%,IF($K22="B",40%,25%)),IF($K22="A",30%,IF($K22="B",20%,10%)))))))))) | O22: =IF($B22="","",IF(B22<30000,35%,IF(B22<50000,30%,IF(B22<100000,25%,20%)))) | P22: =IF($A22="","",COUNTIFS(持仓表!$A:$A,$A22,持仓表!$G:$G,">0")) | Q22: =IF($A22="","",COUNTIFS(持仓表!$A:$A,$A22,持仓表!$D:$D,"是",持仓表!$G:$G,">0")) | R22: =IF($A22="","",MAX(0,P22-Q22)) | S22: =IF($B22="","",IF(B22<50000,3,IF(B22<100000,4,5))) | T22: =IF($A22="","",IF(OR(M22>=4,I22<=-8%),"防守",IF(OR(M22>=2,I22<=-5%),"警戒","正常"))) | U22: =IF($A22="","",IF(AND(L22>=3,M22<=2,T22<>"防守"),"是","否")) | V22: =IF($A22="","",IF(AND(E22<N22,R22<S22,M22<=2,I22>-15%),"是","否")) | W22: =IF($A22="","",IF(OR(M22>=3,I22<=-15%),"是","否")) | X22: =IF($A22="","",IFERROR(maxifs(候选池!$AB:$AB,候选池!$A:$A,$A22),0)) | Y22: =IF($A22="","",IF(OR(M22>=4,I22<=-8%),MAX(0,B22*60%-C22),IF(AND(ISNUMBER(AD22),B22>AD22),IF(B22<30000,0,IF(B22<100000,MAX(0,(B22-AD22)*0.2),MAX(0,(B22-AD22)*0.3))),0))) | AA22: =IF($A22="","",IF($AA$2<>"",$AA$2,"")) | AB22: =IF($A22="","",IF(B22<30000,0.03,IF(B22<100000,0.02,0.015))) | AC22: =IF($A22="","",IFERROR(DATEDIF($A$2,$A22,"m"),0)) | AD22: =IF($A22="","",IF(OR(AA22="",AB22="",AC22=""),"",AA22*POWER(1+AB22,AC22))) | AE22: =IF($A22="","",IF(OR(AD22="",AD22=0),"",B22/AD22-1)) | AG22: =IF($A22="","",IF(B22<30000,"婴儿",IF(B22<100000,"成长","成熟"))) | AQ22: =IF($A22="","",B22-$AA$2-SUM($F$2:F22))
D23: =IF($A23="","",SUMIFS(持仓表!$J:$J,持仓表!$A:$A,$A23)) | E23: =IFERROR(D23/B23,0) -> 0 | G23: =IF($B23="","",MAX($B$2:B23)) | H23: =IFERROR((B23-F23)/F23,0) -> 0 | I23: =IFERROR((B23-G23)/G23,0) -> 0 | N23: =IF($B23="","",MIN(70%,IF($I23<=-15%,10%,IF($I23<=-10%,30%,IF($M23>=4,10%,IF($M23>=3,30%,IF($J23="强",IF($K23="A",70%,IF($K23="B",60%,40%)),IF($J23="中性",IF($K23="A",50%,IF($K23="B",40%,25%)),IF($K23="A",30%,IF($K23="B",20%,10%)))))))))) | O23: =IF($B23="","",IF(B23<30000,35%,IF(B23<50000,30%,IF(B23<100000,25%,20%)))) | P23: =IF($A23="","",COUNTIFS(持仓表!$A:$A,$A23,持仓表!$G:$G,">0")) | Q23: =IF($A23="","",COUNTIFS(持仓表!$A:$A,$A23,持仓表!$D:$D,"是",持仓表!$G:$G,">0")) | R23: =IF($A23="","",MAX(0,P23-Q23)) | S23: =IF($B23="","",IF(B23<50000,3,IF(B23<100000,4,5))) | T23: =IF($A23="","",IF(OR(M23>=4,I23<=-8%),"防守",IF(OR(M23>=2,I23<=-5%),"警戒","正常"))) | U23: =IF($A23="","",IF(AND(L23>=3,M23<=2,T23<>"防守"),"是","否")) | V23: =IF($A23="","",IF(AND(E23<N23,R23<S23,M23<=2,I23>-15%),"是","否")) | W23: =IF($A23="","",IF(OR(M23>=3,I23<=-15%),"是","否")) | X23: =IF($A23="","",IFERROR(maxifs(候选池!$AB:$AB,候选池!$A:$A,$A23),0)) | Y23: =IF($A23="","",IF(OR(M23>=4,I23<=-8%),MAX(0,B23*60%-C23),IF(AND(ISNUMBER(AD23),B23>AD23),IF(B23<30000,0,IF(B23<100000,MAX(0,(B23-AD23)*0.2),MAX(0,(B23-AD23)*0.3))),0))) | AA23: =IF($A23="","",IF($AA$2<>"",$AA$2,"")) | AB23: =IF($A23="","",IF(B23<30000,0.03,IF(B23<100000,0.02,0.015))) | AC23: =IF($A23="","",IFERROR(DATEDIF($A$2,$A23,"m"),0)) | AD23: =IF($A23="","",IF(OR(AA23="",AB23="",AC23=""),"",AA23*POWER(1+AB23,AC23))) | AE23: =IF($A23="","",IF(OR(AD23="",AD23=0),"",B23/AD23-1)) | AG23: =IF($A23="","",IF(B23<30000,"婴儿",IF(B23<100000,"成长","成熟"))) | AQ23: =IF($A23="","",B23-$AA$2-SUM($F$2:F23))
D24: =IF($A24="","",SUMIFS(持仓表!$J:$J,持仓表!$A:$A,$A24)) | E24: =IFERROR(D24/B24,0) -> 0 | G24: =IF($B24="","",MAX($B$2:B24)) | H24: =IFERROR((B24-F24)/F24,0) -> 0 | I24: =IFERROR((B24-G24)/G24,0) -> 0 | N24: =IF($B24="","",MIN(70%,IF($I24<=-15%,10%,IF($I24<=-10%,30%,IF($M24>=4,10%,IF($M24>=3,30%,IF($J24="强",IF($K24="A",70%,IF($K24="B",60%,40%)),IF($J24="中性",IF($K24="A",50%,IF($K24="B",40%,25%)),IF($K24="A",30%,IF($K24="B",20%,10%)))))))))) | O24: =IF($B24="","",IF(B24<30000,35%,IF(B24<50000,30%,IF(B24<100000,25%,20%)))) | P24: =IF($A24="","",COUNTIFS(持仓表!$A:$A,$A24,持仓表!$G:$G,">0")) | Q24: =IF($A24="","",COUNTIFS(持仓表!$A:$A,$A24,持仓表!$D:$D,"是",持仓表!$G:$G,">0")) | R24: =IF($A24="","",MAX(0,P24-Q24)) | S24: =IF($B24="","",IF(B24<50000,3,IF(B24<100000,4,5))) | T24: =IF($A24="","",IF(OR(M24>=4,I24<=-8%),"防守",IF(OR(M24>=2,I24<=-5%),"警戒","正常"))) | U24: =IF($A24="","",IF(AND(L24>=3,M24<=2,T24<>"防守"),"是","否")) | V24: =IF($A24="","",IF(AND(E24<N24,R24<S24,M24<=2,I24>-15%),"是","否")) | W24: =IF($A24="","",IF(OR(M24>=3,I24<=-15%),"是","否")) | X24: =IF($A24="","",IFERROR(maxifs(候选池!$AB:$AB,候选池!$A:$A,$A24),0)) | Y24: =IF($A24="","",IF(OR(M24>=4,I24<=-8%),MAX(0,B24*60%-C24),IF(AND(ISNUMBER(AD24),B24>AD24),IF(B24<30000,0,IF(B24<100000,MAX(0,(B24-AD24)*0.2),MAX(0,(B24-AD24)*0.3))),0))) | AA24: =IF($A24="","",IF($AA$2<>"",$AA$2,"")) | AB24: =IF($A24="","",IF(B24<30000,0.03,IF(B24<100000,0.02,0.015))) | AC24: =IF($A24="","",IFERROR(DATEDIF($A$2,$A24,"m"),0)) | AD24: =IF($A24="","",IF(OR(AA24="",AB24="",AC24=""),"",AA24*POWER(1+AB24,AC24))) | AE24: =IF($A24="","",IF(OR(AD24="",AD24=0),"",B24/AD24-1)) | AG24: =IF($A24="","",IF(B24<30000,"婴儿",IF(B24<100000,"成长","成熟"))) | AQ24: =IF($A24="","",B24-$AA$2-SUM($F$2:F24))
... D201: =IF($A201="","",SUMIFS(持仓表!$J:$J,持仓表!$A:$A,$A201)) | E201: =IFERROR(D201/B201,0) -> 0 | G201: =IF($B201="","",MAX($B$2:B201)) | H201: =IFERROR((B201-F201)/F201,0) -> 0 | I201: =IFERROR((B201-G201)/G201,0) -> 0 | N201: =IF($B201="","",MIN(70%,IF($I201<=-15%,10%,IF($I201<=-10%,30%,IF($M201>=4,10%,IF($M201>=3,30%,IF($J201="强",IF($K201="A",70%,IF($K201="B",60%,40%)),IF($J201="中性",IF($K201="A",50%,IF($K201="B",40%,25%)),IF($K201="A",30%,IF($K201="B",20%,10%)))))))))) | O201: =IF($B201="","",IF(B201<30000,35%,IF(B201<50000,30%,IF(B201<100000,25%,20%)))) | P201: =IF($A201="","",COUNTIFS(持仓表!$A:$A,$A201,持仓表!$G:$G,">0")) | Q201: =IF($A201="","",COUNTIFS(持仓表!$A:$A,$A201,持仓表!$D:$D,"是",持仓表!$G:$G,">0")) | R201: =IF($A201="","",MAX(0,P201-Q201)) | S201: =IF($B201="","",IF(B201<50000,3,IF(B201<100000,4,5))) | T201: =IF($A201="","",IF(OR(M201>=4,I201<=-8%),"防守",IF(OR(M201>=2,I201<=-5%),"警戒","正常"))) | U201: =IF($A201="","",IF(AND(L201>=3,M201<=2,T201<>"防守"),"是","否")) | V201: =IF($A201="","",IF(AND(E201<N201,R201<S201,M201<=2,I201>-15%),"是","否")) | W201: =IF($A201="","",IF(OR(M201>=3,I201<=-15%),"是","否")) | X201: =IF($A201="","",IFERROR(maxifs(候选池!$AB:$AB,候选池!$A:$A,$A201),0)) | Y201: =IF($A201="","",IF(OR(M201>=4,I201<=-8%),MAX(0,B201*60%-C201),IF(AND(ISNUMBER(AD201),B201>AD201),IF(B201<30000,0,IF(B201<100000,MAX(0,(B201-AD201)*0.2),MAX(0,(B201-AD201)*0.3))),0))) | AA201: =IF($A201="","",IF($AA$2<>"",$AA$2,"")) | AB201: =IF($A201="","",IF(B201<30000,0.03,IF(B201<100000,0.02,0.015))) | AC201: =IF($A201="","",IFERROR(DATEDIF($A$2,$A201,"m"),0)) | AD201: =IF($A201="","",IF(OR(AA201="",AB201="",AC201=""),"",AA201*POWER(1+AB201,AC201))) | AE201: =IF($A201="","",IF(OR(AD201="",AD201=0),"",B201/AD201-1)) | AG201: =IF($A201="","",IF(B201<30000,"婴儿",IF(B201<100000,"成长","成熟"))) | AQ201: =IF($A201="","",B201-$AA$2-SUM($F$2:F201))

Sheet 持仓表
A1: 日期 | B1: 股票名称 | C1: 代码 | D1: 是否WAIVED | E1: WAIVED基准价 | F1: 买入日期 | G1: 持股数量 Shares | H1: 持仓均价 EntryPrice | I1: 当前价 Close | J1: 持仓市值 | K1: 成本金额 | L1: 浮盈亏金额 | M1: 浮盈亏比 ProfitRatio | N1: 持仓占比 PositionRatio | O1: 买点低点 BuyPointLow | P1: 止损价 StopPrice | Q1: 是否破止损 | R1: ratio | S1: DL_P | T1: valid | U1: SignalType | V1: SignalInvalid | W1: RiskWatch | X1: 是否确认一卖 | Y1: 是否超单股上限 | Z1: 盈亏状态 | AA1: 处置动作 | AB1: 执行结论 | AC1: 处置原因 | AD1: 备注
A2: 46224 | B2: 东风股份 | C2: 600006 | D2: 是 | E2: 5.24 | F2: 45971 | G2: 100 | H2: 8.711 | I2: 5.33 | J2: =IFERROR(G2*I2,0) -> 533 | K2: =IFERROR(G2*H2,0) -> 871.1 | L2: =IFERROR(J2-K2,0) -> -338.1 | M2: =IFERROR((I2-H2)/H2,0) -> -0.38812995 | N2: =IFERROR(J2/INDEX(账户总表!$B:$B,MATCH($A2,账户总表!$A:$A,0)),0) -> 0.026222417 | O2: 5.24 | P2: =IF($A2="","",IF($D2="是",IF(E2>0,E2*0.92,MAX(O2*0.98,H2*0.92)),MAX(O2*0.98,H2*0.92))) -> 4.8208 | Q2: =IF($A2="","",IF(AND(I2>0,P2>0,I2<=P2),"是","否")) -> 否 | V2: =IF($A2="","",IF(OR(AND(O2>0,I2<O2),AND(T2="False",S2<0.8)),"是","否")) -> 否 | W2: =IF($A2="","",IF(AND(I2<H2,S2<0.8),"是","否")) -> 是 | X2: =IF($A2="","",IF(AND(R2<60%,S2>0.8,T2="True",U2="一卖"),"是","否")) -> 否 | Y2: =IF($A2="","",IF(D2="是","否",IF(N2>LOOKUP(2,1/(账户总表!$A:$A<>""),账户总表!$O:$O),"是","否"))) -> 否 | Z2: =IF($A2="","",IF(M2>=0,"盈利","亏损")) -> 亏损 | AA2: =IF($A2="","",IF(OR(Q2="是",M2<=-8%,V2="是",X2="是"),"卖出",IF(Y2="是","减仓",IF(W2="是","观察","持有")))) -> 卖出 | AB2: =IF($A2="","",IF(D2="是",IF(I2<=E2*0.92,"立即卖出(WAIVED止损)","继续持有(WAIVED)"),IF(OR(M2<=-10%,Q2="是"),"立即卖出",IF(OR(AA2="卖出",V2="是",X2="是"),"次日卖出",IF(AND(Y2="是",NOT(OR(Q2="是",M2<=-8%,V2="是",X2="是"))),"减仓至上限",IF(W2="是","观察","继续持有")))))) -> 继续持有(WAIVED) | AC2: =IF($A2="","",IF(Q2="是","触发止损",IF(M2<=-8%,"固定止损",IF(V2="是","信号失效",IF(X2="是","确认一卖",IF(Y2="是","单股超限",IF(W2="是","DL_P弱化","规则内持有"))))))) -> 固定止损
A3: 46224 | B3: 万华化学 | C3: 600309 | D3: 否 | F3: 46217 | G3: 100 | H3: 67.558 | I3: 75.49 | J3: =IFERROR(G3*I3,0) -> 7549 | K3: =IFERROR(G3*H3,0) -> 6755.8 | L3: =IFERROR(J3-K3,0) -> 793.2 | M3: =IFERROR((I3-H3)/H3,0) -> 0.11741023 | N3: =IFERROR(J3/INDEX(账户总表!$B:$B,MATCH($A3,账户总表!$A:$A,0)),0) -> 0.37139405 | O3: 70.4 | P3: =IF($A3="","",IF($D3="是",IF(E3>0,E3*0.92,MAX(O3*0.98,H3*0.92)),MAX(O3*0.98,H3*0.92))) -> 68.992 | Q3: =IF($A3="","",IF(AND(I3>0,P3>0,I3<=P3),"是","否")) -> 否 | V3: =IF($A3="","",IF(OR(AND(O3>0,I3<O3),AND(T3="False",S3<0.8)),"是","否")) -> 否 | W3: =IF($A3="","",IF(AND(I3<H3,S3<0.8),"是","否")) -> 否 | X3: =IF($A3="","",IF(AND(R3<60%,S3>0.8,T3="True",U3="一卖"),"是","否")) -> 否 | Y3: =IF($A3="","",IF(D3="是","否",IF(N3>LOOKUP(2,1/(账户总表!$A:$A<>""),账户总表!$O:$O),"是","否"))) -> 是 | Z3: =IF($A3="","",IF(M3>=0,"盈利","亏损")) -> 盈利 | AA3: =IF($A3="","",IF(OR(Q3="是",M3<=-8%,V3="是",X3="是"),"卖出",IF(Y3="是","减仓",IF(W3="是","观察","持有")))) -> 减仓 | AB3: =IF($A3="","",IF(D3="是",IF(I3<=E3*0.92,"立即卖出(WAIVED止损)","继续持有(WAIVED)"),IF(OR(M3<=-10%,Q3="是"),"立即卖出",IF(OR(AA3="卖出",V3="是",X3="是"),"次日卖出",IF(AND(Y3="是",NOT(OR(Q3="是",M3<=-8%,V3="是",X3="是"))),"减仓至上限",IF(W3="是","观察","继续持有")))))) -> 减仓至上限 | AC3: =IF($A3="","",IF(Q3="是","触发止损",IF(M3<=-8%,"固定止损",IF(V3="是","信号失效",IF(X3="是","确认一卖",IF(Y3="是","单股超限",IF(W3="是","DL_P弱化","规则内持有"))))))) -> 单股超限
A4: 46224 | B4: 隆基绿能 | C4: 601012 | D4: 否 | F4: 46221 | G4: 200 | H4: 11.107 | I4: 12.8 | J4: =IFERROR(G4*I4,0) -> 2560 | K4: =IFERROR(G4*H4,0) -> 2221.4 | L4: =IFERROR(J4-K4,0) -> 338.6 | M4: =IFERROR((I4-H4)/H4,0) -> 0.1524264 | N4: =IFERROR(J4/INDEX(账户总表!$B:$B,MATCH($A4,账户总表!$A:$A,0)),0) -> 0.12594632 | O4: 11.63 | P4: =IF($A4="","",IF($D4="是",IF(E4>0,E4*0.92,MAX(O4*0.98,H4*0.92)),MAX(O4*0.98,H4*0.92))) -> 11.3974 | Q4: =IF($A4="","",IF(AND(I4>0,P4>0,I4<=P4),"是","否")) -> 否 | V4: =IF($A4="","",IF(OR(AND(O4>0,I4<O4),AND(T4="False",S4<0.8)),"是","否")) -> 否 | W4: =IF($A4="","",IF(AND(I4<H4,S4<0.8),"是","否")) -> 否 | X4: =IF($A4="","",IF(AND(R4<60%,S4>0.8,T4="True",U4="一卖"),"是","否")) -> 否 | Y4: =IF($A4="","",IF(D4="是","否",IF(N4>LOOKUP(2,1/(账户总表!$A:$A<>""),账户总表!$O:$O),"是","否"))) -> 否 | Z4: =IF($A4="","",IF(M4>=0,"盈利","亏损")) -> 盈利 | AA4: =IF($A4="","",IF(OR(Q4="是",M4<=-8%,V4="是",X4="是"),"卖出",IF(Y4="是","减仓",IF(W4="是","观察","持有")))) -> 持有 | AB4: =IF($A4="","",IF(D4="是",IF(I4<=E4*0.92,"立即卖出(WAIVED止损)","继续持有(WAIVED)"),IF(OR(M4<=-10%,Q4="是"),"立即卖出",IF(OR(AA4="卖出",V4="是",X4="是"),"次日卖出",IF(AND(Y4="是",NOT(OR(Q4="是",M4<=-8%,V4="是",X4="是"))),"减仓至上限",IF(W4="是","观察","继续持有")))))) -> 继续持有 | AC4: =IF($A4="","",IF(Q4="是","触发止损",IF(M4<=-8%,"固定止损",IF(V4="是","信号失效",IF(X4="是","确认一卖",IF(Y4="是","单股超限",IF(W4="是","DL_P弱化","规则内持有"))))))) -> 规则内持有
A5: 46227 | B5: 创力集团 | C5: 603012 | D5: 否 | F5: 2026-07-24 | G5: 100 | H5: 8.021 | I5: 8.03 | J5: =IF(A5="","",G5*I5) -> 803 | K5: =IF(A5="","",G5*H5) -> 802.1 | L5: =IF(A5="","",J5-K5) -> 0.9 | M5: =IFERROR((I5-H5)/H5,0) -> 0.0011220546 | N5: =IFERROR(J5/INDEX(账户总表!$B:$B,MATCH($A5,账户总表!$A:$A,0)),0) -> 0.038527381 | P5: 7.61995 | Q5: =IF($A5="","",IF(AND(I5>0,P5>0,I5<=P5),"是","否")) -> 否 | V5: =IF($A5="","",IF(OR(AND(O5>0,I5<O5),AND(T5="False",S5<0.8)),"是","否")) -> 否 | W5: =IF($A5="","",IF(AND(I5<H5,S5<0.8),"是","否")) -> 否 | X5: =IF($A5="","",IF(AND(R5<60%,S5>0.8,T5="True",U5="一卖"),"是","否")) -> 否 | Y5: =IF($A5="","",IF(D5="是","否",IF(N5>LOOKUP(2,1/(账户总表!$A:$A<>""),账户总表!$O:$O),"是","否"))) -> 否 | Z5: =IF($A5="","",IF(M5>=0,"盈利","亏损")) -> 盈利 | AA5: =IF($A5="","",IF(OR(Q5="是",M5<=-8%,V5="是",X5="是"),"卖出",IF(Y5="是","减仓",IF(W5="是","观察","持有")))) -> 持有 | AB5: =IF($A5="","",IF(D5="是",IF(I5<=E5*0.92,"立即卖出(WAIVED止损)","继续持有(WAIVED)"),IF(OR(M5<=-10%,Q5="是"),"立即卖出",IF(OR(AA5="卖出",V5="是",X5="是"),"次日卖出",IF(AND(Y5="是",NOT(OR(Q5="是",M5<=-8%,V5="是",X5="是"))),"减仓至上限",IF(W5="是","观察","继续持有")))))) -> 继续持有 | AC5: =IF($A5="","",IF(Q5="是","触发止损",IF(M5<=-8%,"固定止损",IF(V5="是","信号失效",IF(X5="是","确认一卖",IF(Y5="是","单股超限",IF(W5="是","DL_P弱化","规则内持有"))))))) -> 规则内持有
A6: 46227 | B6: 新五丰 | C6: 600975 | D6: 否 | F6: 2026-07-24 | G6: 300 | H6: 4.804 | I6: 4.73 | J6: =IF(A6="","",G6*I6) -> 1419 | K6: =IF(A6="","",G6*H6) -> 1441.2 | L6: =IF(A6="","",J6-K6) -> -22.2 | M6: =IFERROR((I6-H6)/H6,0) -> -0.01540383 | N6: =IFERROR(J6/INDEX(账户总表!$B:$B,MATCH($A6,账户总表!$A:$A,0)),0) -> 0.068082632 | P6: 4.5638 | Q6: =IF($A6="","",IF(AND(I6>0,P6>0,I6<=P6),"是","否")) -> 否 | V6: =IF($A6="","",IF(OR(AND(O6>0,I6<O6),AND(T6="False",S6<0.8)),"是","否")) -> 否 | W6: =IF($A6="","",IF(AND(I6<H6,S6<0.8),"是","否")) -> 是 | X6: =IF($A6="","",IF(AND(R6<60%,S6>0.8,T6="True",U6="一卖"),"是","否")) -> 否 | Y6: =IF($A6="","",IF(D6="是","否",IF(N6>LOOKUP(2,1/(账户总表!$A:$A<>""),账户总表!$O:$O),"是","否"))) -> 否 | Z6: =IF($A6="","",IF(M6>=0,"盈利","亏损")) -> 亏损 | AA6: =IF($A6="","",IF(OR(Q6="是",M6<=-8%,V6="是",X6="是"),"卖出",IF(Y6="是","减仓",IF(W6="是","观察","持有")))) -> 观察 | AB6: =IF($A6="","",IF(D6="是",IF(I6<=E6*0.92,"立即卖出(WAIVED止损)","继续持有(WAIVED)"),IF(OR(M6<=-10%,Q6="是"),"立即卖出",IF(OR(AA6="卖出",V6="是",X6="是"),"次日卖出",IF(AND(Y6="是",NOT(OR(Q6="是",M6<=-8%,V6="是",X6="是"))),"减仓至上限",IF(W6="是","观察","继续持有")))))) -> 观察 | AC6: =IF($A6="","",IF(Q6="是","触发止损",IF(M6<=-8%,"固定止损",IF(V6="是","信号失效",IF(X6="是","确认一卖",IF(Y6="是","单股超限",IF(W6="是","DL_P弱化","规则内持有"))))))) -> DL_P弱化
A7: 46227 | B7: 方盛制药 | C7: 603998 | D7: 否 | F7: 2026-07-24 | G7: 100 | H7: 9.271 | I7: 8.96 | J7: =IF(A7="","",G7*I7) -> 896 | K7: =IF(A7="","",G7*H7) -> 927.1 | L7: =IF(A7="","",J7-K7) -> -31.1 | M7: =IFERROR((I7-H7)/H7,0) -> -0.033545464 | N7: =IFERROR(J7/INDEX(账户总表!$B:$B,MATCH($A7,账户总表!$A:$A,0)),0) -> 0.042989456 | P7: 8.80745 | Q7: =IF($A7="","",IF(AND(I7>0,P7>0,I7<=P7),"是","否")) -> 否 | V7: =IF($A7="","",IF(OR(AND(O7>0,I7<O7),AND(T7="False",S7<0.8)),"是","否")) -> 否 | W7: =IF($A7="","",IF(AND(I7<H7,S7<0.8),"是","否")) -> 是 | X7: =IF($A7="","",IF(AND(R7<60%,S7>0.8,T7="True",U7="一卖"),"是","否")) -> 否 | Y7: =IF($A7="","",IF(D7="是","否",IF(N7>LOOKUP(2,1/(账户总表!$A:$A<>""),账户总表!$O:$O),"是","否"))) -> 否 | Z7: =IF($A7="","",IF(M7>=0,"盈利","亏损")) -> 亏损 | AA7: =IF($A7="","",IF(OR(Q7="是",M7<=-8%,V7="是",X7="是"),"卖出",IF(Y7="是","减仓",IF(W7="是","观察","持有")))) -> 观察 | AB7: =IF($A7="","",IF(D7="是",IF(I7<=E7*0.92,"立即卖出(WAIVED止损)","继续持有(WAIVED)"),IF(OR(M7<=-10%,Q7="是"),"立即卖出",IF(OR(AA7="卖出",V7="是",X7="是"),"次日卖出",IF(AND(Y7="是",NOT(OR(Q7="是",M7<=-8%,V7="是",X7="是"))),"减仓至上限",IF(W7="是","观察","继续持有")))))) -> 观察 | AC7: =IF($A7="","",IF(Q7="是","触发止损",IF(M7<=-8%,"固定止损",IF(V7="是","信号失效",IF(X7="是","确认一卖",IF(Y7="是","单股超限",IF(W7="是","DL_P弱化","规则内持有"))))))) -> DL_P弱化
A8: 46227 | B8: 建研院 | C8: 603183 | D8: 否 | F8: 2026-07-24 | G8: 200 | H8: 3.966 | I8: 4.02 | J8: =IF(A8="","",G8*I8) -> 804 | K8: =IF(A8="","",G8*H8) -> 793.2 | L8: =IF(A8="","",J8-K8) -> 10.8 | M8: =IFERROR((I8-H8)/H8,0) -> 0.013615734 | N8: =IFERROR(J8/INDEX(账户总表!$B:$B,MATCH($A8,账户总表!$A:$A,0)),0) -> 0.03857536 | P8: 3.7677 | Q8: =IF($A8="","",IF(AND(I8>0,P8>0,I8<=P8),"是","否")) -> 否 | V8: =IF($A8="","",IF(OR(AND(O8>0,I8<O8),AND(T8="False",S8<0.8)),"是","否")) -> 否 | W8: =IF($A8="","",IF(AND(I8<H8,S8<0.8),"是","否")) -> 否 | X8: =IF($A8="","",IF(AND(R8<60%,S8>0.8,T8="True",U8="一卖"),"是","否")) -> 否 | Y8: =IF($A8="","",IF(D8="是","否",IF(N8>LOOKUP(2,1/(账户总表!$A:$A<>""),账户总表!$O:$O),"是","否"))) -> 否 | Z8: =IF($A8="","",IF(M8>=0,"盈利","亏损")) -> 盈利 | AA8: =IF($A8="","",IF(OR(Q8="是",M8<=-8%,V8="是",X8="是"),"卖出",IF(Y8="是","减仓",IF(W8="是","观察","持有")))) -> 持有 | AB8: =IF($A8="","",IF(D8="是",IF(I8<=E8*0.92,"立即卖出(WAIVED止损)","继续持有(WAIVED)"),IF(OR(M8<=-10%,Q8="是"),"立即卖出",IF(OR(AA8="卖出",V8="是",X8="是"),"次日卖出",IF(AND(Y8="是",NOT(OR(Q8="是",M8<=-8%,V8="是",X8="是"))),"减仓至上限",IF(W8="是","观察","继续持有")))))) -> 继续持有 | AC8: =IF($A8="","",IF(Q8="是","触发止损",IF(M8<=-8%,"固定止损",IF(V8="是","信号失效",IF(X8="是","确认一卖",IF(Y8="是","单股超限",IF(W8="是","DL_P弱化","规则内持有"))))))) -> 规则内持有
A9: 46227 | B9: 曲美家居 | C9: 603818 | D9: 否 | F9: 2026-07-24 | G9: 500 | H9: 3.142 | I9: 3.09 | J9: =IF(A9="","",G9*I9) -> 1545 | K9: =IF(A9="","",G9*H9) -> 1571 | L9: =IF(A9="","",J9-K9) -> -26 | M9: =IFERROR((I9-H9)/H9,0) -> -0.016549968 | N9: =IFERROR(J9/INDEX(账户总表!$B:$B,MATCH($A9,账户总表!$A:$A,0)),0) -> 0.074128024 | P9: 2.9849 | Q9: =IF($A9="","",IF(AND(I9>0,P9>0,I9<=P9),"是","否")) -> 否 | V9: =IF($A9="","",IF(OR(AND(O9>0,I9<O9),AND(T9="False",S9<0.8)),"是","否")) -> 否 | W9: =IF($A9="","",IF(AND(I9<H9,S9<0.8),"是","否")) -> 是 | X9: =IF($A9="","",IF(AND(R9<60%,S9>0.8,T9="True",U9="一卖"),"是","否")) -> 否 | Y9: =IF($A9="","",IF(D9="是","否",IF(N9>LOOKUP(2,1/(账户总表!$A:$A<>""),账户总表!$O:$O),"是","否"))) -> 否 | Z9: =IF($A9="","",IF(M9>=0,"盈利","亏损")) -> 亏损 | AA9: =IF($A9="","",IF(OR(Q9="是",M9<=-8%,V9="是",X9="是"),"卖出",IF(Y9="是","减仓",IF(W9="是","观察","持有")))) -> 观察 | AB9: =IF($A9="","",IF(D9="是",IF(I9<=E9*0.92,"立即卖出(WAIVED止损)","继续持有(WAIVED)"),IF(OR(M9<=-10%,Q9="是"),"立即卖出",IF(OR(AA9="卖出",V9="是",X9="是"),"次日卖出",IF(AND(Y9="是",NOT(OR(Q9="是",M9<=-8%,V9="是",X9="是"))),"减仓至上限",IF(W9="是","观察","继续持有")))))) -> 观察 | AC9: =IF($A9="","",IF(Q9="是","触发止损",IF(M9<=-8%,"固定止损",IF(V9="是","信号失效",IF(X9="是","确认一卖",IF(Y9="是","单股超限",IF(W9="是","DL_P弱化","规则内持有"))))))) -> DL_P弱化
